Workbook
Name AccountTypeList: Lists!$T$2:$T$3
Name CallStatusList: Lists!$B$2:$B$8
Name CallTypeList: Lists!$C$2:$C$4
Name CheckNo: Lists!$J$3
Name CheckYes: Lists!$J$2
Name CompletionList: Lists!$S$2:$S$3
Name EquipStatusList: Lists!$E$2:$E$4
Name InstWeek2End: Installs!$P$5
Name InstWeekEnd: Installs!$P$4
Name InstWeekStart: Installs!$P$3
Name InternalTechList: Lists!$O$2:$O$8
Name ModulePlatformList: Lists!$L$2:$L$4
Name ModuleStatusList: Lists!$N$2:$N$9
Name ModuleTypeList: Lists!$M$2:$M$11
Name PartsStatusList: Lists!$G$2:$G$6
Name PaymentStatusList: Lists!$P$2:$P$6
Name PaymentTermsList: Lists!$R$2:$R$5
Name PMStatusList: Lists!$H$2:$H$8
Name PMStyleList: Lists!$F$2:$F$5
Name ProducerList: OFFSET(Lists!$Q$2,0,0,MAX(1,COUNTA(Lists!$Q$2:$Q$30)),1)
Name RepList: Lists!$I$2:$I$10
Name RequirementsList: Lists!$W$2:$W$3
Name TechList: Lists!$A$2:$A$9
Name YesNoList: Lists!$D$2:$D$3

Sheet SOP
B1: STANDARD OPERATING PROCEDURE — Equipment Forecasting & Install Tracker
B2: Last updated: July 30, 2026 · Questions: contact the service manager
B4: Jump to a tab:
B5: → Dashboard
B6: → Projected Sales or Lease
B7: → Installs
B8: → Lists
B9: → Install Clock
B10: WHAT EACH TAB DOES
B11: SOP — this page. How to use the file.
B12: Dashboard — live sales performance summary. All numbers update automatically; never type on this tab.
B13: Projected Sales or Lease — the SALES TEAM works here. One row per high-value equipment deal.
... B98: If you ever want a completed deal to stop showing in the AUTO section, add it to the tracker above under the same name (or set its Equipment Status to Installed).

Sheet Dashboard
A1: SALES & LEASE DASHBOARD
A2: Auto-updates from the Projected Sales or Lease tab. Deals marked X (fell through) are excluded from all figures except the "Fell Through" count.
A3: Go to: | B3: SOP | C3: Projected Sales or Lease | D3: Installs | E3: Lists
A5: Active Deals | B5: Active Pipeline $ | C5: Completed Deals | D5: Completed $ | E5: Total Booked $ (Active + Completed) | F5: Fell Through
A6: =COUNTIFS('Projected Sales or Lease'!$A$3:$A$200,"<>",'Projected Sales or Lease'!$L$3:$L$200,"=") -> 14 | B6: =SUMIFS('Projected Sales or Lease'!$F$3:$F$200,'Projected Sales or Lease'!$A$3:$A$200,"<>",'Projected Sales or Lease'!$L$3:$L$200,"=") -> 286643.36 | C6: =COUNTIFS('Projected Sales or Lease'!$L$3:$L$200,"✔") -> 15 | D6: =SUMIFS('Projected Sales or Lease'!$F$3:$F$200,'Projected Sales or Lease'!$L$3:$L$200,"✔") -> 453859.92 | E6: =SUMIFS('Projected Sales or Lease'!$F$3:$F$200,'Projected Sales or Lease'!$A$3:$A$200,"<>",'Projected Sales or Lease'!$L$3:$L$200,"<>X") -> 740503.28 | F6: =COUNTIFS('Projected Sales or Lease'!$L$3:$L$200,"X") -> 0
A9: BY PRODUCER — projected sales & leases
A10: Producer | B10: # Deals | C10: Sales $ | D10: Lease $ | E10: Total $ | F10: Completed # | G10: Completed $ | H10: Open $
A11: =IF(Lists!$Q$2="","",Lists!$Q$2) -> Bill | B11: =IF($A11="","",COUNTIFS('Projected Sales or Lease'!$B$3:$B$200,$A11,'Projected Sales or Lease'!$L$3:$L$200,"<>X")) -> 0 | C11: =IF($A11="","",SUMIFS('Projected Sales or Lease'!$F$3:$F$200,'Projected Sales or Lease'!$B$3:$B$200,$A11,'Projected Sales or Lease'!$L$3:$L$200,"<>X",'Projected Sales or Lease'!$J$3:$J$200,"<>Lease")) -> 0 | D11: =IF($A11="","",SUMIFS('Projected Sales or Lease'!$F$3:$F$200,'Projected Sales or Lease'!$B$3:$B$200,$A11,'Projected Sales or Lease'!$L$3:$L$200,"<>X",'Projected Sales or Lease'!$J$3:$J$200,"Lease")) -> 0 | E11: =IF($A11="","",SUMIFS('Projected Sales or Lease'!$F$3:$F$200,'Projected Sales or Lease'!$B$3:$B$200,$A11,'Projected Sales or Lease'!$L$3:$L$200,"<>X")) -> 0 | F11: =IF($A11="","",COUNTIFS('Projected Sales or Lease'!$B$3:$B$200,$A11,'Projected Sales or Lease'!$L$3:$L$200,"✔")) -> 0 | G11: =IF($A11="","",SUMIFS('Projected Sales or Lease'!$F$3:$F$200,'Projected Sales or Lease'!$B$3:$B$200,$A11,'Projected Sales or Lease'!$L$3:$L$200,"✔")) -> 0 | H11: =IF($A11="","",$E11-$G11) -> 0
A12: =IF(Lists!$Q$3="","",Lists!$Q$3) -> Lance | B12: =IF($A12="","",COUNTIFS('Projected Sales or Lease'!$B$3:$B$200,$A12,'Projected Sales or Lease'!$L$3:$L$200,"<>X")) -> 1 | C12: =IF($A12="","",SUMIFS('Projected Sales or Lease'!$F$3:$F$200,'Projected Sales or Lease'!$B$3:$B$200,$A12,'Projected Sales or Lease'!$L$3:$L$200,"<>X",'Projected Sales or Lease'!$J$3:$J$200,"<>Lease")) -> 23953.08 | D12: =IF($A12="","",SUMIFS('Projected Sales or Lease'!$F$3:$F$200,'Projected Sales or Lease'!$B$3:$B$200,$A12,'Projected Sales or Lease'!$L$3:$L$200,"<>X",'Projected Sales or Lease'!$J$3:$J$200,"Lease")) -> 0 | E12: =IF($A12="","",SUMIFS('Projected Sales or Lease'!$F$3:$F$200,'Projected Sales or Lease'!$B$3:$B$200,$A12,'Projected Sales or Lease'!$L$3:$L$200,"<>X")) -> 23953.08 | F12: =IF($A12="","",COUNTIFS('Projected Sales or Lease'!$B$3:$B$200,$A12,'Projected Sales or Lease'!$L$3:$L$200,"✔")) -> 1 | G12: =IF($A12="","",SUMIFS('Projected Sales or Lease'!$F$3:$F$200,'Projected Sales or Lease'!$B$3:$B$200,$A12,'Projected Sales or Lease'!$L$3:$L$200,"✔")) -> 23953.08 | H12: =IF($A12="","",$E12-$G12) -> 0
A13: =IF(Lists!$Q$4="","",Lists!$Q$4) -> Sean | B13: =IF($A13="","",COUNTIFS('Projected Sales or Lease'!$B$3:$B$200,$A13,'Projected Sales or Lease'!$L$3:$L$200,"<>X")) -> 3 | C13: =IF($A13="","",SUMIFS('Projected Sales or Lease'!$F$3:$F$200,'Projected Sales or Lease'!$B$3:$B$200,$A13,'Projected Sales or Lease'!$L$3:$L$200,"<>X",'Projected Sales or Lease'!$J$3:$J$200,"<>Lease")) -> 0 | D13: =IF($A13="","",SUMIFS('Projected Sales or Lease'!$F$3:$F$200,'Projected Sales or Lease'!$B$3:$B$200,$A13,'Projected Sales or Lease'!$L$3:$L$200,"<>X",'Projected Sales or Lease'!$J$3:$J$200,"Lease")) -> 59728.4 | E13: =IF($A13="","",SUMIFS('Projected Sales or Lease'!$F$3:$F$200,'Projected Sales or Lease'!$B$3:$B$200,$A13,'Projected Sales or Lease'!$L$3:$L$200,"<>X")) -> 59728.4 | F13: =IF($A13="","",COUNTIFS('Projected Sales or Lease'!$B$3:$B$200,$A13,'Projected Sales or Lease'!$L$3:$L$200,"✔")) -> 1 | G13: =IF($A13="","",SUMIFS('Projected Sales or Lease'!$F$3:$F$200,'Projected Sales or Lease'!$B$3:$B$200,$A13,'Projected Sales or Lease'!$L$3:$L$200,"✔")) -> 19800 | H13: =IF($A13="","",$E13-$G13) -> 39928.4
A14: =IF(Lists!$Q$5="","",Lists!$Q$5) -> Shannon | B14: =IF($A14="","",COUNTIFS('Projected Sales or Lease'!$B$3:$B$200,$A14,'Projected Sales or Lease'!$L$3:$L$200,"<>X")) -> 1 | C14: =IF($A14="","",SUMIFS('Projected Sales or Lease'!$F$3:$F$200,'Projected Sales or Lease'!$B$3:$B$200,$A14,'Projected Sales or Lease'!$L$3:$L$200,"<>X",'Projected Sales or Lease'!$J$3:$J$200,"<>Lease")) -> 16051 | D14: =IF($A14="","",SUMIFS('Projected Sales or Lease'!$F$3:$F$200,'Projected Sales or Lease'!$B$3:$B$200,$A14,'Projected Sales or Lease'!$L$3:$L$200,"<>X",'Projected Sales or Lease'!$J$3:$J$200,"Lease")) -> 0 | E14: =IF($A14="","",SUMIFS('Projected Sales or Lease'!$F$3:$F$200,'Projected Sales or Lease'!$B$3:$B$200,$A14,'Projected Sales or Lease'!$L$3:$L$200,"<>X")) -> 16051 | F14: =IF($A14="","",COUNTIFS('Projected Sales or Lease'!$B$3:$B$200,$A14,'Projected Sales or Lease'!$L$3:$L$200,"✔")) -> 0 | G14: =IF($A14="","",SUMIFS('Projected Sales or Lease'!$F$3:$F$200,'Projected Sales or Lease'!$B$3:$B$200,$A14,'Projected Sales or Lease'!$L$3:$L$200,"✔")) -> 0 | H14: =IF($A14="","",$E14-$G14) -> 16051
A15: =IF(Lists!$Q$6="","",Lists!$Q$6) -> Lizbeth | B15: =IF($A15="","",COUNTIFS('Projected Sales or Lease'!$B$3:$B$200,$A15,'Projected Sales or Lease'!$L$3:$L$200,"<>X")) -> 10 | C15: =IF($A15="","",SUMIFS('Projected Sales or Lease'!$F$3:$F$200,'Projected Sales or Lease'!$B$3:$B$200,$A15,'Projected Sales or Lease'!$L$3:$L$200,"<>X",'Projected Sales or Lease'!$J$3:$J$200,"<>Lease")) -> 238090.64 | D15: =IF($A15="","",SUMIFS('Projected Sales or Lease'!$F$3:$F$200,'Projected Sales or Lease'!$B$3:$B$200,$A15,'Projected Sales or Lease'!$L$3:$L$200,"<>X",'Projected Sales or Lease'!$J$3:$J$200,"Lease")) -> 39600 | E15: =IF($A15="","",SUMIFS('Projected Sales or Lease'!$F$3:$F$200,'Projected Sales or Lease'!$B$3:$B$200,$A15,'Projected Sales or Lease'!$L$3:$L$200,"<>X")) -> 277690.64 | F15: =IF($A15="","",COUNTIFS('Projected Sales or Lease'!$B$3:$B$200,$A15,'Projected Sales or Lease'!$L$3:$L$200,"✔")) -> 4 | G15: =IF($A15="","",SUMIFS('Projected Sales or Lease'!$F$3:$F$200,'Projected Sales or Lease'!$B$3:$B$200,$A15,'Projected Sales or Lease'!$L$3:$L$200,"✔")) -> 133008.38 | H15: =IF($A15="","",$E15-$G15) -> 144682.26
A16: =IF(Lists!$Q$7="","",Lists!$Q$7) -> Amanda | B16: =IF($A16="","",COUNTIFS('Projected Sales or Lease'!$B$3:$B$200,$A16,'Projected Sales or Lease'!$L$3:$L$200,"<>X")) -> 12 | C16: =IF($A16="","",SUMIFS('Projected Sales or Lease'!$F$3:$F$200,'Projected Sales or Lease'!$B$3:$B$200,$A16,'Projected Sales or Lease'!$L$3:$L$200,"<>X",'Projected Sales or Lease'!$J$3:$J$200,"<>Lease")) -> 348080.16 | D16: =IF($A16="","",SUMIFS('Projected Sales or Lease'!$F$3:$F$200,'Projected Sales or Lease'!$B$3:$B$200,$A16,'Projected Sales or Lease'!$L$3:$L$200,"<>X",'Projected Sales or Lease'!$J$3:$J$200,"Lease")) -> 15000 | E16: =IF($A16="","",SUMIFS('Projected Sales or Lease'!$F$3:$F$200,'Projected Sales or Lease'!$B$3:$B$200,$A16,'Projected Sales or Lease'!$L$3:$L$200,"<>X")) -> 363080.16 | F16: =IF($A16="","",COUNTIFS('Projected Sales or Lease'!$B$3:$B$200,$A16,'Projected Sales or Lease'!$L$3:$L$200,"✔")) -> 9 | G16: =IF($A16="","",SUMIFS('Projected Sales or Lease'!$F$3:$F$200,'Projected Sales or Lease'!$B$3:$B$200,$A16,'Projected Sales or Lease'!$L$3:$L$200,"✔")) -> 277098.46 | H16: =IF($A16="","",$E16-$G16) -> 85981.7
A17: =IF(Lists!$Q$8="","",Lists!$Q$8) -> Jesus | B17: =IF($A17="","",COUNTIFS('Projected Sales or Lease'!$B$3:$B$200,$A17,'Projected Sales or Lease'!$L$3:$L$200,"<>X")) -> 0 | C17: =IF($A17="","",SUMIFS('Projected Sales or Lease'!$F$3:$F$200,'Projected Sales or Lease'!$B$3:$B$200,$A17,'Projected Sales or Lease'!$L$3:$L$200,"<>X",'Projected Sales or Lease'!$J$3:$J$200,"<>Lease")) -> 0 | D17: =IF($A17="","",SUMIFS('Projected Sales or Lease'!$F$3:$F$200,'Projected Sales or Lease'!$B$3:$B$200,$A17,'Projected Sales or Lease'!$L$3:$L$200,"<>X",'Projected Sales or Lease'!$J$3:$J$200,"Lease")) -> 0 | E17: =IF($A17="","",SUMIFS('Projected Sales or Lease'!$F$3:$F$200,'Projected Sales or Lease'!$B$3:$B$200,$A17,'Projected Sales or Lease'!$L$3:$L$200,"<>X")) -> 0 | F17: =IF($A17="","",COUNTIFS('Projected Sales or Lease'!$B$3:$B$200,$A17,'Projected Sales or Lease'!$L$3:$L$200,"✔")) -> 0 | G17: =IF($A17="","",SUMIFS('Projected Sales or Lease'!$F$3:$F$200,'Projected Sales or Lease'!$B$3:$B$200,$A17,'Projected Sales or Lease'!$L$3:$L$200,"✔")) -> 0 | H17: =IF($A17="","",$E17-$G17) -> 0
A18: =IF(Lists!$Q$9="","",Lists!$Q$9) | B18: =IF($A18="","",COUNTIFS('Projected Sales or Lease'!$B$3:$B$200,$A18,'Projected Sales or Lease'!$L$3:$L$200,"<>X")) | C18: =IF($A18="","",SUMIFS('Projected Sales or Lease'!$F$3:$F$200,'Projected Sales or Lease'!$B$3:$B$200,$A18,'Projected Sales or Lease'!$L$3:$L$200,"<>X",'Projected Sales or Lease'!$J$3:$J$200,"<>Lease")) | D18: =IF($A18="","",SUMIFS('Projected Sales or Lease'!$F$3:$F$200,'Projected Sales or Lease'!$B$3:$B$200,$A18,'Projected Sales or Lease'!$L$3:$L$200,"<>X",'Projected Sales or Lease'!$J$3:$J$200,"Lease")) | E18: =IF($A18="","",SUMIFS('Projected Sales or Lease'!$F$3:$F$200,'Projected Sales or Lease'!$B$3:$B$200,$A18,'Projected Sales or Lease'!$L$3:$L$200,"<>X")) | F18: =IF($A18="","",COUNTIFS('Projected Sales or Lease'!$B$3:$B$200,$A18,'Projected Sales or Lease'!$L$3:$L$200,"✔")) | G18: =IF($A18="","",SUMIFS('Projected Sales or Lease'!$F$3:$F$200,'Projected Sales or Lease'!$B$3:$B$200,$A18,'Projected Sales or Lease'!$L$3:$L$200,"✔")) | H18: =IF($A18="","",$E18-$G18)
A19: =IF(Lists!$Q$10="","",Lists!$Q$10) | B19: =IF($A19="","",COUNTIFS('Projected Sales or Lease'!$B$3:$B$200,$A19,'Projected Sales or Lease'!$L$3:$L$200,"<>X")) | C19: =IF($A19="","",SUMIFS('Projected Sales or Lease'!$F$3:$F$200,'Projected Sales or Lease'!$B$3:$B$200,$A19,'Projected Sales or Lease'!$L$3:$L$200,"<>X",'Projected Sales or Lease'!$J$3:$J$200,"<>Lease")) | D19: =IF($A19="","",SUMIFS('Projected Sales or Lease'!$F$3:$F$200,'Projected Sales or Lease'!$B$3:$B$200,$A19,'Projected Sales or Lease'!$L$3:$L$200,"<>X",'Projected Sales or Lease'!$J$3:$J$200,"Lease")) | E19: =IF($A19="","",SUMIFS('Projected Sales or Lease'!$F$3:$F$200,'Projected Sales or Lease'!$B$3:$B$200,$A19,'Projected Sales or Lease'!$L$3:$L$200,"<>X")) | F19: =IF($A19="","",COUNTIFS('Projected Sales or Lease'!$B$3:$B$200,$A19,'Projected Sales or Lease'!$L$3:$L$200,"✔")) | G19: =IF($A19="","",SUMIFS('Projected Sales or Lease'!$F$3:$F$200,'Projected Sales or Lease'!$B$3:$B$200,$A19,'Projected Sales or Lease'!$L$3:$L$200,"✔")) | H19: =IF($A19="","",$E19-$G19)
A20: =IF(Lists!$Q$11="","",Lists!$Q$11) | B20: =IF($A20="","",COUNTIFS('Projected Sales or Lease'!$B$3:$B$200,$A20,'Projected Sales or Lease'!$L$3:$L$200,"<>X")) | C20: =IF($A20="","",SUMIFS('Projected Sales or Lease'!$F$3:$F$200,'Projected Sales or Lease'!$B$3:$B$200,$A20,'Projected Sales or Lease'!$L$3:$L$200,"<>X",'Projected Sales or Lease'!$J$3:$J$200,"<>Lease")) | D20: =IF($A20="","",SUMIFS('Projected Sales or Lease'!$F$3:$F$200,'Projected Sales or Lease'!$B$3:$B$200,$A20,'Projected Sales or Lease'!$L$3:$L$200,"<>X",'Projected Sales or Lease'!$J$3:$J$200,"Lease")) | E20: =IF($A20="","",SUMIFS('Projected Sales or Lease'!$F$3:$F$200,'Projected Sales or Lease'!$B$3:$B$200,$A20,'Projected Sales or Lease'!$L$3:$L$200,"<>X")) | F20: =IF($A20="","",COUNTIFS('Projected Sales or Lease'!$B$3:$B$200,$A20,'Projected Sales or Lease'!$L$3:$L$200,"✔")) | G20: =IF($A20="","",SUMIFS('Projected Sales or Lease'!$F$3:$F$200,'Projected Sales or Lease'!$B$3:$B$200,$A20,'Projected Sales or Lease'!$L$3:$L$200,"✔")) | H20: =IF($A20="","",$E20-$G20)
A21: =IF(Lists!$Q$12="","",Lists!$Q$12) | B21: =IF($A21="","",COUNTIFS('Projected Sales or Lease'!$B$3:$B$200,$A21,'Projected Sales or Lease'!$L$3:$L$200,"<>X")) | C21: =IF($A21="","",SUMIFS('Projected Sales or Lease'!$F$3:$F$200,'Projected Sales or Lease'!$B$3:$B$200,$A21,'Projected Sales or Lease'!$L$3:$L$200,"<>X",'Projected Sales or Lease'!$J$3:$J$200,"<>Lease")) | D21: =IF($A21="","",SUMIFS('Projected Sales or Lease'!$F$3:$F$200,'Projected Sales or Lease'!$B$3:$B$200,$A21,'Projected Sales or Lease'!$L$3:$L$200,"<>X",'Projected Sales or Lease'!$J$3:$J$200,"Lease")) | E21: =IF($A21="","",SUMIFS('Projected Sales or Lease'!$F$3:$F$200,'Projected Sales or Lease'!$B$3:$B$200,$A21,'Projected Sales or Lease'!$L$3:$L$200,"<>X")) | F21: =IF($A21="","",COUNTIFS('Projected Sales or Lease'!$B$3:$B$200,$A21,'Projected Sales or Lease'!$L$3:$L$200,"✔")) | G21: =IF($A21="","",SUMIFS('Projected Sales or Lease'!$F$3:$F$200,'Projected Sales or Lease'!$B$3:$B$200,$A21,'Projected Sales or Lease'!$L$3:$L$200,"✔")) | H21: =IF($A21="","",$E21-$G21)
A22: =IF(Lists!$Q$13="","",Lists!$Q$13) | B22: =IF($A22="","",COUNTIFS('Projected Sales or Lease'!$B$3:$B$200,$A22,'Projected Sales or Lease'!$L$3:$L$200,"<>X")) | C22: =IF($A22="","",SUMIFS('Projected Sales or Lease'!$F$3:$F$200,'Projected Sales or Lease'!$B$3:$B$200,$A22,'Projected Sales or Lease'!$L$3:$L$200,"<>X",'Projected Sales or Lease'!$J$3:$J$200,"<>Lease")) | D22: =IF($A22="","",SUMIFS('Projected Sales or Lease'!$F$3:$F$200,'Projected Sales or Lease'!$B$3:$B$200,$A22,'Projected Sales or Lease'!$L$3:$L$200,"<>X",'Projected Sales or Lease'!$J$3:$J$200,"Lease")) | E22: =IF($A22="","",SUMIFS('Projected Sales or Lease'!$F$3:$F$200,'Projected Sales or Lease'!$B$3:$B$200,$A22,'Projected Sales or Lease'!$L$3:$L$200,"<>X")) | F22: =IF($A22="","",COUNTIFS('Projected Sales or Lease'!$B$3:$B$200,$A22,'Projected Sales or Lease'!$L$3:$L$200,"✔")) | G22: =IF($A22="","",SUMIFS('Projected Sales or Lease'!$F$3:$F$200,'Projected Sales or Lease'!$B$3:$B$200,$A22,'Projected Sales or Lease'!$L$3:$L$200,"✔")) | H22: =IF($A22="","",$E22-$G22)
A23: =IF(Lists!$Q$14="","",Lists!$Q$14) | B23: =IF($A23="","",COUNTIFS('Projected Sales or Lease'!$B$3:$B$200,$A23,'Projected Sales or Lease'!$L$3:$L$200,"<>X")) | C23: =IF($A23="","",SUMIFS('Projected Sales or Lease'!$F$3:$F$200,'Projected Sales or Lease'!$B$3:$B$200,$A23,'Projected Sales or Lease'!$L$3:$L$200,"<>X",'Projected Sales or Lease'!$J$3:$J$200,"<>Lease")) | D23: =IF($A23="","",SUMIFS('Projected Sales or Lease'!$F$3:$F$200,'Projected Sales or Lease'!$B$3:$B$200,$A23,'Projected Sales or Lease'!$L$3:$L$200,"<>X",'Projected Sales or Lease'!$J$3:$J$200,"Lease")) | E23: =IF($A23="","",SUMIFS('Projected Sales or Lease'!$F$3:$F$200,'Projected Sales or Lease'!$B$3:$B$200,$A23,'Projected Sales or Lease'!$L$3:$L$200,"<>X")) | F23: =IF($A23="","",COUNTIFS('Projected Sales or Lease'!$B$3:$B$200,$A23,'Projected Sales or Lease'!$L$3:$L$200,"✔")) | G23: =IF($A23="","",SUMIFS('Projected Sales or Lease'!$F$3:$F$200,'Projected Sales or Lease'!$B$3:$B$200,$A23,'Projected Sales or Lease'!$L$3:$L$200,"✔")) | H23: =IF($A23="","",$E23-$G23)
A24: =IF(Lists!$Q$15="","",Lists!$Q$15) | B24: =IF($A24="","",COUNTIFS('Projected Sales or Lease'!$B$3:$B$200,$A24,'Projected Sales or Lease'!$L$3:$L$200,"<>X")) | C24: =IF($A24="","",SUMIFS('Projected Sales or Lease'!$F$3:$F$200,'Projected Sales or Lease'!$B$3:$B$200,$A24,'Projected Sales or Lease'!$L$3:$L$200,"<>X",'Projected Sales or Lease'!$J$3:$J$200,"<>Lease")) | D24: =IF($A24="","",SUMIFS('Projected Sales or Lease'!$F$3:$F$200,'Projected Sales or Lease'!$B$3:$B$200,$A24,'Projected Sales or Lease'!$L$3:$L$200,"<>X",'Projected Sales or Lease'!$J$3:$J$200,"Lease")) | E24: =IF($A24="","",SUMIFS('Projected Sales or Lease'!$F$3:$F$200,'Projected Sales or Lease'!$B$3:$B$200,$A24,'Projected Sales or Lease'!$L$3:$L$200,"<>X")) | F24: =IF($A24="","",COUNTIFS('Projected Sales or Lease'!$B$3:$B$200,$A24,'Projected Sales or Lease'!$L$3:$L$200,"✔")) | G24: =IF($A24="","",SUMIFS('Projected Sales or Lease'!$F$3:$F$200,'Projected Sales or Lease'!$B$3:$B$200,$A24,'Projected Sales or Lease'!$L$3:$L$200,"✔")) | H24: =IF($A24="","",$E24-$G24)
A25: =IF(Lists!$Q$16="","",Lists!$Q$16) | B25: =IF($A25="","",COUNTIFS('Projected Sales or Lease'!$B$3:$B$200,$A25,'Projected Sales or Lease'!$L$3:$L$200,"<>X")) | C25: =IF($A25="","",SUMIFS('Projected Sales or Lease'!$F$3:$F$200,'Projected Sales or Lease'!$B$3:$B$200,$A25,'Projected Sales or Lease'!$L$3:$L$200,"<>X",'Projected Sales or Lease'!$J$3:$J$200,"<>Lease")) | D25: =IF($A25="","",SUMIFS('Projected Sales or Lease'!$F$3:$F$200,'Projected Sales or Lease'!$B$3:$B$200,$A25,'Projected Sales or Lease'!$L$3:$L$200,"<>X",'Projected Sales or Lease'!$J$3:$J$200,"Lease")) | E25: =IF($A25="","",SUMIFS('Projected Sales or Lease'!$F$3:$F$200,'Projected Sales or Lease'!$B$3:$B$200,$A25,'Projected Sales or Lease'!$L$3:$L$200,"<>X")) | F25: =IF($A25="","",COUNTIFS('Projected Sales or Lease'!$B$3:$B$200,$A25,'Projected Sales or Lease'!$L$3:$L$200,"✔")) | G25: =IF($A25="","",SUMIFS('Projected Sales or Lease'!$F$3:$F$200,'Projected Sales or Lease'!$B$3:$B$200,$A25,'Projected Sales or Lease'!$L$3:$L$200,"✔")) | H25: =IF($A25="","",$E25-$G25)
A26: (No producer / not on list) | B26: =COUNTIFS('Projected Sales or Lease'!$A$3:$A$200,"<>",'Projected Sales or Lease'!$L$3:$L$200,"<>X")-SUM(B11:B25) -> 2 | C26: =SUMIFS('Projected Sales or Lease'!$F$3:$F$200,'Projected Sales or Lease'!$A$3:$A$200,"<>",'Projected Sales or Lease'!$L$3:$L$200,"<>X",'Projected Sales or Lease'!$J$3:$J$200,"<>Lease")-SUM(C11:C25) -> 0 | D26: =SUMIFS('Projected Sales or Lease'!$F$3:$F$200,'Projected Sales or Lease'!$A$3:$A$200,"<>",'Projected Sales or Lease'!$L$3:$L$200,"<>X",'Projected Sales or Lease'!$J$3:$J$200,"Lease")-SUM(D11:D25) -> 0 | E26: =SUMIFS('Projected Sales or Lease'!$F$3:$F$200,'Projected Sales or Lease'!$A$3:$A$200,"<>",'Projected Sales or Lease'!$L$3:$L$200,"<>X")-SUM(E11:E25) -> 0 | F26: =COUNTIFS('Projected Sales or Lease'!$L$3:$L$200,"✔")-SUM(F11:F25) -> 0 | G26: =SUMIFS('Projected Sales or Lease'!$F$3:$F$200,'Projected Sales or Lease'!$L$3:$L$200,"✔")-SUM(G11:G25) -> 0 | H26: =$E26-$G26 -> 0
A27: TOTAL | B27: =SUM(B11:B26) -> 29 | C27: =SUM(C11:C26) -> 626174.88 | D27: =SUM(D11:D26) -> 114328.4 | E27: =SUM(E11:E26) -> 740503.28 | F27: =SUM(F11:F26) -> 15 | G27: =SUM(G11:G26) -> 453859.92 | H27: =SUM(H11:H26) -> 286643.36
A30: BY PAYMENT TERMS | E30: DEAL PROGRESS (active + completed)
A31: Payment Terms | B31: # Deals | C31: Amount $ | E31: Stage | F31: # Deals | G31: Amount $
A32: =Lists!$R$2 -> Payment Plan | B32: =COUNTIFS('Projected Sales or Lease'!$J$3:$J$200,$A32,'Projected Sales or Lease'!$L$3:$L$200,"<>X") -> 2 | C32: =SUMIFS('Projected Sales or Lease'!$F$3:$F$200,'Projected Sales or Lease'!$J$3:$J$200,$A32,'Projected Sales or Lease'!$L$3:$L$200,"<>X") -> 118616.06 | E32: Good to Order ✔ | F32: =COUNTIFS('Projected Sales or Lease'!$G$3:$G$200,"✔",'Projected Sales or Lease'!$L$3:$L$200,"<>X") -> 22 | G32: =SUMIFS('Projected Sales or Lease'!$F$3:$F$200,'Projected Sales or Lease'!$G$3:$G$200,"✔",'Projected Sales or Lease'!$L$3:$L$200,"<>X") -> 614521.86
A33: =Lists!$R$3 -> 50% Down + 50% upon install/30 days after | B33: =COUNTIFS('Projected Sales or Lease'!$J$3:$J$200,$A33,'Projected Sales or Lease'!$L$3:$L$200,"<>X") -> 4 | C33: =SUMIFS('Projected Sales or Lease'!$F$3:$F$200,'Projected Sales or Lease'!$J$3:$J$200,$A33,'Projected Sales or Lease'!$L$3:$L$200,"<>X") -> 73322.28 | E33: Equipment Ordered ✔ | F33: =COUNTIFS('Projected Sales or Lease'!$H$3:$H$200,"✔",'Projected Sales or Lease'!$L$3:$L$200,"<>X") -> 21 | G33: =SUMIFS('Projected Sales or Lease'!$F$3:$F$200,'Projected Sales or Lease'!$H$3:$H$200,"✔",'Projected Sales or Lease'!$L$3:$L$200,"<>X") -> 594721.86
A34: =Lists!$R$4 -> Lease | B34: =COUNTIFS('Projected Sales or Lease'!$J$3:$J$200,$A34,'Projected Sales or Lease'!$L$3:$L$200,"<>X") -> 6 | C34: =SUMIFS('Projected Sales or Lease'!$F$3:$F$200,'Projected Sales or Lease'!$J$3:$J$200,$A34,'Projected Sales or Lease'!$L$3:$L$200,"<>X") -> 114328.4 | E34: Deal Complete ✔ | F34: =COUNTIFS('Projected Sales or Lease'!$L$3:$L$200,"✔") -> 15 | G34: =SUMIFS('Projected Sales or Lease'!$F$3:$F$200,'Projected Sales or Lease'!$L$3:$L$200,"✔") -> 453859.92
A35: =Lists!$R$5 -> Paid in Full | B35: =COUNTIFS('Projected Sales or Lease'!$J$3:$J$200,$A35,'Projected Sales or Lease'!$L$3:$L$200,"<>X") -> 11 | C35: =SUMIFS('Projected Sales or Lease'!$F$3:$F$200,'Projected Sales or Lease'!$J$3:$J$200,$A35,'Projected Sales or Lease'!$L$3:$L$200,"<>X") -> 318255.12
A36: (Not set) | B36: =COUNTIFS('Projected Sales or Lease'!$A$3:$A$200,"<>",'Projected Sales or Lease'!$J$3:$J$200,"=",'Projected Sales or Lease'!$L$3:$L$200,"<>X") -> 6 | C36: =SUMIFS('Projected Sales or Lease'!$F$3:$F$200,'Projected Sales or Lease'!$A$3:$A$200,"<>",'Projected Sales or Lease'!$J$3:$J$200,"=",'Projected Sales or Lease'!$L$3:$L$200,"<>X") -> 115981.42

Sheet Projected Sales or Lease
A1: PROJECTED SALES OR LEASE | E1: Sales team: one row per deal — see the SOP tab for full instructions. Account Type flags Avi/Richard accounts. Deal Completion: ✔ = finalized (row turns green + deal auto-copies to the Installs tab) · X = fell through (row turns red, excluded from Dashboard).
A2: Customer Name | B2: Producer | C2: Account Type | D2: Date of Deal | E2: Equipment | F2: Equipment Deal Amount ($) | G2: Good to Order ✔ | H2: Equipment Ordered ✔ | I2: Equipment ETA | J2: Payment Terms | K2: Invoice # | L2: Deal Completion | M2: Notes | N2: new? | O2: rank
A3: Truffle & Rye | B3: Amanda | E3: La Marz GS3, jay grinder | F3: 11118.85 | G3: ✔ | H3: ✔ | I3: Here | J3: Paid in Full | K3: 740831 | L3: ✔ | M3: Waiting on broker to ship to Turks for final amount | N3: =IF(AND($L3="✔",$A3<>"",COUNTIF(Installs!$B$5:$B$159,$A3)=0),1,0) -> 1 | O3: =IF($N3=1,SUM($N$3:$N3),"") -> 1
A4: Jonathan's The Rub - Bridgeland | B4: Amanda | C4: Avi Account | E4: Cameo c'2s | F4: 22151.26 | G4: ✔ | H4: ✔ | I4: Installed | J4: Payment Plan | K4: 734302 | L4: ✔ | N4: =IF(AND($L4="✔",$A4<>"",COUNTIF(Installs!$B$5:$B$159,$A4)=0),1,0) -> 1 | O4: =IF($N4=1,SUM($N$3:$N4),"") -> 2
A5: Coco Crepe Elyson Town Center | B5: Lizbeth | E5: Eversys Enigma e'4s Classic | F5: 37611.26 | G5: ✔ | H5: ✔ | J5: Paid in Full | K5: 745528 | M5: Still under remodel | N5: =IF(AND($L5="✔",$A5<>"",COUNTIF(Installs!$B$5:$B$159,$A5)=0),1,0) -> 0 | O5: =IF($N5=1,SUM($N$3:$N5),"")
A6: Valentinas Coffee | B6: Lizbeth | E6: La Marzocco Strada XT 2 Group, Mazzer ZM Filter Grinder - Black, Mazzer Robur S Electronic, Puqpress Q2 Automatic Tamper BLACK, Everpure EZ-RO 200/10 Gallon Hydropneumatic Tank, Blendtec Stealth 885, Blendtec Rapid Rinse Station | F6: 49601.19 | G6: ✔ | H6: ✔ | J6: Paid in Full | K6: 754770 754497 749838 | L6: ✔ | M6: Special order. Waiting on ETA from LM. | N6: =IF(AND($L6="✔",$A6<>"",COUNTIF(Installs!$B$5:$B$159,$A6)=0),1,0) -> 1 | O6: =IF($N6=1,SUM($N$3:$N6),"") -> 3
A7: El toro tex mex | B7: Lizbeth | C7: Avi Account | E7: Eversys e'4 | F7: 35000 | M7: Working on getting out of Coca Cola Lease | N7: =IF(AND($L7="✔",$A7<>"",COUNTIF(Installs!$B$5:$B$159,$A7)=0),1,0) -> 0 | O7: =IF($N7=1,SUM($N$3:$N7),"")
A8: Ciao Bella Bakery | N8: =IF(AND($L8="✔",$A8<>"",COUNTIF(Installs!$B$5:$B$159,$A8)=0),1,0) -> 0 | O8: =IF($N8=1,SUM($N$3:$N8),"")
A9: Work Around Café | B9: Amanda | E9: strada s 2 gr, jay, mahl ek43, mahl e65, fetco 1251, itbdd, puq | F9: 49930.42 | N9: =IF(AND($L9="✔",$A9<>"",COUNTIF(Installs!$B$5:$B$159,$A9)=0),1,0) -> 0 | O9: =IF($N9=1,SUM($N$3:$N9),"")
A10: Coco Crepe Bellaire | B10: Lizbeth | E10: La Marzocco Linea Classic S 2 Group AV & La Marzocco Swift Dual-Hopper Espresso Grinder | F10: 27271 | G10: ✔ | H10: ✔ | I10: Here | J10: 50% Down + 50% upon install/30 days after | K10: 746261 | N10: =IF(AND($L10="✔",$A10<>"",COUNTIF(Installs!$B$5:$B$159,$A10)=0),1,0) -> 0 | O10: =IF($N10=1,SUM($N$3:$N10),"")
A11: Local Foods - ATX #2 | B11: Amanda | E11: La Marzocco Linea Classic S 2 Group AV & La Marzocco Swift Dual-Hopper Espresso Grinder, Fetco 1251, ITB-DD EZRO200 | F11: 31902 | G11: ✔ | H11: ✔ | I11: Here | J11: Paid in Full | K11: 746493 | L11: ✔ | N11: =IF(AND($L11="✔",$A11<>"",COUNTIF(Installs!$B$5:$B$159,$A11)=0),1,0) -> 0 | O11: =IF($N11=1,SUM($N$3:$N11),"")
A12: Bella Flori | N12: =IF(AND($L12="✔",$A12<>"",COUNTIF(Installs!$B$5:$B$159,$A12)=0),1,0) -> 0 | O12: =IF($N12=1,SUM($N$3:$N12),"")
A13: Luzia Coffee Shop | B13: Lizbeth | E13: Invicta 3GR, Robur S E, Puqpress | F13: 26089.52 | G13: ✔ | H13: ✔ | I13: Installed | J13: Paid in Full | K13: 748258 | L13: ✔ | M13: Pending Down Payment | N13: =IF(AND($L13="✔",$A13<>"",COUNTIF(Installs!$B$5:$B$159,$A13)=0),1,0) -> 0 | O13: =IF($N13=1,SUM($N$3:$N13),"")
A14: The Audrey Restaurant & Bar Post Oak | B14: Lizbeth | E14: Eversys Cameo c'2s | F14: 19800 | G14: ✔ | H14: ✔ | I14: Installed | J14: Lease | L14: ✔ | N14: =IF(AND($L14="✔",$A14<>"",COUNTIF(Installs!$B$5:$B$159,$A14)=0),1,0) -> 1 | O14: =IF($N14=1,SUM($N$3:$N14),"") -> 4
A15: Lakewood Yacht Club | B15: Lizbeth | C15: Avi Account | E15: Eversys Cameo c'2s | F15: 19800 | G15: ✔ | J15: Lease | N15: =IF(AND($L15="✔",$A15<>"",COUNTIF(Installs!$B$5:$B$159,$A15)=0),1,0) -> 0 | O15: =IF($N15=1,SUM($N$3:$N15),"")
A16: Common Bond Spring | B16: Amanda | C16: Avi Account | E16: 2 x e4s with 1.5 wands SN: 0110710025266E0006 Fetco 1252 Plus SN: 1252UB23015260303 Bunn ITB-DD SN: ITB0065171 Fetco GRS1202 SN:12021A00020259710 | F16: 96464.8 | G16: ✔ | H16: ✔ | I16: Installed | J16: Payment Plan | K16: 749148 | L16: ✔ | N16: =IF(AND($L16="✔",$A16<>"",COUNTIF(Installs!$B$5:$B$159,$A16)=0),1,0) -> 0 | O16: =IF($N16=1,SUM($N$3:$N16),"")
A17: CoPlay Cove | B17: Lizbeth | E17: e4s SN: 0110700025150E0012 | F17: 37517.67 | G17: ✔ | H17: ✔ | I17: Installed | J17: Paid in Full | K17: 735103 | L17: ✔ | N17: =IF(AND($L17="✔",$A17<>"",COUNTIF(Installs!$B$5:$B$159,$A17)=0),1,0) -> 0 | O17: =IF($N17=1,SUM($N$3:$N17),"")
A18: Sunrise Coffee | B18: Amanda | E18: Linea S 2 Group SN:LS029320 Mazzer Super Jolly SN:2540764 | F18: 21043.39 | G18: ✔ | H18: ✔ | I18: Installed | J18: Paid in Full | K18: 751629 | L18: ✔ | N18: =IF(AND($L18="✔",$A18<>"",COUNTIF(Installs!$B$5:$B$159,$A18)=0),1,0) -> 0 | O18: =IF($N18=1,SUM($N$3:$N18),"")
A19: Latte Cafe - La Grange | B19: Amanda | E19: Rancilio Classe 9 | F19: 14018.16 | G19: ✔ | H19: ✔ | I19: Installed | J19: Paid in Full | K19: 752128 | L19: ✔ | N19: =IF(AND($L19="✔",$A19<>"",COUNTIF(Installs!$B$5:$B$159,$A19)=0),1,0) -> 0 | O19: =IF($N19=1,SUM($N$3:$N19),"")
A20: Taha Market Mediterranean Foods | B20: Sean | E20: Eversys Cameo c'2s | F20: 19800 | G20: ✔ | H20: ✔ | I20: Installed | J20: Lease | K20: X | L20: ✔ | N20: =IF(AND($L20="✔",$A20<>"",COUNTIF(Installs!$B$5:$B$159,$A20)=0),1,0) -> 0 | O20: =IF($N20=1,SUM($N$3:$N20),"")
A21: Clover | B21: Amanda | E21: Eversys e'4s | F21: 35400 | G21: ✔ | H21: ✔ | I21: Installed | J21: Paid in Full | K21: 754732 | L21: ✔ | N21: =IF(AND($L21="✔",$A21<>"",COUNTIF(Installs!$B$5:$B$159,$A21)=0),1,0) -> 0 | O21: =IF($N21=1,SUM($N$3:$N21),"")
A22: Parkwood American Grille | B22: Amanda | C22: Avi Account | E22: Eversys Legacy | F22: 16051.28 | G22: ✔ | H22: ✔ | I22: Mid-August | J22: 50% Down + 50% upon install/30 days after | K22: 756106 | M22: Will need Cameo until Legacycomes in. | N22: =IF(AND($L22="✔",$A22<>"",COUNTIF(Installs!$B$5:$B$159,$A22)=0),1,0) -> 0 | O22: =IF($N22=1,SUM($N$3:$N22),"")
A23: Uchi - Houston | B23: Shannon | E23: Eversys Legacy | F23: 16051 | M23: Will use loaner Legacy unit trial is over | N23: =IF(AND($L23="✔",$A23<>"",COUNTIF(Installs!$B$5:$B$159,$A23)=0),1,0) -> 0 | O23: =IF($N23=1,SUM($N$3:$N23),"")
A24: Brews & Books | B24: Lance | E24: Eversys Cameo c'2s | F24: 23953.08 | G24: ✔ | H24: ✔ | I24: 45121 | J24: Paid in Full | K24: 755161 | L24: ✔ | N24: =IF(AND($L24="✔",$A24<>"",COUNTIF(Installs!$B$5:$B$159,$A24)=0),1,0) -> 1 | O24: =IF($N24=1,SUM($N$3:$N24),"") -> 5
A25: Riot Comedy Club | B25: Sean | E25: Rancilio Classe 5 Compact, Mazzer SJ E, Mazzer Mini E | F25: 11128.4 | G25: ✔ | H25: ✔ | I25: Here | J25: Lease | M25: Tentative install date 7/28 earliest. | N25: =IF(AND($L25="✔",$A25<>"",COUNTIF(Installs!$B$5:$B$159,$A25)=0),1,0) -> 0 | O25: =IF($N25=1,SUM($N$3:$N25),"")
A26: Osso & Kristalla | B26: Sean | C26: Avi Account | E26: Everysys E'4 | F26: 28800 | G26: ✔ | H26: ✔ | J26: Lease | M26: Will be month to month, $800/mo | N26: =IF(AND($L26="✔",$A26<>"",COUNTIF(Installs!$B$5:$B$159,$A26)=0),1,0) -> 0 | O26: =IF($N26=1,SUM($N$3:$N26),"")
A27: bloom chica brew | B27: Amanda | E27: linea classic, jay grinder | F27: 30000 | G27: ✔ | H27: ✔ | J27: Paid in Full | K27: 743957 | L27: ✔ | M27: 3rd party installation | N27: =IF(AND($L27="✔",$A27<>"",COUNTIF(Installs!$B$5:$B$159,$A27)=0),1,0) -> 0 | O27: =IF($N27=1,SUM($N$3:$N27),"")
A28: kol fac 118 | B28: Amanda | E28: cameo c'2s | F28: 20000 | G28: ✔ | H28: ✔ | J28: 50% Down + 50% upon install/30 days after | K28: 756855 | N28: =IF(AND($L28="✔",$A28<>"",COUNTIF(Installs!$B$5:$B$159,$A28)=0),1,0) -> 0 | O28: =IF($N28=1,SUM($N$3:$N28),"")
A29: petroleum club | B29: Amanda | C29: Avi Account | E29: cameo c'2s | F29: 15000 | G29: ✔ | H29: ✔ | I29: ready | J29: Lease | L29: ✔ | N29: =IF(AND($L29="✔",$A29<>"",COUNTIF(Installs!$B$5:$B$159,$A29)=0),1,0) -> 0 | O29: =IF($N29=1,SUM($N$3:$N29),"")
A30: Vam Foods #2 | B30: Lizbeth | E30: Bravilor Sego 12 120V | F30: 10000 | J30: 50% Down + 50% upon install/30 days after | M30: Waiting for approval on purchase | N30: =IF(AND($L30="✔",$A30<>"",COUNTIF(Installs!$B$5:$B$159,$A30)=0),1,0) -> 0 | O30: =IF($N30=1,SUM($N$3:$N30),"")
A31: Mexico Lindo Bakery | B31: Lizbeth | E31: Rancilio Classe 5 USB 2 Group Auto-Volumetric | F31: 15000 | N31: =IF(AND($L31="✔",$A31<>"",COUNTIF(Installs!$B$5:$B$159,$A31)=0),1,0) -> 0 | O31: =IF($N31=1,SUM($N$3:$N31),"")
N32: =IF(AND($L32="✔",$A32<>"",COUNTIF(Installs!$B$5:$B$159,$A32)=0),1,0) -> 0 | O32: =IF($N32=1,SUM($N$3:$N32),"")
N33: =IF(AND($L33="✔",$A33<>"",COUNTIF(Installs!$B$5:$B$159,$A33)=0),1,0) -> 0 | O33: =IF($N33=1,SUM($N$3:$N33),"")
N34: =IF(AND($L34="✔",$A34<>"",COUNTIF(Installs!$B$5:$B$159,$A34)=0),1,0) -> 0 | O34: =IF($N34=1,SUM($N$3:$N34),"")
N35: =IF(AND($L35="✔",$A35<>"",COUNTIF(Installs!$B$5:$B$159,$A35)=0),1,0) -> 0 | O35: =IF($N35=1,SUM($N$3:$N35),"")
N36: =IF(AND($L36="✔",$A36<>"",COUNTIF(Installs!$B$5:$B$159,$A36)=0),1,0) -> 0 | O36: =IF($N36=1,SUM($N$3:$N36),"")
N37: =IF(AND($L37="✔",$A37<>"",COUNTIF(Installs!$B$5:$B$159,$A37)=0),1,0) -> 0 | O37: =IF($N37=1,SUM($N$3:$N37),"")
N38: =IF(AND($L38="✔",$A38<>"",COUNTIF(Installs!$B$5:$B$159,$A38)=0),1,0) -> 0 | O38: =IF($N38=1,SUM($N$3:$N38),"")
N39: =IF(AND($L39="✔",$A39<>"",COUNTIF(Installs!$B$5:$B$159,$A39)=0),1,0) -> 0 | O39: =IF($N39=1,SUM($N$3:$N39),"")
N40: =IF(AND($L40="✔",$A40<>"",COUNTIF(Installs!$B$5:$B$159,$A40)=0),1,0) -> 0 | O40: =IF($N40=1,SUM($N$3:$N40),"")
...

Sheet Install Clock
A1: ⏱ INSTALL CLOCK
A2: ← Back to the Installation Tracker | C2: Everything here is read-only and recalculates on open. Fix things on the Installs tab.
A4: Today | B4: This week (Mon–Sun) | C4: Next week | D4: ⚠ Equipment NOT ready | E4: ⚠ Past due & not ready | F4: ⚠ Customer not ready | G4: Completed installs | H4: In queue (not yet installed)
A5: =TODAY() -> 46254 | B5: =TEXT(Installs!$P$3,"m/d")&" – "&TEXT(Installs!$P$4,"m/d") -> 8/17 – 8/23 | C5: =TEXT(Installs!$P$3+7,"m/d")&" – "&TEXT(Installs!$P$5,"m/d") -> 8/24 – 8/30 | D5: =COUNTIF(Installs!$M$5:$M$200,"⚠ EQUIP NOT READY") -> 0 | E5: =COUNTIF(Installs!$M$5:$M$200,"⚠ PAST DUE - NOT READY") -> 0 | F5: =COUNTIF(Installs!$M$5:$M$200,"⚠ CUSTOMER NOT READY") -> 0 | G5: =COUNTIF(Installs!$D$5:$D$200,"Installed") -> 41 | H5: =COUNTIF(Installs!$O$5:$O$200,"<999999999") -> 13
A7: ⚠ AT RISK NOW — scheduled this week or next (or already past due) and not ready
A8: # | B8: Account | C8: Why it's flagged | D8: Equip Status | E8: Install Date | F8: Assigned Tech | G8: Work Order | H8: Requirements
A9: =IF($P9="","",1) | B9: =IF($P9="","",IFERROR(IF(INDEX(Installs!$B$1:$B$200,$P9)="","",INDEX(Installs!$B$1:$B$200,$P9)),"")) | C9: =IF($P9="","",IFERROR(IF(INDEX(Installs!$M$1:$M$200,$P9)="","",INDEX(Installs!$M$1:$M$200,$P9)),"")) | D9: =IF($P9="","",IFERROR(IF(INDEX(Installs!$D$1:$D$200,$P9)="","",INDEX(Installs!$D$1:$D$200,$P9)),"")) | E9: =IF($P9="","",IFERROR(IF(INDEX(Installs!$E$1:$E$200,$P9)="","",INDEX(Installs!$E$1:$E$200,$P9)),"")) | F9: =IF($P9="","",IFERROR(IF(INDEX(Installs!$F$1:$F$200,$P9)="","",INDEX(Installs!$F$1:$F$200,$P9)),"")) | G9: =IF($P9="","",IFERROR(IF(INDEX(Installs!$G$1:$G$200,$P9)="","",INDEX(Installs!$G$1:$G$200,$P9)),"")) | H9: =IF($P9="","",IFERROR(IF(INDEX(Installs!$H$1:$H$200,$P9)="","",INDEX(Installs!$H$1:$H$200,$P9)),"")) | P9: =IFERROR(MATCH(1,Installs!$R$5:$R$200,0)+4,"")
A10: =IF($P10="","",2) | B10: =IF($P10="","",IFERROR(IF(INDEX(Installs!$B$1:$B$200,$P10)="","",INDEX(Installs!$B$1:$B$200,$P10)),"")) | C10: =IF($P10="","",IFERROR(IF(INDEX(Installs!$M$1:$M$200,$P10)="","",INDEX(Installs!$M$1:$M$200,$P10)),"")) | D10: =IF($P10="","",IFERROR(IF(INDEX(Installs!$D$1:$D$200,$P10)="","",INDEX(Installs!$D$1:$D$200,$P10)),"")) | E10: =IF($P10="","",IFERROR(IF(INDEX(Installs!$E$1:$E$200,$P10)="","",INDEX(Installs!$E$1:$E$200,$P10)),"")) | F10: =IF($P10="","",IFERROR(IF(INDEX(Installs!$F$1:$F$200,$P10)="","",INDEX(Installs!$F$1:$F$200,$P10)),"")) | G10: =IF($P10="","",IFERROR(IF(INDEX(Installs!$G$1:$G$200,$P10)="","",INDEX(Installs!$G$1:$G$200,$P10)),"")) | H10: =IF($P10="","",IFERROR(IF(INDEX(Installs!$H$1:$H$200,$P10)="","",INDEX(Installs!$H$1:$H$200,$P10)),"")) | P10: =IFERROR(MATCH(2,Installs!$R$5:$R$200,0)+4,"")
A11: =IF($P11="","",3) | B11: =IF($P11="","",IFERROR(IF(INDEX(Installs!$B$1:$B$200,$P11)="","",INDEX(Installs!$B$1:$B$200,$P11)),"")) | C11: =IF($P11="","",IFERROR(IF(INDEX(Installs!$M$1:$M$200,$P11)="","",INDEX(Installs!$M$1:$M$200,$P11)),"")) | D11: =IF($P11="","",IFERROR(IF(INDEX(Installs!$D$1:$D$200,$P11)="","",INDEX(Installs!$D$1:$D$200,$P11)),"")) | E11: =IF($P11="","",IFERROR(IF(INDEX(Installs!$E$1:$E$200,$P11)="","",INDEX(Installs!$E$1:$E$200,$P11)),"")) | F11: =IF($P11="","",IFERROR(IF(INDEX(Installs!$F$1:$F$200,$P11)="","",INDEX(Installs!$F$1:$F$200,$P11)),"")) | G11: =IF($P11="","",IFERROR(IF(INDEX(Installs!$G$1:$G$200,$P11)="","",INDEX(Installs!$G$1:$G$200,$P11)),"")) | H11: =IF($P11="","",IFERROR(IF(INDEX(Installs!$H$1:$H$200,$P11)="","",INDEX(Installs!$H$1:$H$200,$P11)),"")) | P11: =IFERROR(MATCH(3,Installs!$R$5:$R$200,0)+4,"")
A12: =IF($P12="","",4) | B12: =IF($P12="","",IFERROR(IF(INDEX(Installs!$B$1:$B$200,$P12)="","",INDEX(Installs!$B$1:$B$200,$P12)),"")) | C12: =IF($P12="","",IFERROR(IF(INDEX(Installs!$M$1:$M$200,$P12)="","",INDEX(Installs!$M$1:$M$200,$P12)),"")) | D12: =IF($P12="","",IFERROR(IF(INDEX(Installs!$D$1:$D$200,$P12)="","",INDEX(Installs!$D$1:$D$200,$P12)),"")) | E12: =IF($P12="","",IFERROR(IF(INDEX(Installs!$E$1:$E$200,$P12)="","",INDEX(Installs!$E$1:$E$200,$P12)),"")) | F12: =IF($P12="","",IFERROR(IF(INDEX(Installs!$F$1:$F$200,$P12)="","",INDEX(Installs!$F$1:$F$200,$P12)),"")) | G12: =IF($P12="","",IFERROR(IF(INDEX(Installs!$G$1:$G$200,$P12)="","",INDEX(Installs!$G$1:$G$200,$P12)),"")) | H12: =IF($P12="","",IFERROR(IF(INDEX(Installs!$H$1:$H$200,$P12)="","",INDEX(Installs!$H$1:$H$200,$P12)),"")) | P12: =IFERROR(MATCH(4,Installs!$R$5:$R$200,0)+4,"")
A13: =IF($P13="","",5) | B13: =IF($P13="","",IFERROR(IF(INDEX(Installs!$B$1:$B$200,$P13)="","",INDEX(Installs!$B$1:$B$200,$P13)),"")) | C13: =IF($P13="","",IFERROR(IF(INDEX(Installs!$M$1:$M$200,$P13)="","",INDEX(Installs!$M$1:$M$200,$P13)),"")) | D13: =IF($P13="","",IFERROR(IF(INDEX(Installs!$D$1:$D$200,$P13)="","",INDEX(Installs!$D$1:$D$200,$P13)),"")) | E13: =IF($P13="","",IFERROR(IF(INDEX(Installs!$E$1:$E$200,$P13)="","",INDEX(Installs!$E$1:$E$200,$P13)),"")) | F13: =IF($P13="","",IFERROR(IF(INDEX(Installs!$F$1:$F$200,$P13)="","",INDEX(Installs!$F$1:$F$200,$P13)),"")) | G13: =IF($P13="","",IFERROR(IF(INDEX(Installs!$G$1:$G$200,$P13)="","",INDEX(Installs!$G$1:$G$200,$P13)),"")) | H13: =IF($P13="","",IFERROR(IF(INDEX(Installs!$H$1:$H$200,$P13)="","",INDEX(Installs!$H$1:$H$200,$P13)),"")) | P13: =IFERROR(MATCH(5,Installs!$R$5:$R$200,0)+4,"")
A14: =IF($P14="","",6) | B14: =IF($P14="","",IFERROR(IF(INDEX(Installs!$B$1:$B$200,$P14)="","",INDEX(Installs!$B$1:$B$200,$P14)),"")) | C14: =IF($P14="","",IFERROR(IF(INDEX(Installs!$M$1:$M$200,$P14)="","",INDEX(Installs!$M$1:$M$200,$P14)),"")) | D14: =IF($P14="","",IFERROR(IF(INDEX(Installs!$D$1:$D$200,$P14)="","",INDEX(Installs!$D$1:$D$200,$P14)),"")) | E14: =IF($P14="","",IFERROR(IF(INDEX(Installs!$E$1:$E$200,$P14)="","",INDEX(Installs!$E$1:$E$200,$P14)),"")) | F14: =IF($P14="","",IFERROR(IF(INDEX(Installs!$F$1:$F$200,$P14)="","",INDEX(Installs!$F$1:$F$200,$P14)),"")) | G14: =IF($P14="","",IFERROR(IF(INDEX(Installs!$G$1:$G$200,$P14)="","",INDEX(Installs!$G$1:$G$200,$P14)),"")) | H14: =IF($P14="","",IFERROR(IF(INDEX(Installs!$H$1:$H$200,$P14)="","",INDEX(Installs!$H$1:$H$200,$P14)),"")) | P14: =IFERROR(MATCH(6,Installs!$R$5:$R$200,0)+4,"")
A15: =IF($P15="","",7) | B15: =IF($P15="","",IFERROR(IF(INDEX(Installs!$B$1:$B$200,$P15)="","",INDEX(Installs!$B$1:$B$200,$P15)),"")) | C15: =IF($P15="","",IFERROR(IF(INDEX(Installs!$M$1:$M$200,$P15)="","",INDEX(Installs!$M$1:$M$200,$P15)),"")) | D15: =IF($P15="","",IFERROR(IF(INDEX(Installs!$D$1:$D$200,$P15)="","",INDEX(Installs!$D$1:$D$200,$P15)),"")) | E15: =IF($P15="","",IFERROR(IF(INDEX(Installs!$E$1:$E$200,$P15)="","",INDEX(Installs!$E$1:$E$200,$P15)),"")) | F15: =IF($P15="","",IFERROR(IF(INDEX(Installs!$F$1:$F$200,$P15)="","",INDEX(Installs!$F$1:$F$200,$P15)),"")) | G15: =IF($P15="","",IFERROR(IF(INDEX(Installs!$G$1:$G$200,$P15)="","",INDEX(Installs!$G$1:$G$200,$P15)),"")) | H15: =IF($P15="","",IFERROR(IF(INDEX(Installs!$H$1:$H$200,$P15)="","",INDEX(Installs!$H$1:$H$200,$P15)),"")) | P15: =IFERROR(MATCH(7,Installs!$R$5:$R$200,0)+4,"")
A16: =IF($P16="","",8) | B16: =IF($P16="","",IFERROR(IF(INDEX(Installs!$B$1:$B$200,$P16)="","",INDEX(Installs!$B$1:$B$200,$P16)),"")) | C16: =IF($P16="","",IFERROR(IF(INDEX(Installs!$M$1:$M$200,$P16)="","",INDEX(Installs!$M$1:$M$200,$P16)),"")) | D16: =IF($P16="","",IFERROR(IF(INDEX(Installs!$D$1:$D$200,$P16)="","",INDEX(Installs!$D$1:$D$200,$P16)),"")) | E16: =IF($P16="","",IFERROR(IF(INDEX(Installs!$E$1:$E$200,$P16)="","",INDEX(Installs!$E$1:$E$200,$P16)),"")) | F16: =IF($P16="","",IFERROR(IF(INDEX(Installs!$F$1:$F$200,$P16)="","",INDEX(Installs!$F$1:$F$200,$P16)),"")) | G16: =IF($P16="","",IFERROR(IF(INDEX(Installs!$G$1:$G$200,$P16)="","",INDEX(Installs!$G$1:$G$200,$P16)),"")) | H16: =IF($P16="","",IFERROR(IF(INDEX(Installs!$H$1:$H$200,$P16)="","",INDEX(Installs!$H$1:$H$200,$P16)),"")) | P16: =IFERROR(MATCH(8,Installs!$R$5:$R$200,0)+4,"")
A17: =IF($P17="","",9) | B17: =IF($P17="","",IFERROR(IF(INDEX(Installs!$B$1:$B$200,$P17)="","",INDEX(Installs!$B$1:$B$200,$P17)),"")) | C17: =IF($P17="","",IFERROR(IF(INDEX(Installs!$M$1:$M$200,$P17)="","",INDEX(Installs!$M$1:$M$200,$P17)),"")) | D17: =IF($P17="","",IFERROR(IF(INDEX(Installs!$D$1:$D$200,$P17)="","",INDEX(Installs!$D$1:$D$200,$P17)),"")) | E17: =IF($P17="","",IFERROR(IF(INDEX(Installs!$E$1:$E$200,$P17)="","",INDEX(Installs!$E$1:$E$200,$P17)),"")) | F17: =IF($P17="","",IFERROR(IF(INDEX(Installs!$F$1:$F$200,$P17)="","",INDEX(Installs!$F$1:$F$200,$P17)),"")) | G17: =IF($P17="","",IFERROR(IF(INDEX(Installs!$G$1:$G$200,$P17)="","",INDEX(Installs!$G$1:$G$200,$P17)),"")) | H17: =IF($P17="","",IFERROR(IF(INDEX(Installs!$H$1:$H$200,$P17)="","",INDEX(Installs!$H$1:$H$200,$P17)),"")) | P17: =IFERROR(MATCH(9,Installs!$R$5:$R$200,0)+4,"")
A18: =IF($P18="","",10) | B18: =IF($P18="","",IFERROR(IF(INDEX(Installs!$B$1:$B$200,$P18)="","",INDEX(Installs!$B$1:$B$200,$P18)),"")) | C18: =IF($P18="","",IFERROR(IF(INDEX(Installs!$M$1:$M$200,$P18)="","",INDEX(Installs!$M$1:$M$200,$P18)),"")) | D18: =IF($P18="","",IFERROR(IF(INDEX(Installs!$D$1:$D$200,$P18)="","",INDEX(Installs!$D$1:$D$200,$P18)),"")) | E18: =IF($P18="","",IFERROR(IF(INDEX(Installs!$E$1:$E$200,$P18)="","",INDEX(Installs!$E$1:$E$200,$P18)),"")) | F18: =IF($P18="","",IFERROR(IF(INDEX(Installs!$F$1:$F$200,$P18)="","",INDEX(Installs!$F$1:$F$200,$P18)),"")) | G18: =IF($P18="","",IFERROR(IF(INDEX(Installs!$G$1:$G$200,$P18)="","",INDEX(Installs!$G$1:$G$200,$P18)),"")) | H18: =IF($P18="","",IFERROR(IF(INDEX(Installs!$H$1:$H$200,$P18)="","",INDEX(Installs!$H$1:$H$200,$P18)),"")) | P18: =IFERROR(MATCH(10,Installs!$R$5:$R$200,0)+4,"")
A19: =IF(SUM(Installs!$Q$5:$Q$200)=0,"✓ Nothing flagged — no scheduled account is at risk right now.",IF(SUM(Installs!$Q$5:$Q$200)>10,"Showing the first 10 of "&SUM(Installs!$Q$5:$Q$200)&" flagged accounts — the rest are the red rows on the Installs tab.","All "&SUM(Installs!$Q$5:$Q$200)&" flagged account(s) are listed above.")) -> ✓ Nothing flagged — no scheduled account is at risk right now.
A21: 🔧 PREP QUEUE — every account not yet installed, in install-date order. Work top to bottom.
A22: Days out | B22: Account | C22: Equipment to prep | D22: Equip Status | E22: Install Date | F22: Assigned Tech | G22: Work Order | H22: Requirements
A23: =IF($P23="","",IFERROR(IF(ISNUMBER(INDEX(Installs!$E$1:$E$200,$P23)),INDEX(Installs!$E$1:$E$200,$P23)-TODAY(),"needs date"),"")) -> -7 | B23: =IF($P23="","",IFERROR(IF(INDEX(Installs!$B$1:$B$200,$P23)="","",INDEX(Installs!$B$1:$B$200,$P23)),"")) -> Ninfa's - Navigation | C23: =IF($P23="","",IFERROR(IF(INDEX(Installs!$C$1:$C$200,$P23)="","",INDEX(Installs!$C$1:$C$200,$P23)),"")) -> TB3 | D23: =IF($P23="","",IFERROR(IF(INDEX(Installs!$D$1:$D$200,$P23)="","",INDEX(Installs!$D$1:$D$200,$P23)),"")) -> Ready | E23: =IF($P23="","",IFERROR(IF(INDEX(Installs!$E$1:$E$200,$P23)="","",INDEX(Installs!$E$1:$E$200,$P23)),"")) -> 46247 | F23: =IF($P23="","",IFERROR(IF(INDEX(Installs!$F$1:$F$200,$P23)="","",INDEX(Installs!$F$1:$F$200,$P23)),"")) | G23: =IF($P23="","",IFERROR(IF(INDEX(Installs!$G$1:$G$200,$P23)="","",INDEX(Installs!$G$1:$G$200,$P23)),"")) | H23: =IF($P23="","",IFERROR(IF(INDEX(Installs!$H$1:$H$200,$P23)="","",INDEX(Installs!$H$1:$H$200,$P23)),"")) | P23: =IF(COUNTIF(Installs!$O$5:$O$200,"<999999999")<1,"",IFERROR(MOD(SMALL(Installs!$O$5:$O$200,1),10000)+4,"")) -> 33
A24: =IF($P24="","",IFERROR(IF(ISNUMBER(INDEX(Installs!$E$1:$E$200,$P24)),INDEX(Installs!$E$1:$E$200,$P24)-TODAY(),"needs date"),"")) -> 0 | B24: =IF($P24="","",IFERROR(IF(INDEX(Installs!$B$1:$B$200,$P24)="","",INDEX(Installs!$B$1:$B$200,$P24)),"")) -> Southern Ice CO | C24: =IF($P24="","",IFERROR(IF(INDEX(Installs!$C$1:$C$200,$P24)="","",INDEX(Installs!$C$1:$C$200,$P24)),"")) -> bunn itcb | D24: =IF($P24="","",IFERROR(IF(INDEX(Installs!$D$1:$D$200,$P24)="","",INDEX(Installs!$D$1:$D$200,$P24)),"")) -> Ready | E24: =IF($P24="","",IFERROR(IF(INDEX(Installs!$E$1:$E$200,$P24)="","",INDEX(Installs!$E$1:$E$200,$P24)),"")) -> 46254 | F24: =IF($P24="","",IFERROR(IF(INDEX(Installs!$F$1:$F$200,$P24)="","",INDEX(Installs!$F$1:$F$200,$P24)),"")) | G24: =IF($P24="","",IFERROR(IF(INDEX(Installs!$G$1:$G$200,$P24)="","",INDEX(Installs!$G$1:$G$200,$P24)),"")) -> WO-0406 | H24: =IF($P24="","",IFERROR(IF(INDEX(Installs!$H$1:$H$200,$P24)="","",INDEX(Installs!$H$1:$H$200,$P24)),"")) -> Ready | P24: =IF(COUNTIF(Installs!$O$5:$O$200,"<999999999")<2,"",IFERROR(MOD(SMALL(Installs!$O$5:$O$200,2),10000)+4,"")) -> 52
A25: =IF($P25="","",IFERROR(IF(ISNUMBER(INDEX(Installs!$E$1:$E$200,$P25)),INDEX(Installs!$E$1:$E$200,$P25)-TODAY(),"needs date"),"")) -> needs date | B25: =IF($P25="","",IFERROR(IF(INDEX(Installs!$B$1:$B$200,$P25)="","",INDEX(Installs!$B$1:$B$200,$P25)),"")) -> kol fac 118 | C25: =IF($P25="","",IFERROR(IF(INDEX(Installs!$C$1:$C$200,$P25)="","",INDEX(Installs!$C$1:$C$200,$P25)),"")) -> cameo, itcb | D25: =IF($P25="","",IFERROR(IF(INDEX(Installs!$D$1:$D$200,$P25)="","",INDEX(Installs!$D$1:$D$200,$P25)),"")) -> Not Ready | E25: =IF($P25="","",IFERROR(IF(INDEX(Installs!$E$1:$E$200,$P25)="","",INDEX(Installs!$E$1:$E$200,$P25)),"")) | F25: =IF($P25="","",IFERROR(IF(INDEX(Installs!$F$1:$F$200,$P25)="","",INDEX(Installs!$F$1:$F$200,$P25)),"")) | G25: =IF($P25="","",IFERROR(IF(INDEX(Installs!$G$1:$G$200,$P25)="","",INDEX(Installs!$G$1:$G$200,$P25)),"")) | H25: =IF($P25="","",IFERROR(IF(INDEX(Installs!$H$1:$H$200,$P25)="","",INDEX(Installs!$H$1:$H$200,$P25)),"")) | P25: =IF(COUNTIF(Installs!$O$5:$O$200,"<999999999")<3,"",IFERROR(MOD(SMALL(Installs!$O$5:$O$200,3),10000)+4,"")) -> 42
A26: =IF($P26="","",IFERROR(IF(ISNUMBER(INDEX(Installs!$E$1:$E$200,$P26)),INDEX(Installs!$E$1:$E$200,$P26)-TODAY(),"needs date"),"")) -> needs date | B26: =IF($P26="","",IFERROR(IF(INDEX(Installs!$B$1:$B$200,$P26)="","",INDEX(Installs!$B$1:$B$200,$P26)),"")) -> Coco Crepes Bellaire | C26: =IF($P26="","",IFERROR(IF(INDEX(Installs!$C$1:$C$200,$P26)="","",INDEX(Installs!$C$1:$C$200,$P26)),"")) -> La Marzocco Linea Classic S 2 Group AV/ La Marzocco Swift Dual-Hopper Espresso Grinder/ Bunn Axiom-APS | D26: =IF($P26="","",IFERROR(IF(INDEX(Installs!$D$1:$D$200,$P26)="","",INDEX(Installs!$D$1:$D$200,$P26)),"")) -> Not Ready | E26: =IF($P26="","",IFERROR(IF(INDEX(Installs!$E$1:$E$200,$P26)="","",INDEX(Installs!$E$1:$E$200,$P26)),"")) | F26: =IF($P26="","",IFERROR(IF(INDEX(Installs!$F$1:$F$200,$P26)="","",INDEX(Installs!$F$1:$F$200,$P26)),"")) | G26: =IF($P26="","",IFERROR(IF(INDEX(Installs!$G$1:$G$200,$P26)="","",INDEX(Installs!$G$1:$G$200,$P26)),"")) | H26: =IF($P26="","",IFERROR(IF(INDEX(Installs!$H$1:$H$200,$P26)="","",INDEX(Installs!$H$1:$H$200,$P26)),"")) | P26: =IF(COUNTIF(Installs!$O$5:$O$200,"<999999999")<4,"",IFERROR(MOD(SMALL(Installs!$O$5:$O$200,4),10000)+4,"")) -> 45
A27: =IF($P27="","",IFERROR(IF(ISNUMBER(INDEX(Installs!$E$1:$E$200,$P27)),INDEX(Installs!$E$1:$E$200,$P27)-TODAY(),"needs date"),"")) -> needs date | B27: =IF($P27="","",IFERROR(IF(INDEX(Installs!$B$1:$B$200,$P27)="","",INDEX(Installs!$B$1:$B$200,$P27)),"")) -> waller county court house | C27: =IF($P27="","",IFERROR(IF(INDEX(Installs!$C$1:$C$200,$P27)="","",INDEX(Installs!$C$1:$C$200,$P27)),"")) -> axiom aps | D27: =IF($P27="","",IFERROR(IF(INDEX(Installs!$D$1:$D$200,$P27)="","",INDEX(Installs!$D$1:$D$200,$P27)),"")) -> Ready | E27: =IF($P27="","",IFERROR(IF(INDEX(Installs!$E$1:$E$200,$P27)="","",INDEX(Installs!$E$1:$E$200,$P27)),"")) | F27: =IF($P27="","",IFERROR(IF(INDEX(Installs!$F$1:$F$200,$P27)="","",INDEX(Installs!$F$1:$F$200,$P27)),"")) | G27: =IF($P27="","",IFERROR(IF(INDEX(Installs!$G$1:$G$200,$P27)="","",INDEX(Installs!$G$1:$G$200,$P27)),"")) | H27: =IF($P27="","",IFERROR(IF(INDEX(Installs!$H$1:$H$200,$P27)="","",INDEX(Installs!$H$1:$H$200,$P27)),"")) -> Not Ready | P27: =IF(COUNTIF(Installs!$O$5:$O$200,"<999999999")<5,"",IFERROR(MOD(SMALL(Installs!$O$5:$O$200,5),10000)+4,"")) -> 48
A28: =IF($P28="","",IFERROR(IF(ISNUMBER(INDEX(Installs!$E$1:$E$200,$P28)),INDEX(Installs!$E$1:$E$200,$P28)-TODAY(),"needs date"),"")) -> needs date | B28: =IF($P28="","",IFERROR(IF(INDEX(Installs!$B$1:$B$200,$P28)="","",INDEX(Installs!$B$1:$B$200,$P28)),"")) -> Doug's Diner | C28: =IF($P28="","",IFERROR(IF(INDEX(Installs!$C$1:$C$200,$P28)="","",INDEX(Installs!$C$1:$C$200,$P28)),"")) -> Fetco MBS x 2 / Powder Machine | D28: =IF($P28="","",IFERROR(IF(INDEX(Installs!$D$1:$D$200,$P28)="","",INDEX(Installs!$D$1:$D$200,$P28)),"")) -> Not Ready | E28: =IF($P28="","",IFERROR(IF(INDEX(Installs!$E$1:$E$200,$P28)="","",INDEX(Installs!$E$1:$E$200,$P28)),"")) | F28: =IF($P28="","",IFERROR(IF(INDEX(Installs!$F$1:$F$200,$P28)="","",INDEX(Installs!$F$1:$F$200,$P28)),"")) -> 3rd Party | G28: =IF($P28="","",IFERROR(IF(INDEX(Installs!$G$1:$G$200,$P28)="","",INDEX(Installs!$G$1:$G$200,$P28)),"")) | H28: =IF($P28="","",IFERROR(IF(INDEX(Installs!$H$1:$H$200,$P28)="","",INDEX(Installs!$H$1:$H$200,$P28)),"")) -> Ready | P28: =IF(COUNTIF(Installs!$O$5:$O$200,"<999999999")<6,"",IFERROR(MOD(SMALL(Installs!$O$5:$O$200,6),10000)+4,"")) -> 50
A29: =IF($P29="","",IFERROR(IF(ISNUMBER(INDEX(Installs!$E$1:$E$200,$P29)),INDEX(Installs!$E$1:$E$200,$P29)-TODAY(),"needs date"),"")) -> needs date | B29: =IF($P29="","",IFERROR(IF(INDEX(Installs!$B$1:$B$200,$P29)="","",INDEX(Installs!$B$1:$B$200,$P29)),"")) -> Two Step Taqueria - South | C29: =IF($P29="","",IFERROR(IF(INDEX(Installs!$C$1:$C$200,$P29)="","",INDEX(Installs!$C$1:$C$200,$P29)),"")) | D29: =IF($P29="","",IFERROR(IF(INDEX(Installs!$D$1:$D$200,$P29)="","",INDEX(Installs!$D$1:$D$200,$P29)),"")) -> Not Ready | E29: =IF($P29="","",IFERROR(IF(INDEX(Installs!$E$1:$E$200,$P29)="","",INDEX(Installs!$E$1:$E$200,$P29)),"")) | F29: =IF($P29="","",IFERROR(IF(INDEX(Installs!$F$1:$F$200,$P29)="","",INDEX(Installs!$F$1:$F$200,$P29)),"")) -> Lance | G29: =IF($P29="","",IFERROR(IF(INDEX(Installs!$G$1:$G$200,$P29)="","",INDEX(Installs!$G$1:$G$200,$P29)),"")) | H29: =IF($P29="","",IFERROR(IF(INDEX(Installs!$H$1:$H$200,$P29)="","",INDEX(Installs!$H$1:$H$200,$P29)),"")) | P29: =IF(COUNTIF(Installs!$O$5:$O$200,"<999999999")<7,"",IFERROR(MOD(SMALL(Installs!$O$5:$O$200,7),10000)+4,"")) -> 51
A30: =IF($P30="","",IFERROR(IF(ISNUMBER(INDEX(Installs!$E$1:$E$200,$P30)),INDEX(Installs!$E$1:$E$200,$P30)-TODAY(),"needs date"),"")) -> needs date | B30: =IF($P30="","",IFERROR(IF(INDEX(Installs!$B$1:$B$200,$P30)="","",INDEX(Installs!$B$1:$B$200,$P30)),"")) -> Scrambles Breakfast & Lunch | C30: =IF($P30="","",IFERROR(IF(INDEX(Installs!$C$1:$C$200,$P30)="","",INDEX(Installs!$C$1:$C$200,$P30)),"")) -> BUNN ITCB & BUNN G9 GRINDER | D30: =IF($P30="","",IFERROR(IF(INDEX(Installs!$D$1:$D$200,$P30)="","",INDEX(Installs!$D$1:$D$200,$P30)),"")) | E30: =IF($P30="","",IFERROR(IF(INDEX(Installs!$E$1:$E$200,$P30)="","",INDEX(Installs!$E$1:$E$200,$P30)),"")) | F30: =IF($P30="","",IFERROR(IF(INDEX(Installs!$F$1:$F$200,$P30)="","",INDEX(Installs!$F$1:$F$200,$P30)),"")) | G30: =IF($P30="","",IFERROR(IF(INDEX(Installs!$G$1:$G$200,$P30)="","",INDEX(Installs!$G$1:$G$200,$P30)),"")) | H30: =IF($P30="","",IFERROR(IF(INDEX(Installs!$H$1:$H$200,$P30)="","",INDEX(Installs!$H$1:$H$200,$P30)),"")) | P30: =IF(COUNTIF(Installs!$O$5:$O$200,"<999999999")<8,"",IFERROR(MOD(SMALL(Installs!$O$5:$O$200,8),10000)+4,"")) -> 53
A31: =IF($P31="","",IFERROR(IF(ISNUMBER(INDEX(Installs!$E$1:$E$200,$P31)),INDEX(Installs!$E$1:$E$200,$P31)-TODAY(),"needs date"),"")) -> needs date | B31: =IF($P31="","",IFERROR(IF(INDEX(Installs!$B$1:$B$200,$P31)="","",INDEX(Installs!$B$1:$B$200,$P31)),"")) -> Truffle & Rye | C31: =IF($P31="","",IFERROR(IF(INDEX(Installs!$C$1:$C$200,$P31)="","",INDEX(Installs!$C$1:$C$200,$P31)),"")) -> La Marz GS3, jay grinder | D31: =IF($P31="","",IFERROR(IF(INDEX(Installs!$D$1:$D$200,$P31)="","",INDEX(Installs!$D$1:$D$200,$P31)),"")) | E31: =IF($P31="","",IFERROR(IF(INDEX(Installs!$E$1:$E$200,$P31)="","",INDEX(Installs!$E$1:$E$200,$P31)),"")) | F31: =IF($P31="","",IFERROR(IF(INDEX(Installs!$F$1:$F$200,$P31)="","",INDEX(Installs!$F$1:$F$200,$P31)),"")) | G31: =IF($P31="","",IFERROR(IF(INDEX(Installs!$G$1:$G$200,$P31)="","",INDEX(Installs!$G$1:$G$200,$P31)),"")) | H31: =IF($P31="","",IFERROR(IF(INDEX(Installs!$H$1:$H$200,$P31)="","",INDEX(Installs!$H$1:$H$200,$P31)),"")) | P31: =IF(COUNTIF(Installs!$O$5:$O$200,"<999999999")<9,"",IFERROR(MOD(SMALL(Installs!$O$5:$O$200,9),10000)+4,"")) -> 161
A32: =IF($P32="","",IFERROR(IF(ISNUMBER(INDEX(Installs!$E$1:$E$200,$P32)),INDEX(Installs!$E$1:$E$200,$P32)-TODAY(),"needs date"),"")) -> needs date | B32: =IF($P32="","",IFERROR(IF(INDEX(Installs!$B$1:$B$200,$P32)="","",INDEX(Installs!$B$1:$B$200,$P32)),"")) -> Jonathan's The Rub - Bridgeland | C32: =IF($P32="","",IFERROR(IF(INDEX(Installs!$C$1:$C$200,$P32)="","",INDEX(Installs!$C$1:$C$200,$P32)),"")) -> Cameo c'2s | D32: =IF($P32="","",IFERROR(IF(INDEX(Installs!$D$1:$D$200,$P32)="","",INDEX(Installs!$D$1:$D$200,$P32)),"")) | E32: =IF($P32="","",IFERROR(IF(INDEX(Installs!$E$1:$E$200,$P32)="","",INDEX(Installs!$E$1:$E$200,$P32)),"")) | F32: =IF($P32="","",IFERROR(IF(INDEX(Installs!$F$1:$F$200,$P32)="","",INDEX(Installs!$F$1:$F$200,$P32)),"")) | G32: =IF($P32="","",IFERROR(IF(INDEX(Installs!$G$1:$G$200,$P32)="","",INDEX(Installs!$G$1:$G$200,$P32)),"")) | H32: =IF($P32="","",IFERROR(IF(INDEX(Installs!$H$1:$H$200,$P32)="","",INDEX(Installs!$H$1:$H$200,$P32)),"")) | P32: =IF(COUNTIF(Installs!$O$5:$O$200,"<999999999")<10,"",IFERROR(MOD(SMALL(Installs!$O$5:$O$200,10),10000)+4,"")) -> 162
A33: =IF($P33="","",IFERROR(IF(ISNUMBER(INDEX(Installs!$E$1:$E$200,$P33)),INDEX(Installs!$E$1:$E$200,$P33)-TODAY(),"needs date"),"")) -> needs date | B33: =IF($P33="","",IFERROR(IF(INDEX(Installs!$B$1:$B$200,$P33)="","",INDEX(Installs!$B$1:$B$200,$P33)),"")) -> Valentinas Coffee | C33: =IF($P33="","",IFERROR(IF(INDEX(Installs!$C$1:$C$200,$P33)="","",INDEX(Installs!$C$1:$C$200,$P33)),"")) -> La Marzocco Strada XT 2 Group, Mazzer ZM Filter Grinder - Black, Mazzer Robur S Electronic, Puqpress Q2 Automatic Tamper BLACK, Everpure EZ-RO 200/10 Gallon Hydropneumatic Tank, Blendtec Stealth 885, Blendtec Rapid Rinse Station | D33: =IF($P33="","",IFERROR(IF(INDEX(Installs!$D$1:$D$200,$P33)="","",INDEX(Installs!$D$1:$D$200,$P33)),"")) | E33: =IF($P33="","",IFERROR(IF(INDEX(Installs!$E$1:$E$200,$P33)="","",INDEX(Installs!$E$1:$E$200,$P33)),"")) | F33: =IF($P33="","",IFERROR(IF(INDEX(Installs!$F$1:$F$200,$P33)="","",INDEX(Installs!$F$1:$F$200,$P33)),"")) | G33: =IF($P33="","",IFERROR(IF(INDEX(Installs!$G$1:$G$200,$P33)="","",INDEX(Installs!$G$1:$G$200,$P33)),"")) | H33: =IF($P33="","",IFERROR(IF(INDEX(Installs!$H$1:$H$200,$P33)="","",INDEX(Installs!$H$1:$H$200,$P33)),"")) | P33: =IF(COUNTIF(Installs!$O$5:$O$200,"<999999999")<11,"",IFERROR(MOD(SMALL(Installs!$O$5:$O$200,11),10000)+4,"")) -> 163
A34: =IF($P34="","",IFERROR(IF(ISNUMBER(INDEX(Installs!$E$1:$E$200,$P34)),INDEX(Installs!$E$1:$E$200,$P34)-TODAY(),"needs date"),"")) -> needs date | B34: =IF($P34="","",IFERROR(IF(INDEX(Installs!$B$1:$B$200,$P34)="","",INDEX(Installs!$B$1:$B$200,$P34)),"")) -> The Audrey Restaurant & Bar Post Oak | C34: =IF($P34="","",IFERROR(IF(INDEX(Installs!$C$1:$C$200,$P34)="","",INDEX(Installs!$C$1:$C$200,$P34)),"")) -> Eversys Cameo c'2s | D34: =IF($P34="","",IFERROR(IF(INDEX(Installs!$D$1:$D$200,$P34)="","",INDEX(Installs!$D$1:$D$200,$P34)),"")) | E34: =IF($P34="","",IFERROR(IF(INDEX(Installs!$E$1:$E$200,$P34)="","",INDEX(Installs!$E$1:$E$200,$P34)),"")) | F34: =IF($P34="","",IFERROR(IF(INDEX(Installs!$F$1:$F$200,$P34)="","",INDEX(Installs!$F$1:$F$200,$P34)),"")) | G34: =IF($P34="","",IFERROR(IF(INDEX(Installs!$G$1:$G$200,$P34)="","",INDEX(Installs!$G$1:$G$200,$P34)),"")) | H34: =IF($P34="","",IFERROR(IF(INDEX(Installs!$H$1:$H$200,$P34)="","",INDEX(Installs!$H$1:$H$200,$P34)),"")) | P34: =IF(COUNTIF(Installs!$O$5:$O$200,"<999999999")<12,"",IFERROR(MOD(SMALL(Installs!$O$5:$O$200,12),10000)+4,"")) -> 164
A35: =IF($P35="","",IFERROR(IF(ISNUMBER(INDEX(Installs!$E$1:$E$200,$P35)),INDEX(Installs!$E$1:$E$200,$P35)-TODAY(),"needs date"),"")) -> needs date | B35: =IF($P35="","",IFERROR(IF(INDEX(Installs!$B$1:$B$200,$P35)="","",INDEX(Installs!$B$1:$B$200,$P35)),"")) -> Brews & Books | C35: =IF($P35="","",IFERROR(IF(INDEX(Installs!$C$1:$C$200,$P35)="","",INDEX(Installs!$C$1:$C$200,$P35)),"")) -> Eversys Cameo c'2s | D35: =IF($P35="","",IFERROR(IF(INDEX(Installs!$D$1:$D$200,$P35)="","",INDEX(Installs!$D$1:$D$200,$P35)),"")) | E35: =IF($P35="","",IFERROR(IF(INDEX(Installs!$E$1:$E$200,$P35)="","",INDEX(Installs!$E$1:$E$200,$P35)),"")) | F35: =IF($P35="","",IFERROR(IF(INDEX(Installs!$F$1:$F$200,$P35)="","",INDEX(Installs!$F$1:$F$200,$P35)),"")) | G35: =IF($P35="","",IFERROR(IF(INDEX(Installs!$G$1:$G$200,$P35)="","",INDEX(Installs!$G$1:$G$200,$P35)),"")) | H35: =IF($P35="","",IFERROR(IF(INDEX(Installs!$H$1:$H$200,$P35)="","",INDEX(Installs!$H$1:$H$200,$P35)),"")) | P35: =IF(COUNTIF(Installs!$O$5:$O$200,"<999999999")<13,"",IFERROR(MOD(SMALL(Installs!$O$5:$O$200,13),10000)+4,"")) -> 165
A36: =IF($P36="","",IFERROR(IF(ISNUMBER(INDEX(Installs!$E$1:$E$200,$P36)),INDEX(Installs!$E$1:$E$200,$P36)-TODAY(),"needs date"),"")) | B36: =IF($P36="","",IFERROR(IF(INDEX(Installs!$B$1:$B$200,$P36)="","",INDEX(Installs!$B$1:$B$200,$P36)),"")) | C36: =IF($P36="","",IFERROR(IF(INDEX(Installs!$C$1:$C$200,$P36)="","",INDEX(Installs!$C$1:$C$200,$P36)),"")) | D36: =IF($P36="","",IFERROR(IF(INDEX(Installs!$D$1:$D$200,$P36)="","",INDEX(Installs!$D$1:$D$200,$P36)),"")) | E36: =IF($P36="","",IFERROR(IF(INDEX(Installs!$E$1:$E$200,$P36)="","",INDEX(Installs!$E$1:$E$200,$P36)),"")) | F36: =IF($P36="","",IFERROR(IF(INDEX(Installs!$F$1:$F$200,$P36)="","",INDEX(Installs!$F$1:$F$200,$P36)),"")) | G36: =IF($P36="","",IFERROR(IF(INDEX(Installs!$G$1:$G$200,$P36)="","",INDEX(Installs!$G$1:$G$200,$P36)),"")) | H36: =IF($P36="","",IFERROR(IF(INDEX(Installs!$H$1:$H$200,$P36)="","",INDEX(Installs!$H$1:$H$200,$P36)),"")) | P36: =IF(COUNTIF(Installs!$O$5:$O$200,"<999999999")<14,"",IFERROR(MOD(SMALL(Installs!$O$5:$O$200,14),10000)+4,""))
A37: =IF($P37="","",IFERROR(IF(ISNUMBER(INDEX(Installs!$E$1:$E$200,$P37)),INDEX(Installs!$E$1:$E$200,$P37)-TODAY(),"needs date"),"")) | B37: =IF($P37="","",IFERROR(IF(INDEX(Installs!$B$1:$B$200,$P37)="","",INDEX(Installs!$B$1:$B$200,$P37)),"")) | C37: =IF($P37="","",IFERROR(IF(INDEX(Installs!$C$1:$C$200,$P37)="","",INDEX(Installs!$C$1:$C$200,$P37)),"")) | D37: =IF($P37="","",IFERROR(IF(INDEX(Installs!$D$1:$D$200,$P37)="","",INDEX(Installs!$D$1:$D$200,$P37)),"")) | E37: =IF($P37="","",IFERROR(IF(INDEX(Installs!$E$1:$E$200,$P37)="","",INDEX(Installs!$E$1:$E$200,$P37)),"")) | F37: =IF($P37="","",IFERROR(IF(INDEX(Installs!$F$1:$F$200,$P37)="","",INDEX(Installs!$F$1:$F$200,$P37)),"")) | G37: =IF($P37="","",IFERROR(IF(INDEX(Installs!$G$1:$G$200,$P37)="","",INDEX(Installs!$G$1:$G$200,$P37)),"")) | H37: =IF($P37="","",IFERROR(IF(INDEX(Installs!$H$1:$H$200,$P37)="","",INDEX(Installs!$H$1:$H$200,$P37)),"")) | P37: =IF(COUNTIF(Installs!$O$5:$O$200,"<999999999")<15,"",IFERROR(MOD(SMALL(Installs!$O$5:$O$200,15),10000)+4,""))
