Workbook
Name ProviderList: OFFSET(Service_Providers!$A$2,0,0,MAX(1,COUNTA(Service_Providers!$A$2:$A$104)),1)

Sheet Dashboard
A1: SERVICE NETWORK MASTER DATABASE - Out-of-Network Accounts
A2: Updates automatically: add providers on Service_Providers (through row 101) and accounts on Accounts (through row 300) - dropdowns, dispatch info, and these tables refresh on their own.
A4: COVERAGE BY STATE | G4: ACCOUNTS BY PROVIDER
A5: State | B5: Total Accounts | C5: With Equipment | D5: Unassigned | E5: % Covered | G5: Provider | H5: Primary For | I5: Secondary For | J5: Dispatch Phone | K5: Dispatch Email
A6: AR | B6: =COUNTIF(Accounts!$G$2:$G$299,A6) -> 2 | C6: =COUNTIFS(Accounts!$G$2:$G$299,A6,Accounts!$I$2:$I$299,"<>") -> 2 | D6: =COUNTIFS(Accounts!$G$2:$G$299,A6,Accounts!$K$2:$K$299,"") -> 0 | E6: =IF(B6=0,0,(B6-D6)/B6) -> 1 | G6: =IF(Service_Providers!A2="","",Service_Providers!A2) -> A-1 Restuarant Service | H6: =IF(G6="","",COUNTIF(Accounts!$K$2:$K$299,G6)) -> 0 | I6: =IF(G6="","",COUNTIF(Accounts!$M$2:$M$299,G6)) -> 0 | J6: =IF(Service_Providers!C2="","",Service_Providers!C2) | K6: =IF(Service_Providers!D2="","",Service_Providers!D2)
A7: AZ | B7: =COUNTIF(Accounts!$G$2:$G$299,A7) -> 4 | C7: =COUNTIFS(Accounts!$G$2:$G$299,A7,Accounts!$I$2:$I$299,"<>") -> 4 | D7: =COUNTIFS(Accounts!$G$2:$G$299,A7,Accounts!$K$2:$K$299,"") -> 0 | E7: =IF(B7=0,0,(B7-D7)/B7) -> 1 | G7: =IF(Service_Providers!A3="","",Service_Providers!A3) -> A-Tech Espresso & Coffee Service Inc. | H7: =IF(G7="","",COUNTIF(Accounts!$K$2:$K$299,G7)) -> 0 | I7: =IF(G7="","",COUNTIF(Accounts!$M$2:$M$299,G7)) -> 0 | J7: =IF(Service_Providers!C3="","",Service_Providers!C3) -> 866.333.7350 | K7: =IF(Service_Providers!D3="","",Service_Providers!D3) -> servicerequest@Atech-service.com
A8: CA | B8: =COUNTIF(Accounts!$G$2:$G$299,A8) -> 8 | C8: =COUNTIFS(Accounts!$G$2:$G$299,A8,Accounts!$I$2:$I$299,"<>") -> 8 | D8: =COUNTIFS(Accounts!$G$2:$G$299,A8,Accounts!$K$2:$K$299,"") -> 0 | E8: =IF(B8=0,0,(B8-D8)/B8) -> 1 | G8: =IF(Service_Providers!A4="","",Service_Providers!A4) -> ABS Coffee Repair | H8: =IF(G8="","",COUNTIF(Accounts!$K$2:$K$299,G8)) -> 0 | I8: =IF(G8="","",COUNTIF(Accounts!$M$2:$M$299,G8)) -> 0 | J8: =IF(Service_Providers!C4="","",Service_Providers!C4) -> 314.389.2866 | K8: =IF(Service_Providers!D4="","",Service_Providers!D4)
A9: CO | B9: =COUNTIF(Accounts!$G$2:$G$299,A9) -> 6 | C9: =COUNTIFS(Accounts!$G$2:$G$299,A9,Accounts!$I$2:$I$299,"<>") -> 6 | D9: =COUNTIFS(Accounts!$G$2:$G$299,A9,Accounts!$K$2:$K$299,"") -> 0 | E9: =IF(B9=0,0,(B9-D9)/B9) -> 1 | G9: =IF(Service_Providers!A5="","",Service_Providers!A5) -> All Espresso Service | H9: =IF(G9="","",COUNTIF(Accounts!$K$2:$K$299,G9)) -> 4 | I9: =IF(G9="","",COUNTIF(Accounts!$M$2:$M$299,G9)) -> 0 | J9: =IF(Service_Providers!C5="","",Service_Providers!C5) -> 754.205.5076 | K9: =IF(Service_Providers!D5="","",Service_Providers!D5) -> service@allespressoservice.com
A10: DC | B10: =COUNTIF(Accounts!$G$2:$G$299,A10) -> 1 | C10: =COUNTIFS(Accounts!$G$2:$G$299,A10,Accounts!$I$2:$I$299,"<>") -> 1 | D10: =COUNTIFS(Accounts!$G$2:$G$299,A10,Accounts!$K$2:$K$299,"") -> 0 | E10: =IF(B10=0,0,(B10-D10)/B10) -> 1 | G10: =IF(Service_Providers!A6="","",Service_Providers!A6) -> All Star Coffee Service | H10: =IF(G10="","",COUNTIF(Accounts!$K$2:$K$299,G10)) -> 2 | I10: =IF(G10="","",COUNTIF(Accounts!$M$2:$M$299,G10)) -> 0 | J10: =IF(Service_Providers!C6="","",Service_Providers!C6) -> 626-315-8498 | K10: =IF(Service_Providers!D6="","",Service_Providers!D6) -> allstarcoffeeservice@gmail.com
A11: FL | B11: =COUNTIF(Accounts!$G$2:$G$299,A11) -> 9 | C11: =COUNTIFS(Accounts!$G$2:$G$299,A11,Accounts!$I$2:$I$299,"<>") -> 9 | D11: =COUNTIFS(Accounts!$G$2:$G$299,A11,Accounts!$K$2:$K$299,"") -> 0 | E11: =IF(B11=0,0,(B11-D11)/B11) -> 1 | G11: =IF(Service_Providers!A7="","",Service_Providers!A7) -> Anytime Beverage Service | H11: =IF(G11="","",COUNTIF(Accounts!$K$2:$K$299,G11)) -> 7 | I11: =IF(G11="","",COUNTIF(Accounts!$M$2:$M$299,G11)) -> 2 | J11: =IF(Service_Providers!C7="","",Service_Providers!C7) -> Contact: Cynthia Phone: 714-335-9964 Cell: 714-395-8108 | K11: =IF(Service_Providers!D7="","",Service_Providers!D7) -> anytimebeverageservice@gmail.com
A12: GA | B12: =COUNTIF(Accounts!$G$2:$G$299,A12) -> 3 | C12: =COUNTIFS(Accounts!$G$2:$G$299,A12,Accounts!$I$2:$I$299,"<>") -> 3 | D12: =COUNTIFS(Accounts!$G$2:$G$299,A12,Accounts!$K$2:$K$299,"") -> 0 | E12: =IF(B12=0,0,(B12-D12)/B12) -> 1 | G12: =IF(Service_Providers!A8="","",Service_Providers!A8) -> B & B Coffee Service | H12: =IF(G12="","",COUNTIF(Accounts!$K$2:$K$299,G12)) -> 2 | I12: =IF(G12="","",COUNTIF(Accounts!$M$2:$M$299,G12)) -> 0 | J12: =IF(Service_Providers!C8="","",Service_Providers!C8) -> 361.855.3066 | K12: =IF(Service_Providers!D8="","",Service_Providers!D8)
A13: IL | B13: =COUNTIF(Accounts!$G$2:$G$299,A13) -> 2 | C13: =COUNTIFS(Accounts!$G$2:$G$299,A13,Accounts!$I$2:$I$299,"<>") -> 2 | D13: =COUNTIFS(Accounts!$G$2:$G$299,A13,Accounts!$K$2:$K$299,"") -> 0 | E13: =IF(B13=0,0,(B13-D13)/B13) -> 1 | G13: =IF(Service_Providers!A9="","",Service_Providers!A9) -> Bar 9 Coffee Services LLC | H13: =IF(G13="","",COUNTIF(Accounts!$K$2:$K$299,G13)) -> 0 | I13: =IF(G13="","",COUNTIF(Accounts!$M$2:$M$299,G13)) -> 0 | J13: =IF(Service_Providers!C9="","",Service_Providers!C9) -> 443-460-4303 | K13: =IF(Service_Providers!D9="","",Service_Providers!D9) -> chuck@bar9coffee.com
A14: IN | B14: =COUNTIF(Accounts!$G$2:$G$299,A14) -> 5 | C14: =COUNTIFS(Accounts!$G$2:$G$299,A14,Accounts!$I$2:$I$299,"<>") -> 5 | D14: =COUNTIFS(Accounts!$G$2:$G$299,A14,Accounts!$K$2:$K$299,"") -> 0 | E14: =IF(B14=0,0,(B14-D14)/B14) -> 1 | G14: =IF(Service_Providers!A10="","",Service_Providers!A10) -> Best Beverage Equipment Service | H14: =IF(G14="","",COUNTIF(Accounts!$K$2:$K$299,G14)) -> 0 | I14: =IF(G14="","",COUNTIF(Accounts!$M$2:$M$299,G14)) -> 3 | J14: =IF(Service_Providers!C10="","",Service_Providers!C10) -> 866-966-5799 ext 1 | K14: =IF(Service_Providers!D10="","",Service_Providers!D10) -> service@bestbeverage.net
A15: KS | B15: =COUNTIF(Accounts!$G$2:$G$299,A15) -> 2 | C15: =COUNTIFS(Accounts!$G$2:$G$299,A15,Accounts!$I$2:$I$299,"<>") -> 2 | D15: =COUNTIFS(Accounts!$G$2:$G$299,A15,Accounts!$K$2:$K$299,"") -> 0 | E15: =IF(B15=0,0,(B15-D15)/B15) -> 1 | G15: =IF(Service_Providers!A11="","",Service_Providers!A11) -> Bev Pro Services | H15: =IF(G15="","",COUNTIF(Accounts!$K$2:$K$299,G15)) -> 0 | I15: =IF(G15="","",COUNTIF(Accounts!$M$2:$M$299,G15)) -> 0 | J15: =IF(Service_Providers!C11="","",Service_Providers!C11) -> 410-571-4902 ext. 501 (Office) | K15: =IF(Service_Providers!D11="","",Service_Providers!D11)
A16: LA | B16: =COUNTIF(Accounts!$G$2:$G$299,A16) -> 3 | C16: =COUNTIFS(Accounts!$G$2:$G$299,A16,Accounts!$I$2:$I$299,"<>") -> 3 | D16: =COUNTIFS(Accounts!$G$2:$G$299,A16,Accounts!$K$2:$K$299,"") -> 0 | E16: =IF(B16=0,0,(B16-D16)/B16) -> 1 | G16: =IF(Service_Providers!A12="","",Service_Providers!A12) -> Beverage Equipment Service Inc. | H16: =IF(G16="","",COUNTIF(Accounts!$K$2:$K$299,G16)) -> 0 | I16: =IF(G16="","",COUNTIF(Accounts!$M$2:$M$299,G16)) -> 0 | J16: =IF(Service_Providers!C12="","",Service_Providers!C12) -> (515) 494-0849 | K16: =IF(Service_Providers!D12="","",Service_Providers!D12) -> bevequip@outlook.com (best - copied on all comms)
A17: MD | B17: =COUNTIF(Accounts!$G$2:$G$299,A17) -> 1 | C17: =COUNTIFS(Accounts!$G$2:$G$299,A17,Accounts!$I$2:$I$299,"<>") -> 1 | D17: =COUNTIFS(Accounts!$G$2:$G$299,A17,Accounts!$K$2:$K$299,"") -> 1 | E17: =IF(B17=0,0,(B17-D17)/B17) -> 0 | G17: =IF(Service_Providers!A13="","",Service_Providers!A13) -> Carolina Beverage Solutions | H17: =IF(G17="","",COUNTIF(Accounts!$K$2:$K$299,G17)) -> 5 | I17: =IF(G17="","",COUNTIF(Accounts!$M$2:$M$299,G17)) -> 0 | J17: =IF(Service_Providers!C13="","",Service_Providers!C13) -> 803-280-5234 | K17: =IF(Service_Providers!D13="","",Service_Providers!D13) -> chris.powers@hotmail.com
... A22: NV | B22: =COUNTIF(Accounts!$G$2:$G$299,A22) -> 2 | C22: =COUNTIFS(Accounts!$G$2:$G$299,A22,Accounts!$I$2:$I$299,"<>") -> 2 | D22: =COUNTIFS(Accounts!$G$2:$G$299,A22,Accounts!$K$2:$K$299,"") -> 0 | E22: =IF(B22=0,0,(B22-D22)/B22) -> 1 | G22: =IF(Service_Providers!A18="","",Service_Providers!A18) -> ETSC (EspressoTech Service Company) | H22: =IF(G22="","",COUNTIF(Accounts!$K$2:$K$299,G22)) -> 7 | I22: =IF(G22="","",COUNTIF(Accounts!$M$2:$M$299,G22)) -> 1 | J22: =IF(Service_Providers!C18="","",Service_Providers!C18) -> (888) 523-1684 | K22: =IF(Service_Providers!D18="","",Service_Providers!D18) -> service@etsc.coffee
A23: OK | B23: =COUNTIF(Accounts!$G$2:$G$299,A23) -> 4 | C23: =COUNTIFS(Accounts!$G$2:$G$299,A23,Accounts!$I$2:$I$299,"<>") -> 4 | D23: =COUNTIFS(Accounts!$G$2:$G$299,A23,Accounts!$K$2:$K$299,"") -> 0 | E23: =IF(B23=0,0,(B23-D23)/B23) -> 1 | G23: =IF(Service_Providers!A20="","",Service_Providers!A20) -> First Coast Espresso | H23: =IF(G23="","",COUNTIF(Accounts!$K$2:$K$299,G23)) -> 1 | I23: =IF(G23="","",COUNTIF(Accounts!$M$2:$M$299,G23)) -> 0 | J23: =IF(Service_Providers!C20="","",Service_Providers!C20) -> 904-654-5662 | K23: =IF(Service_Providers!D20="","",Service_Providers!D20) -> jose@firstcoastespresso.com
A24: PA | B24: =COUNTIF(Accounts!$G$2:$G$299,A24) -> 1 | C24: =COUNTIFS(Accounts!$G$2:$G$299,A24,Accounts!$I$2:$I$299,"<>") -> 1 | D24: =COUNTIFS(Accounts!$G$2:$G$299,A24,Accounts!$K$2:$K$299,"") -> 0 | E24: =IF(B24=0,0,(B24-D24)/B24) -> 1 | G24: =IF(Service_Providers!A21="","",Service_Providers!A21) -> Iconik Coffee | H24: =IF(G24="","",COUNTIF(Accounts!$K$2:$K$299,G24)) -> 0 | I24: =IF(G24="","",COUNTIF(Accounts!$M$2:$M$299,G24)) -> 0 | J24: =IF(Service_Providers!C21="","",Service_Providers!C21) -> (505) 428-0669 | K24: =IF(Service_Providers!D21="","",Service_Providers!D21) -> sean@iconikcoffee.com
A25: SC | B25: =COUNTIF(Accounts!$G$2:$G$299,A25) -> 1 | C25: =COUNTIFS(Accounts!$G$2:$G$299,A25,Accounts!$I$2:$I$299,"<>") -> 1 | D25: =COUNTIFS(Accounts!$G$2:$G$299,A25,Accounts!$K$2:$K$299,"") -> 0 | E25: =IF(B25=0,0,(B25-D25)/B25) -> 1 | G25: =IF(Service_Providers!A23="","",Service_Providers!A23) -> Izzy's Espresso Services Inc. | H25: =IF(G25="","",COUNTIF(Accounts!$K$2:$K$299,G25)) -> 0 | I25: =IF(G25="","",COUNTIF(Accounts!$M$2:$M$299,G25)) -> 0 | J25: =IF(Service_Providers!C23="","",Service_Providers!C23) -> 816-373-7011 | K25: =IF(Service_Providers!D23="","",Service_Providers!D23) -> chris@izzysespresso.com
A26: TN | B26: =COUNTIF(Accounts!$G$2:$G$299,A26) -> 1 | C26: =COUNTIFS(Accounts!$G$2:$G$299,A26,Accounts!$I$2:$I$299,"<>") -> 1 | D26: =COUNTIFS(Accounts!$G$2:$G$299,A26,Accounts!$K$2:$K$299,"") -> 0 | E26: =IF(B26=0,0,(B26-D26)/B26) -> 1 | G26: =IF(Service_Providers!A24="","",Service_Providers!A24) -> Jaguar Coffee Co. | H26: =IF(G26="","",COUNTIF(Accounts!$K$2:$K$299,G26)) -> 5 | I26: =IF(G26="","",COUNTIF(Accounts!$M$2:$M$299,G26)) -> 1 | J26: =IF(Service_Providers!C24="","",Service_Providers!C24) -> 352 442 2506 | K26: =IF(Service_Providers!D24="","",Service_Providers!D24) -> sam.mendez@jaguarcoffee.com
A27: TX | B27: =COUNTIF(Accounts!$G$2:$G$299,A27) -> 10 | C27: =COUNTIFS(Accounts!$G$2:$G$299,A27,Accounts!$I$2:$I$299,"<>") -> 10 | D27: =COUNTIFS(Accounts!$G$2:$G$299,A27,Accounts!$K$2:$K$299,"") -> 0 | E27: =IF(B27=0,0,(B27-D27)/B27) -> 1 | G27: =IF(Service_Providers!A25="","",Service_Providers!A25) -> JVG Coffee Mechanics | H27: =IF(G27="","",COUNTIF(Accounts!$K$2:$K$299,G27)) -> 1 | I27: =IF(G27="","",COUNTIF(Accounts!$M$2:$M$299,G27)) -> 0 | J27: =IF(Service_Providers!C25="","",Service_Providers!C25) -> 919-240-8083 | K27: =IF(Service_Providers!D25="","",Service_Providers!D25) -> hayes@jvgcoffeemechanics.com
A28: VA | B28: =COUNTIF(Accounts!$G$2:$G$299,A28) -> 2 | C28: =COUNTIFS(Accounts!$G$2:$G$299,A28,Accounts!$I$2:$I$299,"<>") -> 2 | D28: =COUNTIFS(Accounts!$G$2:$G$299,A28,Accounts!$K$2:$K$299,"") -> 1 | E28: =IF(B28=0,0,(B28-D28)/B28) -> 0.5 | G28: =IF(Service_Providers!A27="","",Service_Providers!A27) -> Ken's Beverage | H28: =IF(G28="","",COUNTIF(Accounts!$K$2:$K$299,G28)) -> 0 | I28: =IF(G28="","",COUNTIF(Accounts!$M$2:$M$299,G28)) -> 0 | J28: =IF(Service_Providers!C27="","",Service_Providers!C27) -> 317.888.6400 | K28: =IF(Service_Providers!D27="","",Service_Providers!D27) -> awhitlock@kensbeverage.com
A29: TOTAL | B29: =SUM(B6:B28) -> 76 | C29: =SUM(C6:C28) -> 76 | D29: =SUM(D6:D28) -> 2 | E29: =IF(B29=0,0,(B29-D29)/B29) -> 0.97368421 | G29: =IF(Service_Providers!A28="","",Service_Providers!A28) -> LIQUISERVE LLC | H29: =IF(G29="","",COUNTIF(Accounts!$K$2:$K$299,G29)) -> 1 | I29: =IF(G29="","",COUNTIF(Accounts!$M$2:$M$299,G29)) -> 0 | J29: =IF(Service_Providers!C28="","",Service_Providers!C28) -> Toll Free: 800-528-6625 Main: 505-247-3707 | K29: =IF(Service_Providers!D28="","",Service_Providers!D28) -> Service@LiquiServe.com
G30: =IF(Service_Providers!A30="","",Service_Providers!A30) -> MB Coffee Services | H30: =IF(G30="","",COUNTIF(Accounts!$K$2:$K$299,G30)) -> 1 | I30: =IF(G30="","",COUNTIF(Accounts!$M$2:$M$299,G30)) -> 0 | J30: =IF(Service_Providers!C30="","",Service_Providers!C30) -> 509.302.7071 | K30: =IF(Service_Providers!D30="","",Service_Providers!D30)
G31: =IF(Service_Providers!A31="","",Service_Providers!A31) -> Midwest Equipment & Espresso Specialists, Inc. | H31: =IF(G31="","",COUNTIF(Accounts!$K$2:$K$299,G31)) -> 0 | I31: =IF(G31="","",COUNTIF(Accounts!$M$2:$M$299,G31)) -> 0 | J31: =IF(Service_Providers!C31="","",Service_Providers!C31) -> 402-293-7490 | K31: =IF(Service_Providers!D31="","",Service_Providers!D31) -> Paul@meesi.omhcoxmail.com
G32: =IF(Service_Providers!A32="","",Service_Providers!A32) -> Orleans Coffee / Perfect Shot Espresso Service | H32: =IF(G32="","",COUNTIF(Accounts!$K$2:$K$299,G32)) -> 1 | I32: =IF(G32="","",COUNTIF(Accounts!$M$2:$M$299,G32)) -> 0 | J32: =IF(Service_Providers!C32="","",Service_Providers!C32) -> 504-827-0878 (Office) | K32: =IF(Service_Providers!D32="","",Service_Providers!D32) -> robbie@orleanscoffee.com
G33: =IF(Service_Providers!A33="","",Service_Providers!A33) -> Prestige Technical Services | H33: =IF(G33="","",COUNTIF(Accounts!$K$2:$K$299,G33)) -> 4 | I33: =IF(G33="","",COUNTIF(Accounts!$M$2:$M$299,G33)) -> 0 | J33: =IF(Service_Providers!C33="","",Service_Providers!C33) -> 636-583-5788 | K33: =IF(Service_Providers!D33="","",Service_Providers!D33) -> prestigetech@prestigetech.us
G34: =IF(Service_Providers!A34="","",Service_Providers!A34) -> PriorityOne Group | H34: =IF(G34="","",COUNTIF(Accounts!$K$2:$K$299,G34)) -> 8 | I34: =IF(G34="","",COUNTIF(Accounts!$M$2:$M$299,G34)) -> 0 | J34: =IF(Service_Providers!C34="","",Service_Providers!C34) -> (800) 226-7146 | K34: =IF(Service_Providers!D34="","",Service_Providers!D34) -> service@priorityone247.com
G35: =IF(Service_Providers!A35="","",Service_Providers!A35) -> Remolinos Group | H35: =IF(G35="","",COUNTIF(Accounts!$K$2:$K$299,G35)) -> 2 | I35: =IF(G35="","",COUNTIF(Accounts!$M$2:$M$299,G35)) -> 0 | J35: =IF(Service_Providers!C35="","",Service_Providers!C35) -> 479.647.6800 | K35: =IF(Service_Providers!D35="","",Service_Providers!D35) -> tech@fidel.coffee
G36: =IF(Service_Providers!A36="","",Service_Providers!A36) -> Shepspresso Solutions | H36: =IF(G36="","",COUNTIF(Accounts!$K$2:$K$299,G36)) -> 0 | I36: =IF(G36="","",COUNTIF(Accounts!$M$2:$M$299,G36)) -> 0 | J36: =IF(Service_Providers!C36="","",Service_Providers!C36) -> 833.377.7370 | K36: =IF(Service_Providers!D36="","",Service_Providers!D36) -> info@shepspresso.com
G37: =IF(Service_Providers!A37="","",Service_Providers!A37) -> STCS | H37: =IF(G37="","",COUNTIF(Accounts!$K$2:$K$299,G37)) -> 7 | I37: =IF(G37="","",COUNTIF(Accounts!$M$2:$M$299,G37)) -> 0 | J37: =IF(Service_Providers!C37="","",Service_Providers!C37) -> 956-536-7846 | K37: =IF(Service_Providers!D37="","",Service_Providers!D37) -> alanmcgee@msn.com
G38: =IF(Service_Providers!A38="","",Service_Providers!A38) -> Stephen's Service Techician | H38: =IF(G38="","",COUNTIF(Accounts!$K$2:$K$299,G38)) -> 0 | I38: =IF(G38="","",COUNTIF(Accounts!$M$2:$M$299,G38)) -> 0 | J38: =IF(Service_Providers!C38="","",Service_Providers!C38) -> 806.789.0810 | K38: =IF(Service_Providers!D38="","",Service_Providers!D38)
G39: =IF(Service_Providers!A39="","",Service_Providers!A39) -> Swanson Service | H39: =IF(G39="","",COUNTIF(Accounts!$K$2:$K$299,G39)) -> 0 | I39: =IF(G39="","",COUNTIF(Accounts!$M$2:$M$299,G39)) -> 0 | J39: =IF(Service_Providers!C39="","",Service_Providers!C39) -> (515) 993-2272 | K39: =IF(Service_Providers!D39="","",Service_Providers!D39) -> swansonservice@msn.com
G40: =IF(Service_Providers!A40="","",Service_Providers!A40) -> Thunderbird Equipment Service | H40: =IF(G40="","",COUNTIF(Accounts!$K$2:$K$299,G40)) -> 4 | I40: =IF(G40="","",COUNTIF(Accounts!$M$2:$M$299,G40)) -> 0 | J40: =IF(Service_Providers!C40="","",Service_Providers!C40) -> 480-294-2434 | K40: =IF(Service_Providers!D40="","",Service_Providers!D40) -> service@thunderbirdequipment.com
G41: =IF(Service_Providers!A41="","",Service_Providers!A41) -> Ultimate Espresso Services | H41: =IF(G41="","",COUNTIF(Accounts!$K$2:$K$299,G41)) -> 1 | I41: =IF(G41="","",COUNTIF(Accounts!$M$2:$M$299,G41)) -> 1 | J41: =IF(Service_Providers!C41="","",Service_Providers!C41) -> 314.541.5256 | K41: =IF(Service_Providers!D41="","",Service_Providers!D41) -> ultimateespressoservices@gmail.com
G42: =IF(Service_Providers!A42="","",Service_Providers!A42) -> WHITEHEAD FOOD EQUIPMENT | H42: =IF(G42="","",COUNTIF(Accounts!$K$2:$K$299,G42)) -> 0 | I42: =IF(G42="","",COUNTIF(Accounts!$M$2:$M$299,G42)) -> 0 | J42: =IF(Service_Providers!C42="","",Service_Providers!C42) -> Office: 405-528-5117 | K42: =IF(Service_Providers!D42="","",Service_Providers!D42) -> Nate@wfeokc.com
G43: =IF(Service_Providers!A26="","",Service_Providers!A26) -> Katz Coffee | H43: =IF(G43="","",COUNTIF(Accounts!$K$2:$K$299,G43)) -> 2 | I43: =IF(G43="","",COUNTIF(Accounts!$M$2:$M$299,G43)) -> 0 | J43: =IF(Service_Providers!C26="","",Service_Providers!C26) -> 713.864.3338 | K43: =IF(Service_Providers!D26="","",Service_Providers!D26) -> service@katzcoffee.com
G44: =IF(Service_Providers!A43="","",Service_Providers!A43) | H44: =IF(G44="","",COUNTIF(Accounts!$K$2:$K$299,G44)) | I44: =IF(G44="","",COUNTIF(Accounts!$M$2:$M$299,G44)) | J44: =IF(Service_Providers!C43="","",Service_Providers!C43) | K44: =IF(Service_Providers!D43="","",Service_Providers!D43)
G45: =IF(Service_Providers!A44="","",Service_Providers!A44) | H45: =IF(G45="","",COUNTIF(Accounts!$K$2:$K$299,G45)) | I45: =IF(G45="","",COUNTIF(Accounts!$M$2:$M$299,G45)) | J45: =IF(Service_Providers!C44="","",Service_Providers!C44) | K45: =IF(Service_Providers!D44="","",Service_Providers!D44)
...

Sheet Service_Providers
A1: Provider_Name | B1: Status | C1: Primary Dispatch Phone | D1: Primary Dispatch Email | E1: Secondary Dispatch Phone | F1: Secondary Dispatch Email | G1: Response Time | H1: Standard Rate | I1: After Hours Rate | J1: Travel Rate Policy | K1: Equipment Serviced | L1: States / ZIP Coverage | M1: Contacts | N1: PM Pricing | O1: Parts Stocking | P1: Coverage Notes / Key Notes | Q1: Last_Updated
A2: A-1 Restuarant Service | L2: TX | M2: 1407 Tulip Ln. Odessa, TX 79761 | Q2: 2026-07-15
A3: A-Tech Espresso & Coffee Service Inc. | C3: 866.333.7350 | D3: servicerequest@Atech-service.com | L3: CA | M3: Contact: Paul Phone: 866.333.7350 servicerequest@Atech-service.com | Q3: 2026-07-15
A4: ABS Coffee Repair | C4: 314.389.2866 | L4: MO | M4: Contact: John Meese Phone: 314.389.2866 | Q4: 2026-07-15
A5: All Espresso Service | B5: Active | C5: 754.205.5076 | D5: service@allespressoservice.com | E5: 954.263.9530 | F5: miguel@allespressoservice.com | H5: Labor $100 Travel $100 hr | I5: Labor OT $150 Trip OT $150 | L5: FL | M5: Contact: Lillie Morton service@allespressoservice.com (866) 237-7782 | Q5: 2026-07-15
A6: All Star Coffee Service | B6: Active | C6: 626-315-8498 | D6: allstarcoffeeservice@gmail.com | E6: 626-627-9369 | H6: Labor $135 hr Travel $135 hr | L6: CA | M6: Contact: Fernando Phone: 626-315-8498 Cell: 626-627-9369 | Q6: 2026-07-15
A7: Anytime Beverage Service | B7: Active | C7: Contact: Cynthia Phone: 714-335-9964 Cell: 714-395-8108 | D7: anytimebeverageservice@gmail.com | E7: Emergency Service Calls 714-335-9964 | F7: absdispatch@gmail.com | L7: CA, CO | M7: Contact: Cynthia Phone: 714-335-9964 Cell: 714-395-8108 Servi23275 Lawson Rd Corona, CA 92883 US www.anytimebeverageservice.com Accounting, Installation and Preventative Maintenance 714-395-8108 anytimebeverageservice@gmail.com | Q7: 2026-07-15
A8: B & B Coffee Service | C8: 361.855.3066 | L8: TX | M8: Phone: 361.855.3066 4307 S Port Ave Ste 128 Corpus Christi, TX 78415 Note: 78 miles away. Closest Bunn Certified Company. | P8: Note: 78 miles away. Closest Bunn Certified Company. | Q8: 2026-07-15
A9: Bar 9 Coffee Services LLC | B9: Active | C9: 443-460-4303 | D9: chuck@bar9coffee.com | L9: DC | M9: Jeremy Lattimer Owner Phone: 443-460-4303 Chuck - Service Coordinator chuck@bar9coffee.com | Q9: 2026-07-15
A10: Best Beverage Equipment Service | B10: Active | C10: 866-966-5799 ext 1 | D10: service@bestbeverage.net | L10: AR, TN | M10: service@bestbeverage.net Phone: 866-966-5799 Contact: Dustin or Melissa. Contact: Dustin Smith Phone: 866-966-5799 ext 1 service@bestbeverage.net | Q10: 2026-07-15
A11: Bev Pro Services | C11: 410-571-4902 ext. 501 (Office) | E11: 410-693-7591 (Mobile) | L11: MD, VA | M11: Contact: Thomas Erber 410-571-4902 ext. 501 Office/ 410-693-7591 Mobile 2100 Concord Blvd. Suite K Crofton, MD 21114 Contact: Thomas Erber 410-571-4902 ext. 501 Office 410-693-7591 Mobile 2100 Concord Blvd. Suite K Crofton, MD 21114 | Q11: 2026-07-15
A12: Beverage Equipment Service Inc. | B12: Active | C12: (515) 494-0849 | D12: bevequip@outlook.com (best - copied on all comms) | F12: rdachenbach@beverageequipmentservice.net | G12: Same-day / Next-day | H12: $105/hr (labor + travel included) | I12: $157.50/hr (1.5x) | J12: $105/hr both directions; no separate truck/mileage charge; can batch/split calls to reduce cost | K12: Wilbur Curtis (full service); Schaerer espresso incl. super-automatic; Coffee Art Pro & bean-to-cup (extremely experienced); recently trained on WMF 5000 and Soul C | L12: IA IA ZIPs: 50158, 50248, 50401, 50421, 50447, 50468, 50525, 50590, 50595, 50703, 51446, 51454, 51531, 51537, 51546, 52501, 52544 | M12: Ryan Dachenbach (President) Phone: (515) 494-0849 Email: rdachenbach@beverageequipmentservice.net Fax: (641) 774-8749 | N12: $176 per machine + parts (SCA1 bean-to-cup example, incl. O-rings; negotiable on volume) | O12: Wide parts variety stocked on vehicles + warehouse for one-trip fixes; large stock of 3M HF-40S filters | P12: Covers all listed Iowa ZIPs. Cedar Rapids area: tech visits at least weekly. North Central / NE Iowa: some sites 2-3 hrs one-way; calls batched to control travel cost. Confirmed OK with paying travel both ways when needed. Ready to set up as client. High priority on minimizing downtime. | Q12: 2026-06-24
A13: Carolina Beverage Solutions | B13: Active | C13: 803-280-5234 | D13: chris.powers@hotmail.com | F13: billing@carolinabev.com | L13: NC, SC | M13: 117 Kanawha Street Fort Mill, SC 29715 Phone: 803-280-5234 Contact: Chris / Val chris.powers@hotmail.com billing@carolinabev.com service@carolinabev.com | Q13: 2026-07-15
A14: Commercial Kitchen | C14: 956.664.8267 | L14: TX | M14: Phone: 956.664.8267 | Q14: 2026-07-15
A15: Duke Services | C15: 714.525.2866 | L15: CA | M15: Phone: 714.525.2866 | Q15: 2026-07-15
A16: Espresso Enterprises | B16: Active | C16: 317-876-9031 | D16: carey@espressoenterprises.com | L16: IN | M16: Contact: Troy Smith/Carey Phone: 317-876-9031 carey@espressoenterprises.com | P16: 1-hour minimum. After first hour billed in 15-min increments. | Q16: 2026-07-15
A17: Espresso Southeast | B17: Active | C17: 770-867-3111 | D17: service@espressosoutheast.com | F17: priscila@espressosoutheast.com | G17: Same day when possible; most calls completed the next day | H17: Labor $100 / hour Travel $100 / hour | I17: Labor $150 / hour Travel $150 / hour Time-and-a-half on labor and travel. | J17: One-way billing (standard). 1-hour minimum. Extended travel may be billed round-trip case-by-case | K17: • Espresso: Most major brands — La Marzocco, Nuova Simonelli, Rancilio, Cimbali, Faema, and others • Coffee & Tea: Fetco, Curtis (Wilbur Curtis), Bunn | L17: – I-85N Greenville, SC – I-20E Augusta, GA – I-16E Swainsboro, GA – I-75S Cordele, GA – I-85S Auburn, AL – I-20W Oxford, AL – I-75N Chattanooga, TN | M17: Owner: Mario Scoccimaro Service Manager: Andrew Kane Mario Jr. Priscila (priscila@espressosoutheast.com) Phone: 770-867-3111 service@espressosoutheast.com | N17: N/A (no formal PM pricing program mentioned). | O17: Extensive inventory for many espresso machines. Fetco inventory is also extensive. Curtis and Bunn have many common parts (somewhat less depth). • If a part is not in stock they can order quickly, or they are happy to use parts you supply from your inventory. | P17: – I-85N Greenville, SC – I-20E Augusta, GA – I-16E Swainsboro, GA – I-75S Cordele, GA – I-85S Auburn, AL – I-20W Oxford, AL – I-75N Chattanooga, TN | Q17: 2026-07-15
A18: ETSC (EspressoTech Service Company) | B18: Active | C18: (888) 523-1684 | D18: service@etsc.coffee | F18: Jess@etsc.coffee | G18: Standard 24-48 hrs (priority & tech availability); same-day when possible | H18: $195 first hour | $125 each additional hour $70/hr travel | I18: 1.5x standard rates (after-hours / weekend) | J18: $70/hr travel for locations outside tech's local service area | K18: Wilbur Curtis - supported; Schaerer espresso - supported (carries Schaerer parts to maximize first-time fix) | L18: KS, IA, IL, MO, NE, CO, OK, MN, WI, TN + more KS ZIPs: 67456, 67460, 67501, 67502, 67554 MO ZIPs: 64804, 64850 | M18: Jessica Peacock Phone: (888) 523-1684 Email: Jess@etsc.coffee Regional contacts (merged from Espresso Tech / ETSC STL): [Illinois] service @ espressotechsc.com | 816-523-1684Technical Support Center | 11614 W 90th Street | Overland Park, KS 66214 [Kansas] Contact: Mark Robey | Phone: 816.523.1684 | service.espressotech@gmail.com [Missouri] Contact: Liz | Phone: 314-939-7159 | liz@etsc.coffee) | 1500 South 1st Capitol Drive Unit 344 | Saint Charles Missouri 63303 | 1500 South 1st Capitol Drive Unit 344 Saint Charles Missouri 63303 | N18: PM billed at standard service rates ($195 first hr / $125 add'l) | O18: Techs carry van stock of common Wilbur Curtis and Schaerer parts | P18: Tech hubs: Overland Park & Wichita KS | Des Moines & Quad Cities IA | Chicago | St. Louis | Elkhorn NE | Denver | Tulsa (OKC coming soon) | Bloomington MN | Milwaukee | Nashville (Knoxville coming soon). KS ZIPs covered: 67456, 67460, 67501, 67502, 67554. | Q18: 2026-07-15
A19: FASTCILITY CORP | B19: Active | C19: Office: (833) 203-2285 | D19: Service@FASTCILITYCORP.COM https://app.servicefusion.com/fastcility Username: Jesus@katzcoffee.com F!xmy5!t03 | E19: 714) 520-1486 | F19: ddavenport@fastcilitycorp.com | H19: Labor $115 / hour 1-hour minimum Travel $115 flat fee Flat fee (not hourly) Fuel Surcharge $25 flat fee Applied per call Parts 25% markup from cost For any parts used during repair | K19: • Bunn • Fetco • Wilbur Curtis • Schaerer • Eversys • La Marzocco • Mazzer • Everpure | L19: • Primary service region: Southwest U.S. (CA, AZ, NV, NM, TX) | M19: Dalton Davenport Business Development Manager Mobile: (714) 520-1486 Email: ddavenport@fastcilitycorp.com | P19: • Confirmed coverage: All ZIP codes provided in the Excel list for Arizona, California, New Mexico, Nevada, and Texas • Excluded: Illinois locations (Chicago / Rosemont) — not covered • Primary service region: Southwest U.S. (CA, AZ, NV, NM, TX) • Note: San Antonio / Austin area coverage requested for near-term expansion
A20: First Coast Espresso | B20: Pending Setup | C20: 904-654-5662 | D20: jose@firstcoastespresso.com | E20: 904-379-1455 | L20: GA | M20: Jose Parada jose@firstcoastespresso.com 3653 Regent Blvd Suite 203 Jacksonville, Fl 32224 904-654-5662 cell 904-379-1455 office $95 per hr labor and $95 per hr trip. 4 hr round trip. | Q20: 2026-07-15
A21: Iconik Coffee | B21: Inactive | C21: (505) 428-0669 | D21: sean@iconikcoffee.com | L21: NM | M21: Sean Ham sean@iconikcoffee.com Phone: (505) 428-0669 1366 Cerrillos Rd Santa Fe, NM 87505 | Q21: 2026-07-15
A22: Intergrated Coffee Solutions | B22: Active | C22: Phone / Text: (864) 606-4418 | D22: integratedcoffeesolutions@gmail.com | E22: Phone / Text: (864) 606-4418 | F22: integratedcoffeesolutions@gmail.com | G22: Within 72 hours (depends on dispatch schedule) | H22: Standard Labor $115 / hour Standard hourly rate Standard Travel $115 / hour 1-hour minimum after 15 minutes of travel. No return rate charged. | I22: Emergency Labor $175 / hour Emergency / after-hours rate Emergency Travel $175 / hour Same 1-hour minimum after 15 min. No return rate charged. | J22: Will travel up to 3 hours from Spartanburg, SC before return travel rates apply. Coverage area is variable beyond that. | K22: • Traditional Espresso: La Marzocco, Astoria, Rocket Espresso, Nuova Simonelli, Synesso, Victoria Arduino, Wega, and more major brands • Superautomatic: Most brands of superautomatic coffee machines • Tea Equipment: Most tea equipment supported | L22: SC | M22: Julia Richardson Director of Communications Same phone: (864) 606-4418 (text OK) Email: integratedcoffeesolutions@gmail.com Website: integratedcoffeesolutions.com | N22: • PM Programs: Yes — monthly installment plans available. Pricing generally ranges from $75–$150 per month depending on the machine. Happy to discuss specifics for your locations. | O22: • Parts: Stock common parts for major brands on trucks. Specialty parts or less-common brands are ordered as needed. | P22: • Emergency Response: Typically within 24 hours • Primary Coverage: Upstate South Carolina (including Powdersville) • Travel Radius: Will travel up to 3 hours from Spartanburg, SC before return travel rates apply. Coverage area is variable beyond that. | Q22: 2026-07-15
A23: Izzy's Espresso Services Inc. | C23: 816-373-7011 | D23: chris@izzysespresso.com | L23: KS | M23: Owner: Chris Isariotis Phone: 816-373-7011 chris@izzysespresso.com | Q23: 2026-07-15
A24: Jaguar Coffee Co. | C24: 352 442 2506 | D24: sam.mendez@jaguarcoffee.com | L24: FL | M24: Contact: Samantha Mendez Phone: 352 442 2506 sam.mendez@jaguarcoffee.com | Q24: 2026-07-15
A25: JVG Coffee Mechanics | B25: Active | C25: 919-240-8083 | D25: hayes@jvgcoffeemechanics.com | L25: VA | M25: 505 Meadowlands Dr Unit 101 Hillsborough, NC 27278 hayes@jvgcoffeemechanics.com 919-240-8083 | Q25: 2026-07-15
A26: Katz Coffee | B26: Active | C26: 713.864.3338 | D26: service@katzcoffee.com | E26: 832.517.9773 | Q26: 46219
A27: Ken's Beverage | C27: 317.888.6400 | D27: awhitlock@kensbeverage.com | L27: IN | M27: Contact: Alan Whitlock Phone: 317.888.6400 awhitlock@kensbeverage.com | Q27: 2026-07-15
A28: LIQUISERVE LLC | B28: Active | C28: Toll Free: 800-528-6625 Main: 505-247-3707 | D28: Service@LiquiServe.com | E28: Office: 505-247-3707 Ext. 1227 Mobile: 505-977-8066 505-308-8682 | F28: Matthew.Baca@LiquiServe.com | G28: Response Time: Next business day (standard). Same-day possible depending on priority/availability. | H28: Labor (Service/Repair/Install) $95/hr Travel $95/hr | I28: Labor (Service/Repair/Install) $142.50/hr Travel$142.50/hr Billed in 15-min increments after first hour. OT for calls outside normal business hours. Fuel surcharge $5 | J28: Round trip from nearest warehouse. Local zone = one-way 30-min charge. | K28: • Wilbur Curtis — Supported (stocked parts) • Schaerer — Supported (stocked parts) • Other: Bunn, Eversys also supported with stocked parts. Rancilio serviced but limited stock. | L28: SD ZIPs: 57501, 57532, 57543, 57551, 57701, 57703, 57717, 57719, 57730, 57735, 57747, 57783, 57785 | M28: Matthew Baca CFO / Primary Contact Dirk Brunson Field Service Supervisor Phone: Office: 505-247-3707 Ext. 1227 Mobile: 505-977-8066 505-308-8682 Email: Matthew.Baca@LiquiServe.com | N28: Preventive Maintenance (PM) $95/hr (or agreed flat) | O28: • Wilbur Curtis — Supported (stocked parts) • Schaerer — Supported (stocked parts) • Other: Bunn, Eversys also supported with stocked parts. Rancilio serviced but limited stock. | P28: Coverage: Broad multi-state territory. For the latest inquiry, most ZIPs in NM, TX, OK, NE are covered. Warehouses: Multiple regional warehouses (travel billed from nearest one). Strong presence in Southwest & Plains states. | Q28: 2026-07-09
A29: Masket Services | B29: Active | C29: 866-803-8088 | D29: service@masketservices.com | E29: 866-803-8088 | F29: shane@masketservices.com | K29: Eversys, Franke, Schaerer , Nuova, Cimbali , Rancilio , Unic , La Marzocco, Synesso, Wega, WMF, Gaggia Curtis, Fetco, Bunn after warranty work | L29: PA | M29: Shane Stroman Service / Sales shane@masketservices.com / 866-803-8088 | Q29: 46223
A30: MB Coffee Services | C30: 509.302.7071 | L30: CA | M30: Contact: Mathew Phone: 509.302.7071 | Q30: 2026-07-15
A31: Midwest Equipment & Espresso Specialists, Inc. | C31: 402-293-7490 | D31: Paul@meesi.omhcoxmail.com | E31: 402-293-7503 | L31: KS, NE | M31: Contact: Jen Phone: 402-293-7490 Fax: 402-293-7503 Paul@meesi.omhcoxmail.com | Q31: 2026-07-15
A32: Orleans Coffee / Perfect Shot Espresso Service | B32: Active | C32: 504-827-0878 (Office) | D32: robbie@orleanscoffee.com | E32: 504-258-6881 (Cell - Robbie Mahner) | L32: LA | M32: Orleans Coffee / Perfect Shot Espresso Service Robbie Mahner Service Manager Perfect Shot Espresso Service 504-258-6881 cell 504-827-0878 office robbie@orleanscoffee.com | Q32: 2026-07-15
A33: Prestige Technical Services | B33: Active | C33: 636-583-5788 | D33: prestigetech@prestigetech.us | L33: KS, OK | M33: Phone: 636-583-5788 prestigetech@prestigetech.us | Q33: 2026-07-15
A34: PriorityOne Group | B34: Active | C34: (800) 226-7146 | D34: service@priorityone247.com | E34: (800) 226-7146 | (303) 577-1285 CO | (505) 234-1831 NM/TX | G34: Zone 1: 24/7/365 | Zone 2: standard + on-call | Zone 3: clustered/scheduled | Zone 4: limited/out-of-area | H34: Beverage $90/hr | Espresso $105/hr | Cooking/Refrig $125-135/hr (valid 11/1/2025 - 12/31/2026) | I34: 1.5x (5pm-10pm) | 2x overnight (10pm-7:30am) | 2x holidays (24 hr) | J34: Travel billed in 15-min increments from last call location (GPS tracked); efficient routing by dispatch | K34: Full beverage equipment service: beverage, espresso, cooking, refrigeration/HVAC | L34: CO, NM, TX + surrounding NM ZIPs: 87002, 87004, 87013, 87020, 87021, 87031, 87104, 87105, 87114, 87121, 87124, 87301, 87401, 87501, 87505, 87507, 87508, 87532, 87571, 87701, 87732, 88007, 88012, 88081, 88201, 88301, 88310, 88317, 88336, 88345, 88353, 88401, 88435 | M34: Customer Service Team Phone: (800) 226-7146 | (303) 577-1285 CO | (505) 234-1831 NM/TX Email: service@priorityone247.com Fax: N/A (use main numbers) | N34: PM contracts available with discounted emergency rates | O34: Parts & equipment support via dedicated Parts team | P34: Strong coverage in CO Front Range, NM, and TX (see zone assignments on Stores tab). Labor & travel billed in quarter-hour increments via mobile/GPS. Fastest service: call Customer Service or email service@priorityone247.com. QR code available for quick requests. | Q34: 2026-06-24
A35: Remolinos Group | C35: 479.647.6800 | D35: tech@fidel.coffee | E35: 479.647.6800 | F35: fidel@remolinosgroup.com | L35: AR | M35: Fidel Samour 479.647.6800 | Q35: 2026-07-15
A36: Shepspresso Solutions | C36: 833.377.7370 | D36: info@shepspresso.com | E36: 970.432.4250 | L36: GA | M36: Shepspresso Solutions Jaime Palmer Business: 833.377.7370 Text for Service: 970.432.4250 info@shepspresso.com 730 Main St PMB358, North Myrtle Beach, SC 29582 | Q36: 2026-07-15
A37: STCS | B37: Active | C37: 956-536-7846 | D37: alanmcgee@msn.com | L37: TX | M37: Contact:Alan McGee Phone: 956-536-7846 Email: alanmcgee@msn.com 200 North Business 77 Combes, TX 78535 | Q37: 2026-07-15
A38: Stephen's Service Techician | C38: 806.789.0810 | L38: TX | M38: Contact: Don Phone: 806.789.0810 | Q38: 2026-07-15
A39: Swanson Service | B39: Active | C39: (515) 993-2272 | D39: swansonservice@msn.com | G39: Usually completes calls within 24 hrs | H39: Labor $90/hr Travel $115/hr | I39: OT: $135/hr labor + $172.50/hr travel (round trip) | J39: Travel $115/hr, round trip, billed hourly | K39: Wilbur Curtis (full service confirmed). Does NOT service Schaerer espresso machines. | L39: IA IA ZIPs: 50158, 50248, 50421, 50468, 50525, 50590, 50595, 50703, 51446, 51531, 51537, 51546, 52501, 52544 | M39: Scott Swanson / Lisa Phone: (515) 993-2272 Email: swansonservice@msn.com | N39: Not provided - follow up | O39: Carries parts on vehicle (details not provided) | P39: Main office in Adel, IA. Serves North Central / NE Iowa; confirmed they can service all listed locations. Same 15 IA ZIPs as Beverage Equipment Service. Response was brief - no details on PM pricing, parts stocking, dispatch process, or W-9. Follow-up recommended. | Q39: 2026-06-25
A40: Thunderbird Equipment Service | B40: Active | C40: 480-294-2434 | D40: service@thunderbirdequipment.com | E40: C| 480-294-2434 O| 602-675-2420 | F40: brian@thunderbirdequipment.com | G40: Same day or Next day | H40: Labor $120/hr Travel $85 hourly | K40: Eversys, Fetco | L40: AZ | M40: Thunderbird Equipment Brian Koren President and Founder Thunderbird Equipment Service 480-294-2434 C 602-675-2420 O Thunderbirdequipment.com 10439 N Cave Creek Rd Suite 10. Phoenix, AZ 85020 | Q40: 2026-07-15
...

Sheet Accounts
A1: Account Name | B1: Main Email | C1: Primary Contact | D1: Main Phone | E1: Address | F1: City | G1: State | H1: Zip | I1: Equipment Details | J1: Ownership | K1: Primary Provider | L1: Dispatch Phone & Email | M1: Secondary Provider | N1: Secondary Phone & Email | O1: Service Region | P1: Last Updated
A2: MTA Engineers, INC | B2: lajean@mtaengineers.com | C2: Claudia Bremer | D2: 501.753.2526 | E2: 8001 National Drive | F2: Little Rock | G2: AR | H2: 72209 | I2: Virtu 9236A | J2: Lease | K2: Remolinos Group | L2: =IF($K2="","",IFERROR(IF(INDEX(Service_Providers!$C$2:$C$104,MATCH($K2,Service_Providers!$A$2:$A$104,0))="","",INDEX(Service_Providers!$C$2:$C$104,MATCH($K2,Service_Providers!$A$2:$A$104,0)))&IF(AND(INDEX(Service_Providers!$C$2:$C$104,MATCH($K2,Service_Providers!$A$2:$A$104,0))<>"",INDEX(Service_Providers!$D$2:$D$104,MATCH($K2,Service_Providers!$A$2:$A$104,0))<>""),CHAR(10),"")&IF(INDEX(Service_Providers!$D$2:$D$104,MATCH($K2,Service_Providers!$A$2:$A$104,0))="","",INDEX(Service_Providers!$D$2:$D$104,MATCH($K2,Service_Providers!$A$2:$A$104,0))),"Provider not found")) -> 479.647.6800 tech@fidel.coffee | M2: Best Beverage Equipment Service | N2: =IF($M2="","",IFERROR(IF(INDEX(Service_Providers!$C$2:$C$104,MATCH($M2,Service_Providers!$A$2:$A$104,0))="","",INDEX(Service_Providers!$C$2:$C$104,MATCH($M2,Service_Providers!$A$2:$A$104,0)))&IF(AND(INDEX(Service_Providers!$C$2:$C$104,MATCH($M2,Service_Providers!$A$2:$A$104,0))<>"",INDEX(Service_Providers!$D$2:$D$104,MATCH($M2,Service_Providers!$A$2:$A$104,0))<>""),CHAR(10),"")&IF(INDEX(Service_Providers!$D$2:$D$104,MATCH($M2,Service_Providers!$A$2:$A$104,0))="","",INDEX(Service_Providers!$D$2:$D$104,MATCH($M2,Service_Providers!$A$2:$A$104,0))),"Provider not found")) -> 866-966-5799 ext 1 service@bestbeverage.net | O2: Arkansas Area | P2: 2026-07-15
A3: Porsche Little Rock | B3: aravi@indigoautogroup.com | C3: Ashley Ravi | D3: 501.497.5656 | E3: 516 Colonel Glenn Plaza Loop | F3: Little Rock | G3: AR | H3: 72210 | I3: De Jong Duke Virtua93; La Marzocco Linea PB 2AV; La Marzocco Swift Grinder | J3: Lease; Owned - Purchased from Katz | K3: Remolinos Group | L3: =IF($K3="","",IFERROR(IF(INDEX(Service_Providers!$C$2:$C$104,MATCH($K3,Service_Providers!$A$2:$A$104,0))="","",INDEX(Service_Providers!$C$2:$C$104,MATCH($K3,Service_Providers!$A$2:$A$104,0)))&IF(AND(INDEX(Service_Providers!$C$2:$C$104,MATCH($K3,Service_Providers!$A$2:$A$104,0))<>"",INDEX(Service_Providers!$D$2:$D$104,MATCH($K3,Service_Providers!$A$2:$A$104,0))<>""),CHAR(10),"")&IF(INDEX(Service_Providers!$D$2:$D$104,MATCH($K3,Service_Providers!$A$2:$A$104,0))="","",INDEX(Service_Providers!$D$2:$D$104,MATCH($K3,Service_Providers!$A$2:$A$104,0))),"Provider not found")) -> 479.647.6800 tech@fidel.coffee | M3: Best Beverage Equipment Service | N3: =IF($M3="","",IFERROR(IF(INDEX(Service_Providers!$C$2:$C$104,MATCH($M3,Service_Providers!$A$2:$A$104,0))="","",INDEX(Service_Providers!$C$2:$C$104,MATCH($M3,Service_Providers!$A$2:$A$104,0)))&IF(AND(INDEX(Service_Providers!$C$2:$C$104,MATCH($M3,Service_Providers!$A$2:$A$104,0))<>"",INDEX(Service_Providers!$D$2:$D$104,MATCH($M3,Service_Providers!$A$2:$A$104,0))<>""),CHAR(10),"")&IF(INDEX(Service_Providers!$D$2:$D$104,MATCH($M3,Service_Providers!$A$2:$A$104,0))="","",INDEX(Service_Providers!$D$2:$D$104,MATCH($M3,Service_Providers!$A$2:$A$104,0))),"Provider not found")) -> 866-966-5799 ext 1 service@bestbeverage.net | O3: Arkansas Area | P3: 2026-07-15
A4: Dominick's Steakhouse | B4: joel@domsteak.com | D4: 480-272-7271 | E4: 15169 N Scottsdale Rd | F4: Scottsdale | G4: AZ | H4: 85254 | I4: Cameo c'2s (Downstairs); Cameo c'2s (Upstairs); Wilbur Curtis G4TP1S63A3100 Coffee Brewer; Wilbur Curtis ILGD-10 | J4: Owned - Purchased from 3rd Party | K4: Thunderbird Equipment Service | L4: =IF($K4="","",IFERROR(IF(INDEX(Service_Providers!$C$2:$C$104,MATCH($K4,Service_Providers!$A$2:$A$104,0))="","",INDEX(Service_Providers!$C$2:$C$104,MATCH($K4,Service_Providers!$A$2:$A$104,0)))&IF(AND(INDEX(Service_Providers!$C$2:$C$104,MATCH($K4,Service_Providers!$A$2:$A$104,0))<>"",INDEX(Service_Providers!$D$2:$D$104,MATCH($K4,Service_Providers!$A$2:$A$104,0))<>""),CHAR(10),"")&IF(INDEX(Service_Providers!$D$2:$D$104,MATCH($K4,Service_Providers!$A$2:$A$104,0))="","",INDEX(Service_Providers!$D$2:$D$104,MATCH($K4,Service_Providers!$A$2:$A$104,0))),"Provider not found")) -> 480-294-2434 service@thunderbirdequipment.com | M4: FASTCILITY CORP | N4: =IF($M4="","",IFERROR(IF(INDEX(Service_Providers!$C$2:$C$104,MATCH($M4,Service_Providers!$A$2:$A$104,0))="","",INDEX(Service_Providers!$C$2:$C$104,MATCH($M4,Service_Providers!$A$2:$A$104,0)))&IF(AND(INDEX(Service_Providers!$C$2:$C$104,MATCH($M4,Service_Providers!$A$2:$A$104,0))<>"",INDEX(Service_Providers!$D$2:$D$104,MATCH($M4,Service_Providers!$A$2:$A$104,0))<>""),CHAR(10),"")&IF(INDEX(Service_Providers!$D$2:$D$104,MATCH($M4,Service_Providers!$A$2:$A$104,0))="","",INDEX(Service_Providers!$D$2:$D$104,MATCH($M4,Service_Providers!$A$2:$A$104,0))),"Provider not found")) -> Office: (833) 203-2285 Service@FASTCILITYCORP.COM https://app.servicefusion.com/fastcility Username: Jesus@katzcoffee.com F!xmy5!t03 | O4: Arizona Area | P4: 2026-07-15
A5: Durant's Steakhouse | B5: andria@primesteakconcepts.com | C5: Paul Morris | D5: 6022645967 | E5: 2611 N Central Ave | F5: Phoenix | G5: AZ | H5: 85004 | I5: Fetco 1231 Plus; Eversys Cameo c'2s | J5: Loaned; Owned - Purchased from 3rd Party | K5: Thunderbird Equipment Service | L5: =IF($K5="","",IFERROR(IF(INDEX(Service_Providers!$C$2:$C$104,MATCH($K5,Service_Providers!$A$2:$A$104,0))="","",INDEX(Service_Providers!$C$2:$C$104,MATCH($K5,Service_Providers!$A$2:$A$104,0)))&IF(AND(INDEX(Service_Providers!$C$2:$C$104,MATCH($K5,Service_Providers!$A$2:$A$104,0))<>"",INDEX(Service_Providers!$D$2:$D$104,MATCH($K5,Service_Providers!$A$2:$A$104,0))<>""),CHAR(10),"")&IF(INDEX(Service_Providers!$D$2:$D$104,MATCH($K5,Service_Providers!$A$2:$A$104,0))="","",INDEX(Service_Providers!$D$2:$D$104,MATCH($K5,Service_Providers!$A$2:$A$104,0))),"Provider not found")) -> 480-294-2434 service@thunderbirdequipment.com | M5: FASTCILITY CORP | N5: =IF($M5="","",IFERROR(IF(INDEX(Service_Providers!$C$2:$C$104,MATCH($M5,Service_Providers!$A$2:$A$104,0))="","",INDEX(Service_Providers!$C$2:$C$104,MATCH($M5,Service_Providers!$A$2:$A$104,0)))&IF(AND(INDEX(Service_Providers!$C$2:$C$104,MATCH($M5,Service_Providers!$A$2:$A$104,0))<>"",INDEX(Service_Providers!$D$2:$D$104,MATCH($M5,Service_Providers!$A$2:$A$104,0))<>""),CHAR(10),"")&IF(INDEX(Service_Providers!$D$2:$D$104,MATCH($M5,Service_Providers!$A$2:$A$104,0))="","",INDEX(Service_Providers!$D$2:$D$104,MATCH($M5,Service_Providers!$A$2:$A$104,0))),"Provider not found")) -> Office: (833) 203-2285 Service@FASTCILITYCORP.COM https://app.servicefusion.com/fastcility Username: Jesus@katzcoffee.com F!xmy5!t03 | O5: Arizona Area | P5: 2026-07-15
A6: Ocean 44 Scottsdale | B6: craig@ocean44.com | D6: 480.867.0044 | E6: 4748 N Goldwater Blvd | F6: Scottsdale | G6: AZ | H6: 85251 | I6: Cameo c'2s; Wilbur Curtis G4TP1S63A3100 Coffee Brewer; Wilbur Curtis ILGD-10 Grinder | J6: Owned - Purchased from 3rd Party | K6: Thunderbird Equipment Service | L6: =IF($K6="","",IFERROR(IF(INDEX(Service_Providers!$C$2:$C$104,MATCH($K6,Service_Providers!$A$2:$A$104,0))="","",INDEX(Service_Providers!$C$2:$C$104,MATCH($K6,Service_Providers!$A$2:$A$104,0)))&IF(AND(INDEX(Service_Providers!$C$2:$C$104,MATCH($K6,Service_Providers!$A$2:$A$104,0))<>"",INDEX(Service_Providers!$D$2:$D$104,MATCH($K6,Service_Providers!$A$2:$A$104,0))<>""),CHAR(10),"")&IF(INDEX(Service_Providers!$D$2:$D$104,MATCH($K6,Service_Providers!$A$2:$A$104,0))="","",INDEX(Service_Providers!$D$2:$D$104,MATCH($K6,Service_Providers!$A$2:$A$104,0))),"Provider not found")) -> 480-294-2434 service@thunderbirdequipment.com | M6: FASTCILITY CORP | N6: =IF($M6="","",IFERROR(IF(INDEX(Service_Providers!$C$2:$C$104,MATCH($M6,Service_Providers!$A$2:$A$104,0))="","",INDEX(Service_Providers!$C$2:$C$104,MATCH($M6,Service_Providers!$A$2:$A$104,0)))&IF(AND(INDEX(Service_Providers!$C$2:$C$104,MATCH($M6,Service_Providers!$A$2:$A$104,0))<>"",INDEX(Service_Providers!$D$2:$D$104,MATCH($M6,Service_Providers!$A$2:$A$104,0))<>""),CHAR(10),"")&IF(INDEX(Service_Providers!$D$2:$D$104,MATCH($M6,Service_Providers!$A$2:$A$104,0))="","",INDEX(Service_Providers!$D$2:$D$104,MATCH($M6,Service_Providers!$A$2:$A$104,0))),"Provider not found")) -> Office: (833) 203-2285 Service@FASTCILITYCORP.COM https://app.servicefusion.com/fastcility Username: Jesus@katzcoffee.com F!xmy5!t03 | O6: Arizona Area | P6: 2026-07-15
A7: Steak 44 Phoenix | B7: jonathan@steak44.com | D7: 602.271.4400 | E7: 5101 N 44th St | F7: Phoenix | G7: AZ | H7: 85018 | I7: Wilbur Curtis G4TP1S63A100 Coffee Brewer; Bunn MHG Grinder; Cameo c'2s | J7: Owned - Purchased from 3rd Party | K7: Thunderbird Equipment Service | L7: =IF($K7="","",IFERROR(IF(INDEX(Service_Providers!$C$2:$C$104,MATCH($K7,Service_Providers!$A$2:$A$104,0))="","",INDEX(Service_Providers!$C$2:$C$104,MATCH($K7,Service_Providers!$A$2:$A$104,0)))&IF(AND(INDEX(Service_Providers!$C$2:$C$104,MATCH($K7,Service_Providers!$A$2:$A$104,0))<>"",INDEX(Service_Providers!$D$2:$D$104,MATCH($K7,Service_Providers!$A$2:$A$104,0))<>""),CHAR(10),"")&IF(INDEX(Service_Providers!$D$2:$D$104,MATCH($K7,Service_Providers!$A$2:$A$104,0))="","",INDEX(Service_Providers!$D$2:$D$104,MATCH($K7,Service_Providers!$A$2:$A$104,0))),"Provider not found")) -> 480-294-2434 service@thunderbirdequipment.com | M7: FASTCILITY CORP | N7: =IF($M7="","",IFERROR(IF(INDEX(Service_Providers!$C$2:$C$104,MATCH($M7,Service_Providers!$A$2:$A$104,0))="","",INDEX(Service_Providers!$C$2:$C$104,MATCH($M7,Service_Providers!$A$2:$A$104,0)))&IF(AND(INDEX(Service_Providers!$C$2:$C$104,MATCH($M7,Service_Providers!$A$2:$A$104,0))<>"",INDEX(Service_Providers!$D$2:$D$104,MATCH($M7,Service_Providers!$A$2:$A$104,0))<>""),CHAR(10),"")&IF(INDEX(Service_Providers!$D$2:$D$104,MATCH($M7,Service_Providers!$A$2:$A$104,0))="","",INDEX(Service_Providers!$D$2:$D$104,MATCH($M7,Service_Providers!$A$2:$A$104,0))),"Provider not found")) -> Office: (833) 203-2285 Service@FASTCILITYCORP.COM https://app.servicefusion.com/fastcility Username: Jesus@katzcoffee.com F!xmy5!t03 | O7: Arizona Area | P7: 2026-07-15
A8: iPEC | B8: mbaker@indigoautogroup.com | C8: Patrick Stam | D8: 760.393.4400 | E8: 6 Jasper Way | F8: Thermal | G8: CA | H8: 92274 | I8: Eversys Cameo c'2m; c'Fridge Beside | J8: Lease | K8: Anytime Beverage Service | L8: =IF($K8="","",IFERROR(IF(INDEX(Service_Providers!$C$2:$C$104,MATCH($K8,Service_Providers!$A$2:$A$104,0))="","",INDEX(Service_Providers!$C$2:$C$104,MATCH($K8,Service_Providers!$A$2:$A$104,0)))&IF(AND(INDEX(Service_Providers!$C$2:$C$104,MATCH($K8,Service_Providers!$A$2:$A$104,0))<>"",INDEX(Service_Providers!$D$2:$D$104,MATCH($K8,Service_Providers!$A$2:$A$104,0))<>""),CHAR(10),"")&IF(INDEX(Service_Providers!$D$2:$D$104,MATCH($K8,Service_Providers!$A$2:$A$104,0))="","",INDEX(Service_Providers!$D$2:$D$104,MATCH($K8,Service_Providers!$A$2:$A$104,0))),"Provider not found")) -> Contact: Cynthia Phone: 714-335-9964 Cell: 714-395-8108 anytimebeverageservice@gmail.com | M8: FASTCILITY CORP | N8: =IF($M8="","",IFERROR(IF(INDEX(Service_Providers!$C$2:$C$104,MATCH($M8,Service_Providers!$A$2:$A$104,0))="","",INDEX(Service_Providers!$C$2:$C$104,MATCH($M8,Service_Providers!$A$2:$A$104,0)))&IF(AND(INDEX(Service_Providers!$C$2:$C$104,MATCH($M8,Service_Providers!$A$2:$A$104,0))<>"",INDEX(Service_Providers!$D$2:$D$104,MATCH($M8,Service_Providers!$A$2:$A$104,0))<>""),CHAR(10),"")&IF(INDEX(Service_Providers!$D$2:$D$104,MATCH($M8,Service_Providers!$A$2:$A$104,0))="","",INDEX(Service_Providers!$D$2:$D$104,MATCH($M8,Service_Providers!$A$2:$A$104,0))),"Provider not found")) -> Office: (833) 203-2285 Service@FASTCILITYCORP.COM https://app.servicefusion.com/fastcility Username: Jesus@katzcoffee.com F!xmy5!t03 | O8: California Area | P8: 2026-07-15
A9: Kol Fac #070CF - Tustin, CA | B9: tkskaff@kolfac.com | C9: Kathy/Destiny | D9: 714.730.2253 | E9: 14091 Newport Avenue | F9: Tustin | G9: CA | H9: 92780 | I9: ITCB Combo Brewer; Cameo c'2s | J9: Loaned; Owned - Purchased from Katz | K9: All Star Coffee Service | L9: =IF($K9="","",IFERROR(IF(INDEX(Service_Providers!$C$2:$C$104,MATCH($K9,Service_Providers!$A$2:$A$104,0))="","",INDEX(Service_Providers!$C$2:$C$104,MATCH($K9,Service_Providers!$A$2:$A$104,0)))&IF(AND(INDEX(Service_Providers!$C$2:$C$104,MATCH($K9,Service_Providers!$A$2:$A$104,0))<>"",INDEX(Service_Providers!$D$2:$D$104,MATCH($K9,Service_Providers!$A$2:$A$104,0))<>""),CHAR(10),"")&IF(INDEX(Service_Providers!$D$2:$D$104,MATCH($K9,Service_Providers!$A$2:$A$104,0))="","",INDEX(Service_Providers!$D$2:$D$104,MATCH($K9,Service_Providers!$A$2:$A$104,0))),"Provider not found")) -> 626-315-8498 allstarcoffeeservice@gmail.com | M9: Anytime Beverage Service | N9: =IF($M9="","",IFERROR(IF(INDEX(Service_Providers!$C$2:$C$104,MATCH($M9,Service_Providers!$A$2:$A$104,0))="","",INDEX(Service_Providers!$C$2:$C$104,MATCH($M9,Service_Providers!$A$2:$A$104,0)))&IF(AND(INDEX(Service_Providers!$C$2:$C$104,MATCH($M9,Service_Providers!$A$2:$A$104,0))<>"",INDEX(Service_Providers!$D$2:$D$104,MATCH($M9,Service_Providers!$A$2:$A$104,0))<>""),CHAR(10),"")&IF(INDEX(Service_Providers!$D$2:$D$104,MATCH($M9,Service_Providers!$A$2:$A$104,0))="","",INDEX(Service_Providers!$D$2:$D$104,MATCH($M9,Service_Providers!$A$2:$A$104,0))),"Provider not found")) -> Contact: Cynthia Phone: 714-335-9964 Cell: 714-395-8108 anytimebeverageservice@gmail.com | O9: California Area | P9: 2026-07-15
A10: Kol Fac #071CF - Huntington Beach, CA | B10: skaffkathy@yahoo.com | C10: Kathy Skaff | D10: 949.235.6782 | E10: 6502 Bolsa Avenue, Unit 102 | F10: Huntington Beach | G10: CA | H10: 92647 | I10: Bunn ITCB Combo Brewer (NS) | J10: Loaned | K10: All Star Coffee Service | L10: =IF($K10="","",IFERROR(IF(INDEX(Service_Providers!$C$2:$C$104,MATCH($K10,Service_Providers!$A$2:$A$104,0))="","",INDEX(Service_Providers!$C$2:$C$104,MATCH($K10,Service_Providers!$A$2:$A$104,0)))&IF(AND(INDEX(Service_Providers!$C$2:$C$104,MATCH($K10,Service_Providers!$A$2:$A$104,0))<>"",INDEX(Service_Providers!$D$2:$D$104,MATCH($K10,Service_Providers!$A$2:$A$104,0))<>""),CHAR(10),"")&IF(INDEX(Service_Providers!$D$2:$D$104,MATCH($K10,Service_Providers!$A$2:$A$104,0))="","",INDEX(Service_Providers!$D$2:$D$104,MATCH($K10,Service_Providers!$A$2:$A$104,0))),"Provider not found")) -> 626-315-8498 allstarcoffeeservice@gmail.com | M10: Anytime Beverage Service | N10: =IF($M10="","",IFERROR(IF(INDEX(Service_Providers!$C$2:$C$104,MATCH($M10,Service_Providers!$A$2:$A$104,0))="","",INDEX(Service_Providers!$C$2:$C$104,MATCH($M10,Service_Providers!$A$2:$A$104,0)))&IF(AND(INDEX(Service_Providers!$C$2:$C$104,MATCH($M10,Service_Providers!$A$2:$A$104,0))<>"",INDEX(Service_Providers!$D$2:$D$104,MATCH($M10,Service_Providers!$A$2:$A$104,0))<>""),CHAR(10),"")&IF(INDEX(Service_Providers!$D$2:$D$104,MATCH($M10,Service_Providers!$A$2:$A$104,0))="","",INDEX(Service_Providers!$D$2:$D$104,MATCH($M10,Service_Providers!$A$2:$A$104,0))),"Provider not found")) -> Contact: Cynthia Phone: 714-335-9964 Cell: 714-395-8108 anytimebeverageservice@gmail.com | O10: California Area | P10: 2026-07-15
A11: Ocean 48 Newport Beach | B11: brent@ocean48.com | D11: 949.989.0048 | E11: 151 Newport Center Drive | F11: Newport Beach | G11: CA | H11: 92660 | I11: Cameo c'2s; Wilbur Curtis G4TP1S63A3100 Coffee Brewer; Wilbur Curtis ILGD-10 Grinder | J11: Owned - Purchased from 3rd Party | K11: Anytime Beverage Service | L11: =IF($K11="","",IFERROR(IF(INDEX(Service_Providers!$C$2:$C$104,MATCH($K11,Service_Providers!$A$2:$A$104,0))="","",INDEX(Service_Providers!$C$2:$C$104,MATCH($K11,Service_Providers!$A$2:$A$104,0)))&IF(AND(INDEX(Service_Providers!$C$2:$C$104,MATCH($K11,Service_Providers!$A$2:$A$104,0))<>"",INDEX(Service_Providers!$D$2:$D$104,MATCH($K11,Service_Providers!$A$2:$A$104,0))<>""),CHAR(10),"")&IF(INDEX(Service_Providers!$D$2:$D$104,MATCH($K11,Service_Providers!$A$2:$A$104,0))="","",INDEX(Service_Providers!$D$2:$D$104,MATCH($K11,Service_Providers!$A$2:$A$104,0))),"Provider not found")) -> Contact: Cynthia Phone: 714-335-9964 Cell: 714-395-8108 anytimebeverageservice@gmail.com | M11: FASTCILITY CORP | N11: =IF($M11="","",IFERROR(IF(INDEX(Service_Providers!$C$2:$C$104,MATCH($M11,Service_Providers!$A$2:$A$104,0))="","",INDEX(Service_Providers!$C$2:$C$104,MATCH($M11,Service_Providers!$A$2:$A$104,0)))&IF(AND(INDEX(Service_Providers!$C$2:$C$104,MATCH($M11,Service_Providers!$A$2:$A$104,0))<>"",INDEX(Service_Providers!$D$2:$D$104,MATCH($M11,Service_Providers!$A$2:$A$104,0))<>""),CHAR(10),"")&IF(INDEX(Service_Providers!$D$2:$D$104,MATCH($M11,Service_Providers!$A$2:$A$104,0))="","",INDEX(Service_Providers!$D$2:$D$104,MATCH($M11,Service_Providers!$A$2:$A$104,0))),"Provider not found")) -> Office: (833) 203-2285 Service@FASTCILITYCORP.COM https://app.servicefusion.com/fastcility Username: Jesus@katzcoffee.com F!xmy5!t03 | O11: California Area | P11: 2026-07-15
A12: Porsche Marin | B12: marinvendors@indigoautogroup.com | D12: (415) 944-1610 | E12: 900 Redwood Hwy | F12: Mill Valley | G12: CA | H12: 94941 | I12: La Marzocco Linea PB 2AV; La Marzocco Swift Grinder; BWS100/10 | J12: Owned - Purchased from Katz | K12: MB Coffee Services | L12: =IF($K12="","",IFERROR(IF(INDEX(Service_Providers!$C$2:$C$104,MATCH($K12,Service_Providers!$A$2:$A$104,0))="","",INDEX(Service_Providers!$C$2:$C$104,MATCH($K12,Service_Providers!$A$2:$A$104,0)))&IF(AND(INDEX(Service_Providers!$C$2:$C$104,MATCH($K12,Service_Providers!$A$2:$A$104,0))<>"",INDEX(Service_Providers!$D$2:$D$104,MATCH($K12,Service_Providers!$A$2:$A$104,0))<>""),CHAR(10),"")&IF(INDEX(Service_Providers!$D$2:$D$104,MATCH($K12,Service_Providers!$A$2:$A$104,0))="","",INDEX(Service_Providers!$D$2:$D$104,MATCH($K12,Service_Providers!$A$2:$A$104,0))),"Provider not found")) -> 509.302.7071 | M12: FASTCILITY CORP | N12: =IF($M12="","",IFERROR(IF(INDEX(Service_Providers!$C$2:$C$104,MATCH($M12,Service_Providers!$A$2:$A$104,0))="","",INDEX(Service_Providers!$C$2:$C$104,MATCH($M12,Service_Providers!$A$2:$A$104,0)))&IF(AND(INDEX(Service_Providers!$C$2:$C$104,MATCH($M12,Service_Providers!$A$2:$A$104,0))<>"",INDEX(Service_Providers!$D$2:$D$104,MATCH($M12,Service_Providers!$A$2:$A$104,0))<>""),CHAR(10),"")&IF(INDEX(Service_Providers!$D$2:$D$104,MATCH($M12,Service_Providers!$A$2:$A$104,0))="","",INDEX(Service_Providers!$D$2:$D$104,MATCH($M12,Service_Providers!$A$2:$A$104,0))),"Provider not found")) -> Office: (833) 203-2285 Service@FASTCILITYCORP.COM https://app.servicefusion.com/fastcility Username: Jesus@katzcoffee.com F!xmy5!t03 | O12: California Area | P12: 2026-07-15
A13: Rolls Royce - Rancho Mirage | B13: lmccurley@indigoautogroup.com | C13: Lesley McCurley | D13: 760.773.5000 | E13: 71-387 Highway 111 | F13: Rancho Mirage | G13: CA | H13: 92270 | I13: Eversys Cameo c'2m; c'Fridge Beside | J13: Lease | K13: Anytime Beverage Service | L13: =IF($K13="","",IFERROR(IF(INDEX(Service_Providers!$C$2:$C$104,MATCH($K13,Service_Providers!$A$2:$A$104,0))="","",INDEX(Service_Providers!$C$2:$C$104,MATCH($K13,Service_Providers!$A$2:$A$104,0)))&IF(AND(INDEX(Service_Providers!$C$2:$C$104,MATCH($K13,Service_Providers!$A$2:$A$104,0))<>"",INDEX(Service_Providers!$D$2:$D$104,MATCH($K13,Service_Providers!$A$2:$A$104,0))<>""),CHAR(10),"")&IF(INDEX(Service_Providers!$D$2:$D$104,MATCH($K13,Service_Providers!$A$2:$A$104,0))="","",INDEX(Service_Providers!$D$2:$D$104,MATCH($K13,Service_Providers!$A$2:$A$104,0))),"Provider not found")) -> Contact: Cynthia Phone: 714-335-9964 Cell: 714-395-8108 anytimebeverageservice@gmail.com | M13: FASTCILITY CORP | N13: =IF($M13="","",IFERROR(IF(INDEX(Service_Providers!$C$2:$C$104,MATCH($M13,Service_Providers!$A$2:$A$104,0))="","",INDEX(Service_Providers!$C$2:$C$104,MATCH($M13,Service_Providers!$A$2:$A$104,0)))&IF(AND(INDEX(Service_Providers!$C$2:$C$104,MATCH($M13,Service_Providers!$A$2:$A$104,0))<>"",INDEX(Service_Providers!$D$2:$D$104,MATCH($M13,Service_Providers!$A$2:$A$104,0))<>""),CHAR(10),"")&IF(INDEX(Service_Providers!$D$2:$D$104,MATCH($M13,Service_Providers!$A$2:$A$104,0))="","",INDEX(Service_Providers!$D$2:$D$104,MATCH($M13,Service_Providers!$A$2:$A$104,0))),"Provider not found")) -> Office: (833) 203-2285 Service@FASTCILITYCORP.COM https://app.servicefusion.com/fastcility Username: Jesus@katzcoffee.com F!xmy5!t03 | O13: California Area | P13: 2026-07-15
A14: Steak 48 Beverly Hills | B14: leila@steak48.com | D14: 310.388.0048 | E14: 9680 Wilshire Blvd. | F14: Beverly Hills | G14: CA | H14: 90212 | I14: Cameo c'2s; Wilbur Curtis G4TPX2S63A3100 Coffee Brewer; Wilbur Curtis ILGD-10 Grinder | J14: Owned - Purchased from 3rd Party | K14: Anytime Beverage Service | L14: =IF($K14="","",IFERROR(IF(INDEX(Service_Providers!$C$2:$C$104,MATCH($K14,Service_Providers!$A$2:$A$104,0))="","",INDEX(Service_Providers!$C$2:$C$104,MATCH($K14,Service_Providers!$A$2:$A$104,0)))&IF(AND(INDEX(Service_Providers!$C$2:$C$104,MATCH($K14,Service_Providers!$A$2:$A$104,0))<>"",INDEX(Service_Providers!$D$2:$D$104,MATCH($K14,Service_Providers!$A$2:$A$104,0))<>""),CHAR(10),"")&IF(INDEX(Service_Providers!$D$2:$D$104,MATCH($K14,Service_Providers!$A$2:$A$104,0))="","",INDEX(Service_Providers!$D$2:$D$104,MATCH($K14,Service_Providers!$A$2:$A$104,0))),"Provider not found")) -> Contact: Cynthia Phone: 714-335-9964 Cell: 714-395-8108 anytimebeverageservice@gmail.com | M14: FASTCILITY CORP | N14: =IF($M14="","",IFERROR(IF(INDEX(Service_Providers!$C$2:$C$104,MATCH($M14,Service_Providers!$A$2:$A$104,0))="","",INDEX(Service_Providers!$C$2:$C$104,MATCH($M14,Service_Providers!$A$2:$A$104,0)))&IF(AND(INDEX(Service_Providers!$C$2:$C$104,MATCH($M14,Service_Providers!$A$2:$A$104,0))<>"",INDEX(Service_Providers!$D$2:$D$104,MATCH($M14,Service_Providers!$A$2:$A$104,0))<>""),CHAR(10),"")&IF(INDEX(Service_Providers!$D$2:$D$104,MATCH($M14,Service_Providers!$A$2:$A$104,0))="","",INDEX(Service_Providers!$D$2:$D$104,MATCH($M14,Service_Providers!$A$2:$A$104,0))),"Provider not found")) -> Office: (833) 203-2285 Service@FASTCILITYCORP.COM https://app.servicefusion.com/fastcility Username: Jesus@katzcoffee.com F!xmy5!t03 | O14: California Area | P14: 2026-07-15
