Workbook
Name ReadyModelList: 'Ready Models'!$A$8:$A$107

Sheet Barn - Back Rack
A1: READY EQUIPMENT LOG — BARN · BACK RACK (everything on these racks is READY TO USE)
A2: LOCATION: BARN. HOW TO USE: Each rack COLUMN below is one pallet (B–Q = 16 pallets). Two pallets side by side = 1 SECTION (8 sections total). Each section is 4 levels high and each slot holds ~12 pieces, so every level gives you 12 numbered lines per pallet. Type the Model in the Model column and the unit Serial beside it. To flag a customer-owned unit, put the customer in parentheses after the model — e.g. Bunn ITCB (Coco’s). The unit still counts toward the model total, and the customer is picked up automatically on the Ready Models tab. ORANGE = Catering pallets (B–E). PURPLE = Dispenser bay, Section S3 (pallets F & G) on all four levels — dispensers are ACCESSORIES logged by QTY, tracked as their own KPI.
A3: LIVE COUNTS — updates as you add or remove equipment
A4: EQUIPMENT READY (excl. dispensers) | C4: EQUIPMENT CAPACITY | E4: OPEN SLOTS | G4: RACK FILL % | I4: CATERING AREA UNITS (B–E) | K4: DISPENSER UNITS (accessories, by qty) | M4: DISPENSER LINES USED (of 96) | O4: DISTINCT MODELS READY (all racks)
A5: =SUM(B25:AG25,B42:AG42,B59:AG59,B76:AG76)-SUM(J25,L25,J42,L42,J59,L59,J76,L76)-SUM(K25,M25,K42,M42,K59,M59,K76,M76) -> 143 | C5: 672 | E5: =MAX(0,C5-A5) -> 529 | G5: =IF(C5=0,0,A5/C5) -> 0.21279762 | I5: =SUM(B25:I25,B42:I42,B59:I59,B76:I76) -> 2 | K5: =SUM(K25,M25,K42,M42,K59,M59,K76,M76) -> 146 | M5: =SUM(J25,L25,J42,L42,J59,L59,J76,L76) -> 11 | O5: =SUMPRODUCT(('Ready Models'!$A$8:$A$157<>"")*('Ready Models'!$K$8:$K$157>0)) -> 86
A7: LEGEND: ORANGE header/tint = CATERING pallets (B–E) PURPLE header/tint = DISPENSER bay (Section S3, pallets F & G, all 4 levels — accessories, logged by Qty, separate KPI) BLUE header = general equipment A filled Model cell turns GREEN = that unit is Ready to Use A PINK serial cell = serial missing, or digits lost before the fix (hover for the note) Slot ID = Pallet + Level, e.g. "H-L3".
A10: LEVEL 4 — TOP (16 pallets · 8 sections · 12 lines per slot)
A11: SECTION → | B11: S1 · PALLET B · L4 (CATERING) | D11: S1 · PALLET C · L4 (CATERING) | F11: S2 · PALLET D · L4 (CATERING) | H11: S2 · PALLET E · L4 (CATERING) | J11: S3 · PALLET F · L4 (DISPENSERS) | L11: S3 · PALLET G · L4 (DISPENSERS) | N11: S4 · PALLET H · L4 | P11: S4 · PALLET I · L4 | R11: S5 · PALLET J · L4 | T11: S5 · PALLET K · L4 | V11: S6 · PALLET L · L4 | X11: S6 · PALLET M · L4 | Z11: S7 · PALLET N · L4 | AB11: S7 · PALLET O · L4 | AD11: S8 · PALLET P · L4 | AF11: S8 · PALLET Q · L4
A12: LINE # | B12: Equipment Model | C12: Serial # | D12: Equipment Model | E12: Serial # | F12: Equipment Model | G12: Serial # | H12: Equipment Model | I12: Serial # | J12: Dispenser / Accessory | K12: Qty | L12: Dispenser / Accessory | M12: Qty | N12: Equipment Model | O12: Serial # | P12: Equipment Model | Q12: Serial # | R12: Equipment Model | S12: Serial # | T12: Equipment Model | U12: Serial # | V12: Equipment Model | W12: Serial # | X12: Equipment Model | Y12: Serial # | Z12: Equipment Model | AA12: Serial # | AB12: Equipment Model | AC12: Serial # | AD12: Equipment Model | AE12: Serial # | AF12: Equipment Model | AG12: Serial # | AI12: LEVEL TOTAL (equipment)
A13: 1 | L13: Bunn TDO5 | M13: 3 | P13: Eversys Cameo c'2m | Q13: 0183330226105C0012 | R13: Bunn G9-2T | S13: G951020201 | Z13: Bunn CWTF-APS Twin | AA13: N/A | AD13: Fetco 51H | AE13: 2996502A | AF13: Fetco MBS-1221
A14: 2 | L14: Bunn TDO4 | M14: 6 | P14: Eversys c'Fridge Beside | Q14: 0107460025057C0021 | R14: Bunn G9-2T | S14: G900064646 | Z14: Bunn CWTF-APS Twin | AA14: N/A | AD14: Fetco 51H | AE14: 3158401 | AF14: Fetco MBS-1221
A15: 3 | L15: Bunn TDO3.5LP | M15: 1 | R15: Bunn G9-2T | S15: N/A | Z15: Bunn CWTF-TC Twin | AA15: TWIN063686 | AD15: Fetco 51H | AE15: 6948299 | AF15: Fetco MBS-1221
A16: 4 | R16: Bunn G9-2T | S16: N/A | Z16: Bunn CWTF-TC Twin | AA16: TWIN063695 | AD16: Fetco 51H | AE16: 07955803A | AF16: Fetco MBS-1221
A17: 5 | R17: Bunn G9-2T | S17: G900047807 | AD17: Fetco 51H | AE17: 20250416 | AF17: Fetco MBS-1221
A18: 6 | R18: Bunn G9-2T | S18: G900032562 | AD18: Fetco 51H | AE18: 11365402A | AF18: Fetco MBS-1221
A19: 7 | R19: Bunn G9-2T | S19: G900005989
A20: 8 | R20: Bunn G9-2T | S20: G900046418
A21: 9 | R21: Bunn G9-2T | S21: G900040890
A22: 10 | R22: Bunn G9-2T | S22: N/A
A23: 11
A24: 12
A25: IN SLOT → | B25: =COUNTA(B13:B24) -> 0 | C25: / 12 | D25: =COUNTA(D13:D24) -> 0 | E25: / 12 | F25: =COUNTA(F13:F24) -> 0 | G25: / 12 | H25: =COUNTA(H13:H24) -> 0 | I25: / 12 | J25: =COUNTA(J13:J24) -> 0 | K25: =SUM(K13:K24) -> 0 | L25: =COUNTA(L13:L24) -> 3 | M25: =SUM(M13:M24) -> 10 | N25: =COUNTA(N13:N24) -> 0 | O25: / 12 | P25: =COUNTA(P13:P24) -> 2 | Q25: / 12 | R25: =COUNTA(R13:R24) -> 10 | S25: / 12 | T25: =COUNTA(T13:T24) -> 0 | U25: / 12 | V25: =COUNTA(V13:V24) -> 0 | W25: / 12 | X25: =COUNTA(X13:X24) -> 0 | Y25: / 12 | Z25: =COUNTA(Z13:Z24) -> 4 | AA25: / 12 | AB25: =COUNTA(AB13:AB24) -> 0 | AC25: / 12 | AD25: =COUNTA(AD13:AD24) -> 6 | AE25: / 12 | AF25: =COUNTA(AF13:AF24) -> 6 | AG25: / 12 | AI25: =SUM(B25:AG25)-SUM(J25,L25,K25,M25) -> 28
A27: LEVEL 3 (16 pallets · 8 sections · 12 lines per slot)
A28: SECTION → | B28: S1 · PALLET B · L3 (CATERING) | D28: S1 · PALLET C · L3 (CATERING) | F28: S2 · PALLET D · L3 (CATERING) | H28: S2 · PALLET E · L3 (CATERING) | J28: S3 · PALLET F · L3 (DISPENSERS) | L28: S3 · PALLET G · L3 (DISPENSERS) | N28: S4 · PALLET H · L3 | P28: S4 · PALLET I · L3 | R28: S5 · PALLET J · L3 | T28: S5 · PALLET K · L3 | V28: S6 · PALLET L · L3 | X28: S6 · PALLET M · L3 | Z28: S7 · PALLET N · L3 | AB28: S7 · PALLET O · L3 | AD28: S8 · PALLET P · L3 | AF28: S8 · PALLET Q · L3
A29: LINE # | B29: Equipment Model | C29: Serial # | D29: Equipment Model | E29: Serial # | F29: Equipment Model | G29: Serial # | H29: Equipment Model | I29: Serial # | J29: Dispenser / Accessory | K29: Qty | L29: Dispenser / Accessory | M29: Qty | N29: Equipment Model | O29: Serial # | P29: Equipment Model | Q29: Serial # | R29: Equipment Model | S29: Serial # | T29: Equipment Model | U29: Serial # | V29: Equipment Model | W29: Serial # | X29: Equipment Model | Y29: Serial # | Z29: Equipment Model | AA29: Serial # | AB29: Equipment Model | AC29: Serial # | AD29: Equipment Model | AE29: Serial # | AF29: Equipment Model | AG29: Serial # | AI29: LEVEL TOTAL (equipment)
A30: 1 | J30: Fetco L4S-10 | K30: 1 | L30: Fetco L4D-10 | M30: 10 | N30: Eversys e'4s (Vida) | P30: Eversys Cameo c'2s | Q30: 0183130226090C0003 | R30: Bunn G9-2T | S30: N/A | T30: Bunn Axiom-APS | U30: AXAP048950 | Z30: Bunn Axiom-15-2U1L | AA30: AX00067024 | AD30: Fetco 2051e | AE30: 470102071577 | AF30: Fetco 1232 Plus | AG30: 12321B23006241064
A31: 2 | J31: Fetco Twin Station | K31: 3 | R31: Bunn G9-2T | S31: N/A | T31: Bunn Axiom-APS | U31: AXAP028650 | Z31: Bunn Axiom-15-2U1L | AA31: AX00067031 | AD31: Fetco 2051e | AE31: 470105071605 | AF31: Fetco 1232 Plus | AG31: 12321B22312252880
A32: 3 | R32: Bunn G9-2T | S32: N/A | T32: Bunn Axiom-APS | U32: AXAP028068 | Z32: Bunn Axiom-15-2U1L | AA32: AX00078697 | AD32: Fetco 2051e | AE32: 470140071828 | AF32: Fetco 52H | AG32: 30105258944
A33: 4 | R33: Bunn G9-2T | S33: N/A | T33: Bunn Axiom-APS | U33: AXAP051199 | Z33: Bunn CWTF-15-2U1L | AA33: CWTF472186 | AD33: Fetco 1151 V+ | AE33: 11515145245217675
A34: 5 | R34: Bunn G9-2T | S34: G9201362 | T34: Bunn Axiom-APS | U34: AXAP050695 | Z34: Bunn CWTF-15-2U1L | AA34: CWTF563341 | AD34: Fetco 2051e | AE34: 470112123156
A35: 6 | R35: Bunn G9-2T | S35: G900045131 | T35: Bunn Axiom-APS | U35: AXAP049761 | Z35: Bunn CWTF-15-2U1L | AA35: CWTF544341 | AD35: Fetco 51H | AE35: 05482600
A36: 7 | R36: Bunn G9-2T | S36: N/A | T36: Bunn Axiom-APS | U36: AXAP058908 | Z36: Bunn Axiom-15-2U1L | AA36: AX00067025
A37: 8 | R37: Bunn G9-2T | S37: G900049473 | T37: Bunn Axiom-APS | U37: AXAP054421 | Z37: Bunn CWTF-TC Twin | AA37: N/A
A38: 9 | R38: Bunn G9-2T | S38: N/A | T38: Bunn Axiom-APS | U38: AXAP025208
A39: 10 | T39: Bunn Axiom-APS | U39: AXAP049092
A40: 11
A41: 12
A42: IN SLOT → | B42: =COUNTA(B30:B41) -> 0 | C42: / 12 | D42: =COUNTA(D30:D41) -> 0 | E42: / 12 | F42: =COUNTA(F30:F41) -> 0 | G42: / 12 | H42: =COUNTA(H30:H41) -> 0 | I42: / 12 | J42: =COUNTA(J30:J41) -> 2 | K42: =SUM(K30:K41) -> 4 | L42: =COUNTA(L30:L41) -> 1 | M42: =SUM(M30:M41) -> 10 | N42: =COUNTA(N30:N41) -> 1 | O42: / 12 | P42: =COUNTA(P30:P41) -> 1 | Q42: / 12 | R42: =COUNTA(R30:R41) -> 9 | S42: / 12 | T42: =COUNTA(T30:T41) -> 10 | U42: / 12 | V42: =COUNTA(V30:V41) -> 0 | W42: / 12 | X42: =COUNTA(X30:X41) -> 0 | Y42: / 12 | Z42: =COUNTA(Z30:Z41) -> 8 | AA42: / 12 | AB42: =COUNTA(AB30:AB41) -> 0 | AC42: / 12 | AD42: =COUNTA(AD30:AD41) -> 6 | AE42: / 12 | AF42: =COUNTA(AF30:AF41) -> 3 | AG42: / 12 | AI42: =SUM(B42:AG42)-SUM(J42,L42,K42,M42) -> 38
A44: LEVEL 2 (16 pallets · 8 sections · 12 lines per slot)
A45: SECTION → | B45: S1 · PALLET B · L2 (CATERING) | D45: S1 · PALLET C · L2 (CATERING) | F45: S2 · PALLET D · L2 (CATERING) | H45: S2 · PALLET E · L2 (CATERING) | J45: S3 · PALLET F · L2 (DISPENSERS) | L45: S3 · PALLET G · L2 (DISPENSERS) | N45: S4 · PALLET H · L2 | P45: S4 · PALLET I · L2 | R45: S5 · PALLET J · L2 | T45: S5 · PALLET K · L2 | V45: S6 · PALLET L · L2 | X45: S6 · PALLET M · L2 | Z45: S7 · PALLET N · L2 | AB45: S7 · PALLET O · L2 | AD45: S8 · PALLET P · L2 | AF45: S8 · PALLET Q · L2
...

Sheet Barn - Front Rack
A1: READY EQUIPMENT LOG — BARN · FRONT RACK (everything on these racks is READY TO USE)
A2: LOCATION: BARN. HOW TO USE: This rack sits IN FRONT of the back rack (double-racked section) and mirrors back-rack pallets J–Q — 8 pallets / 4 sections, 4 levels high, 12 lines per slot. Type the Model in the Model column and the unit Serial beside it. To flag a customer-owned unit, put the customer in parentheses after the model — e.g. Bunn ITCB (Coco’s). The unit still counts toward the model total, and the customer is picked up automatically on the Ready Models tab. Serial columns are formatted as Text so long serial numbers keep every digit.
A3: LIVE COUNTS — updates as you add or remove equipment
A4: EQUIPMENT READY on front rack | C4: EQUIPMENT CAPACITY | E4: OPEN SLOTS | G4: RACK FILL % | I4: SECTIONS ON THIS RACK | K4: PALLETS (J–Q) | M4: LEVELS PER SECTION | O4: LINES PER SLOT
A5: =SUM(B25:Q25,B42:Q42,B59:Q59,B76:Q76) -> 82 | C5: 384 | E5: =MAX(0,C5-A5) -> 302 | G5: =IF(C5=0,0,A5/C5) -> 0.21354167 | I5: 4 | K5: 8 | M5: 4 | O5: 12
A7: LEGEND: BLUE header = general equipment A filled Model cell turns GREEN = that unit is Ready to Use A PINK serial cell = serial still missing Slot ID = Pallet + Level, e.g. "M-L3". Front-rack pallets sit directly in front of back-rack pallets of the same letter. Customer-owned units are logged on the Ready Models tab.
A10: LEVEL 4 — TOP (8 pallets · 4 sections · 12 lines per slot)
A11: SECTION → | B11: S1 · PALLET J · L4 | D11: S1 · PALLET K · L4 | F11: S2 · PALLET L · L4 | H11: S2 · PALLET M · L4 | J11: S3 · PALLET N · L4 | L11: S3 · PALLET O · L4 | N11: S4 · PALLET P · L4 | P11: S4 · PALLET Q · L4
A12: LINE # | B12: Equipment Model | C12: Serial # | D12: Equipment Model | E12: Serial # | F12: Equipment Model | G12: Serial # | H12: Equipment Model | I12: Serial # | J12: Equipment Model | K12: Serial # | L12: Equipment Model | M12: Serial # | N12: Equipment Model | O12: Serial # | P12: Equipment Model | Q12: Serial # | S12: LEVEL TOTAL
A13: 1 | B13: Bunn G9-2 | C13: G900055242
A14: 2 | B14: Bunn G9-2 | C14: N/A
A15: 3 | B15: Bunn G9-2 | C15: G900107448
A16: 4 | B16: Bunn G9-2 | C16: G900029673
A17: 5 | B17: Bunn G9-2 | C17: G900006469
A18: 6 | B18: Bunn G9-2 | C18: N/A
A19: 7 | B19: Bunn G9-2 | C19: N/A
A20: 8 | B20: Bunn G9-2 | C20: N/A
A21: 9 | B21: Bunn G9-2 | C21: G900046332
A22: 10 | B22: Bunn G9-2 | C22: G900057284
A23: 11
A24: 12
A25: IN SLOT → | B25: =COUNTA(B13:B24) -> 10 | C25: / 12 | D25: =COUNTA(D13:D24) -> 0 | E25: / 12 | F25: =COUNTA(F13:F24) -> 0 | G25: / 12 | H25: =COUNTA(H13:H24) -> 0 | I25: / 12 | J25: =COUNTA(J13:J24) -> 0 | K25: / 12 | L25: =COUNTA(L13:L24) -> 0 | M25: / 12 | N25: =COUNTA(N13:N24) -> 0 | O25: / 12 | P25: =COUNTA(P13:P24) -> 0 | Q25: / 12 | S25: =SUM(B25:Q25) -> 10
A27: LEVEL 3 (8 pallets · 4 sections · 12 lines per slot)
A28: SECTION → | B28: S1 · PALLET J · L3 | D28: S1 · PALLET K · L3 | F28: S2 · PALLET L · L3 | H28: S2 · PALLET M · L3 | J28: S3 · PALLET N · L3 | L28: S3 · PALLET O · L3 | N28: S4 · PALLET P · L3 | P28: S4 · PALLET Q · L3
A29: LINE # | B29: Equipment Model | C29: Serial # | D29: Equipment Model | E29: Serial # | F29: Equipment Model | G29: Serial # | H29: Equipment Model | I29: Serial # | J29: Equipment Model | K29: Serial # | L29: Equipment Model | M29: Serial # | N29: Equipment Model | O29: Serial # | P29: Equipment Model | Q29: Serial # | S29: LEVEL TOTAL
A30: 1 | B30: Bunn G9-2 | C30: G900075324 | J30: DeJongDuke Virtu | K30: 2024021984901 | N30: Fetco 51H | O30: N/A
A31: 2 | B31: Bunn G9-2 | C31: N/A | J31: Bravilor Esprecious 22 | N31: Fetco MBS-1221 | O31: 12211X11721231918
A32: 3 | B32: Bunn G9-2 | C32: G90000474 | J32: WAT Water CT Sparkling 3202-200
A33: 4 | B33: Bunn G9-2 | C33: N/A
A34: 5 | B34: Bunn G9-2 | C34: N/A
A35: 6 | B35: Bunn G9-2 | C35: N/A
A36: 7 | B36: Bunn G9-2 | C36: G900001858
A37: 8 | B37: Bunn G9-2 | C37: G900003290
A38: 9 | B38: Bunn G9-1 | C38: G900011600
A39: 10
A40: 11
A41: 12
A42: IN SLOT → | B42: =COUNTA(B30:B41) -> 9 | C42: / 12 | D42: =COUNTA(D30:D41) -> 0 | E42: / 12 | F42: =COUNTA(F30:F41) -> 0 | G42: / 12 | H42: =COUNTA(H30:H41) -> 0 | I42: / 12 | J42: =COUNTA(J30:J41) -> 3 | K42: / 12 | L42: =COUNTA(L30:L41) -> 0 | M42: / 12 | N42: =COUNTA(N30:N41) -> 2 | O42: / 12 | P42: =COUNTA(P30:P41) -> 0 | Q42: / 12 | S42: =SUM(B42:Q42) -> 14
A44: LEVEL 2 (8 pallets · 4 sections · 12 lines per slot)
A45: SECTION → | B45: S1 · PALLET J · L2 | D45: S1 · PALLET K · L2 | F45: S2 · PALLET L · L2 | H45: S2 · PALLET M · L2 | J45: S3 · PALLET N · L2 | L45: S3 · PALLET O · L2 | N45: S4 · PALLET P · L2 | P45: S4 · PALLET Q · L2
...

Sheet Equipment by Location
A1: EQUIPMENT BY LOCATION — outside the Barn racks (everything listed here is READY TO USE)
A2: HOW TO USE: Five separate lists, one per location. Enter the Equipment Name, its Serial Number, and the Qty. Use one line per unit where you track serials; use Qty for anything you hold in bulk (leave Qty blank and it counts as 1). Everything typed here rolls into the Ready Models totals automatically, under its own location column — no need to touch that tab. OUT OF STATE covers anything staged outside Texas; use the Serial Number line as normal and note the state or site in the name if it helps you find it. Customer-owned units work the same way here: put the customer in parentheses after the name, e.g. Bunn ITCB (Coco’s).
A3: LIVE COUNTS — units held at each location
A4: FRONT LOBBY UNITS | E4: SERVICE ROOM UNITS | I4: PRODUCTION UNITS | M4: TRAINING ROOM UNITS | Q4: OUT OF STATE UNITS
A5: =SUM(C11:C50)+SUMPRODUCT((A11:A50<>"")*(C11:C50="")) -> 9 | E5: =SUM(G11:G50)+SUMPRODUCT((E11:E50<>"")*(G11:G50="")) -> 8 | I5: =SUM(K11:K50)+SUMPRODUCT((I11:I50<>"")*(K11:K50="")) -> 12 | M5: =SUM(O11:O50)+SUMPRODUCT((M11:M50<>"")*(O11:O50="")) -> 14 | Q5: =SUM(S11:S50)+SUMPRODUCT((Q11:Q50<>"")*(S11:S50="")) -> 1
A7: A blank Qty counts as 1 unit. Lines are capped at 40 per location — say the word if a list needs more room. Equipment Name has a dropdown of everything already known to the workbook; typing a brand-new name is fine and it will be added to Ready Models on its own.
A9: FRONT LOBBY | E9: SERVICE ROOM | I9: PRODUCTION | M9: TRAINING ROOM | Q9: OUT OF STATE
A10: Equipment Name | B10: Serial Number | C10: Qty | E10: Equipment Name | F10: Serial Number | G10: Qty | I10: Equipment Name | J10: Serial Number | K10: Qty | M10: Equipment Name | N10: Serial Number | O10: Qty | Q10: Equipment Name | R10: Serial Number | S10: Qty
A11: Bunn G3 | B11: G300003239 | C11: 1 | E11: Bunn H5X 220V | F11: HX00125853 | G11: 1 | I11: Fetco 62H | J11: 05804303A | K11: 1 | M11: Fetco GR2.3 | N11: 740113153011 | O11: 1 | Q11: Eversys Cameo c'2s | S11: 1
A12: Bunn G2 | B12: G200002189 | C12: 1 | E12: Bunn ITCB | F12: ITCB143274 | G12: 1 | I12: Bunn ITCB | J12: ITCB104656 | K12: 1 | M12: Fetco 2051e | N12: 470148071861 | O12: 1
A13: Fetco 1251 Plus | B13: 12511B2300529007 | C13: 1 | E13: Rancilio Classe 5 Compact 120v | F13: 10410928 | G13: 1 | I13: Ditting KR1403 | J13: 25838 | K13: 1 | M13: Bunn Sure Immersion 220 | N13: B2C0004800 | O13: 1
A14: La Marzocco Wally | B14: WM001197 | C14: 1 | E14: Bunn CWTF-APS | F14: CWTF547351 | G14: 1 | I14: Ditting KR1403 | J14: 14466 | K14: 1 | M14: Bunn ITCB NS | N14: ITCB1736001 | O14: 1
A15: La Marzocco Strada XT | B15: SR001304 | C15: 1 | E15: Eversys e'4s ST X-Wide | F15: 0116600022255E0004 | G15: 1 | I15: Ditting KR1403 | J15: 1063 | K15: 1 | M15: Bunn G9-2T | N15: N/A | O15: 1
A16: Mazzer Robur S E | B16: 1928657 | C16: 1 | E16: La Marzocco Strada 2EP | F16: ST004299 | G16: 1 | I16: Ditting KR1403 | J16: 1168 | K16: 1 | M16: Mazzer Kony Doser | N16: 0924004 | O16: 1
A17: Mazzer Robur S E | B17: 2109963 | C17: 1 | E17: Eversys Shotmaster CT | F17: 0115390026159E0001 | G17: 1 | I17: Ditting KR1403 | J17: 1067 | K17: 1 | M17: Faema E61 Legend S/2 | N17: 1171694 | O17: 1
A18: La Marzocco KB90 ABR | B18: KB000276 | C18: 1 | E18: Eversys Shotmaster CT | F18: 0115390026159E0002 | G18: 1 | I18: Ditting KR1403 | J18: 24724 | K18: 1 | M18: La Marzocco Swift Grinder | N18: 4533-1 | O18: 1
A19: Mazzer Super Jolly V Up Timer | B19: 2403595 | C19: 1 | I19: Ditting KR1403 | J19: 1172 | K19: 1 | M19: Eversys Cameo c'2s | N19: 1912045 | O19: 1
I20: Bunn G3 | J20: G300057356 | K20: 1 | M20: Frosty Factory 217A | N20: 33713 | O20: 1
I21: Eversys e'4m | J21: 0110710023346E0004 | K21: 1 | M21: Eversys e'4s | N21: 011700026065E0011 | O21: 1
I22: Eversys Shotmaster S/Pro | J22: 0116650021340E0001 | K22: 1 | M22: Mazzer Super Jolly V Up Timer | N22: 2403738 | O22: 1
M23: Fetco MBS-1251 | N23: 125111A1172261546 | O23: 1
M24: Bunn Nitron | N24: N2GM012751 / CLDD021918 | O24: 1
A51: LINES USED → | B51: =COUNTA(A11:A50)&" / 40" -> 9 / 40 | C51: =SUM(C11:C50)+SUMPRODUCT((A11:A50<>"")*(C11:C50="")) -> 9 | E51: LINES USED → | F51: =COUNTA(E11:E50)&" / 40" -> 8 / 40 | G51: =SUM(G11:G50)+SUMPRODUCT((E11:E50<>"")*(G11:G50="")) -> 8 | I51: LINES USED → | J51: =COUNTA(I11:I50)&" / 40" -> 12 / 40 | K51: =SUM(K11:K50)+SUMPRODUCT((I11:I50<>"")*(K11:K50="")) -> 12 | M51: LINES USED → | N51: =COUNTA(M11:M50)&" / 40" -> 14 / 40 | O51: =SUM(O11:O50)+SUMPRODUCT((M11:M50<>"")*(O11:O50="")) -> 14 | Q51: LINES USED → | R51: =COUNTA(Q11:Q50)&" / 40" -> 1 / 40 | S51: =SUM(S11:S50)+SUMPRODUCT((Q11:Q50<>"")*(S11:S50="")) -> 1

Sheet SA & Dallas Warehouses
A1: SA & DALLAS WAREHOUSES — equipment and modules held off-site (everything listed here is READY TO USE)
A2: HOW TO USE: Same format as the Equipment by Location tab. Each warehouse has two sections — EQUIPMENT and MODULES — and each takes an Equipment Name, its Serial Number, and a Qty. Use one line per unit where you track serials; use Qty for anything held in bulk (leave Qty blank and it counts as 1). Everything typed here rolls into the Ready Models totals automatically under its own warehouse column. Modules are totalled separately from equipment, the same way dispensers are, so they never inflate the equipment count. Customer-owned units work here too: put the customer in parentheses after the name, e.g. Bunn ITCB (Coco’s).
A3: LIVE COUNTS — units held at each warehouse
A4: SAN ANTONIO EQUIPMENT | E4: SAN ANTONIO MODULES | I4: DALLAS EQUIPMENT | M4: DALLAS MODULES
A5: =SUM(C11:C50)+SUMPRODUCT((A11:A50<>"")*(C11:C50="")) -> 10 | E5: =SUM(G11:G50)+SUMPRODUCT((E11:E50<>"")*(G11:G50="")) -> 0 | I5: =SUM(K11:K50)+SUMPRODUCT((I11:I50<>"")*(K11:K50="")) -> 0 | M5: =SUM(O11:O50)+SUMPRODUCT((M11:M50<>"")*(O11:O50="")) -> 0
A7: A blank Qty counts as 1 unit. Each section holds 40 lines — say the word if one needs more room. Equipment Name has a dropdown of everything already known to the workbook; typing a brand-new name is fine and it will be added to Ready Models on its own.
A9: SAN ANTONIO — EQUIPMENT | E9: SAN ANTONIO — MODULES | I9: DALLAS — EQUIPMENT | M9: DALLAS — MODULES
A10: Equipment Name | B10: Serial Number | C10: Qty | E10: Module Name | F10: Serial Number | G10: Qty | I10: Equipment Name | J10: Serial Number | K10: Qty | M10: Module Name | N10: Serial Number | O10: Qty
A11: Bunn ITCB | B11: ITCB105226 | C11: 1
A12: Fetco 1252 Plus | B12: 1252UB2304923049233759 | C12: 1
A13: Mazzer Robur Automatic S | B13: 2242353 | C13: 1
A14: Mazzer Super Jolly Timer | B14: 2403603 | C14: 1
A15: Bunn G3 | B15: G300037527 | C15: 1
A16: Bunn FPG-2E | B16: LPG0077016 | C16: 1
A17: Bunn G9-2T | B17: G900046511 | C17: 1
A18: Bunn H5X 120V | B18: HX00143258 | C18: 1
A19: Bunn G1 | B19: G100013007 | C19: 1
A20: Eversys Cameo c'2s | B20: 0099820023247C0024 | C20: 1
A51: LINES USED → | B51: =COUNTA(A11:A50)&" / 40" -> 10 / 40 | C51: =SUM(C11:C50)+SUMPRODUCT((A11:A50<>"")*(C11:C50="")) -> 10 | E51: LINES USED → | F51: =COUNTA(E11:E50)&" / 40" -> 0 / 40 | G51: =SUM(G11:G50)+SUMPRODUCT((E11:E50<>"")*(G11:G50="")) -> 0 | I51: LINES USED → | J51: =COUNTA(I11:I50)&" / 40" -> 0 / 40 | K51: =SUM(K11:K50)+SUMPRODUCT((I11:I50<>"")*(K11:K50="")) -> 0 | M51: LINES USED → | N51: =COUNTA(M11:M50)&" / 40" -> 0 / 40 | O51: =SUM(O11:O50)+SUMPRODUCT((M11:M50<>"")*(O11:O50="")) -> 0

Sheet Rack Map
A1: RACK MAP — BARN planogram overview (units in each slot)
A2: Each cell is one SLOT (pallet × level) and shows how many of its 12 lines are filled. GREEN = full, AMBER = partly filled, GREY = empty. Two pallets side by side = one section. Orange headers = Catering (B–E). Purple = Dispenser bay, Section S3 (pallets F & G) on all four levels. This map covers the BARN only — equipment in the Front Lobby, Service Room, Production and Training Room is on the Equipment by Location tab.
A4: BARN — BACK RACK · 8 sections / 16 pallets (B–Q)
A5: LEVEL ↓ / PALLET → | B5: B | C5: C | D5: D | E5: E | F5: F | G5: G | H5: H | I5: I | J5: J | K5: K | L5: L | M5: M | N5: N | O5: O | P5: P | Q5: Q
A6: Level 4 (Top) | B6: ='Barn - Back Rack'!B25 -> 0 | C6: ='Barn - Back Rack'!D25 -> 0 | D6: ='Barn - Back Rack'!F25 -> 0 | E6: ='Barn - Back Rack'!H25 -> 0 | F6: ='Barn - Back Rack'!J25 -> 0 | G6: ='Barn - Back Rack'!L25 -> 3 | H6: ='Barn - Back Rack'!N25 -> 0 | I6: ='Barn - Back Rack'!P25 -> 2 | J6: ='Barn - Back Rack'!R25 -> 10 | K6: ='Barn - Back Rack'!T25 -> 0 | L6: ='Barn - Back Rack'!V25 -> 0 | M6: ='Barn - Back Rack'!X25 -> 0 | N6: ='Barn - Back Rack'!Z25 -> 4 | O6: ='Barn - Back Rack'!AB25 -> 0 | P6: ='Barn - Back Rack'!AD25 -> 6 | Q6: ='Barn - Back Rack'!AF25 -> 6
A7: Level 3 | B7: ='Barn - Back Rack'!B42 -> 0 | C7: ='Barn - Back Rack'!D42 -> 0 | D7: ='Barn - Back Rack'!F42 -> 0 | E7: ='Barn - Back Rack'!H42 -> 0 | F7: ='Barn - Back Rack'!J42 -> 2 | G7: ='Barn - Back Rack'!L42 -> 1 | H7: ='Barn - Back Rack'!N42 -> 1 | I7: ='Barn - Back Rack'!P42 -> 1 | J7: ='Barn - Back Rack'!R42 -> 9 | K7: ='Barn - Back Rack'!T42 -> 10 | L7: ='Barn - Back Rack'!V42 -> 0 | M7: ='Barn - Back Rack'!X42 -> 0 | N7: ='Barn - Back Rack'!Z42 -> 8 | O7: ='Barn - Back Rack'!AB42 -> 0 | P7: ='Barn - Back Rack'!AD42 -> 6 | Q7: ='Barn - Back Rack'!AF42 -> 3
A8: Level 2 | B8: ='Barn - Back Rack'!B59 -> 0 | C8: ='Barn - Back Rack'!D59 -> 0 | D8: ='Barn - Back Rack'!F59 -> 0 | E8: ='Barn - Back Rack'!H59 -> 0 | F8: ='Barn - Back Rack'!J59 -> 1 | G8: ='Barn - Back Rack'!L59 -> 1 | H8: ='Barn - Back Rack'!N59 -> 1 | I8: ='Barn - Back Rack'!P59 -> 1 | J8: ='Barn - Back Rack'!R59 -> 11 | K8: ='Barn - Back Rack'!T59 -> 10 | L8: ='Barn - Back Rack'!V59 -> 7 | M8: ='Barn - Back Rack'!X59 -> 8 | N8: ='Barn - Back Rack'!Z59 -> 0 | O8: ='Barn - Back Rack'!AB59 -> 0 | P8: ='Barn - Back Rack'!AD59 -> 2 | Q8: ='Barn - Back Rack'!AF59 -> 0
A9: Level 1 (Floor) | B9: ='Barn - Back Rack'!B76 -> 0 | C9: ='Barn - Back Rack'!D76 -> 0 | D9: ='Barn - Back Rack'!F76 -> 0 | E9: ='Barn - Back Rack'!H76 -> 2 | F9: ='Barn - Back Rack'!J76 -> 2 | G9: ='Barn - Back Rack'!L76 -> 1 | H9: ='Barn - Back Rack'!N76 -> 1 | I9: ='Barn - Back Rack'!P76 -> 1 | J9: ='Barn - Back Rack'!R76 -> 5 | K9: ='Barn - Back Rack'!T76 -> 9 | L9: ='Barn - Back Rack'!V76 -> 4 | M9: ='Barn - Back Rack'!X76 -> 5 | N9: ='Barn - Back Rack'!Z76 -> 3 | O9: ='Barn - Back Rack'!AB76 -> 3 | P9: ='Barn - Back Rack'!AD76 -> 2 | Q9: ='Barn - Back Rack'!AF76 -> 2
A10: PALLET TOTAL | B10: =SUM(B6:B9) -> 0 | C10: =SUM(C6:C9) -> 0 | D10: =SUM(D6:D9) -> 0 | E10: =SUM(E6:E9) -> 2 | F10: =SUM(F6:F9) -> 5 | G10: =SUM(G6:G9) -> 6 | H10: =SUM(H6:H9) -> 3 | I10: =SUM(I6:I9) -> 5 | ... Q10: =SUM(Q6:Q9) -> 11
A11: Sections: S1 = B+C, S2 = D+E (both CATERING) · S3 = F+G (DISPENSER bay, all 4 levels, accessories logged by qty) · S4 = H+I · S5 = J+K · S6 = L+M · S7 = N+O · S8 = P+Q.
A13: BARN — FRONT RACK · 4 sections / 8 pallets (J–Q), double-racked in front of the back rack
A14: LEVEL ↓ / PALLET → | B14: J | C14: K | D14: L | E14: M | F14: N | G14: O | H14: P | I14: Q
A15: Level 4 (Top) | B15: ='Barn - Front Rack'!B25 -> 10 | C15: ='Barn - Front Rack'!D25 -> 0 | D15: ='Barn - Front Rack'!F25 -> 0 | E15: ='Barn - Front Rack'!H25 -> 0 | F15: ='Barn - Front Rack'!J25 -> 0 | G15: ='Barn - Front Rack'!L25 -> 0 | H15: ='Barn - Front Rack'!N25 -> 0 | I15: ='Barn - Front Rack'!P25 -> 0
A16: Level 3 | B16: ='Barn - Front Rack'!B42 -> 9 | C16: ='Barn - Front Rack'!D42 -> 0 | D16: ='Barn - Front Rack'!F42 -> 0 | E16: ='Barn - Front Rack'!H42 -> 0 | F16: ='Barn - Front Rack'!J42 -> 3 | G16: ='Barn - Front Rack'!L42 -> 0 | H16: ='Barn - Front Rack'!N42 -> 2 | I16: ='Barn - Front Rack'!P42 -> 0
A17: Level 2 | B17: ='Barn - Front Rack'!B59 -> 9 | C17: ='Barn - Front Rack'!D59 -> 6 | D17: ='Barn - Front Rack'!F59 -> 8 | E17: ='Barn - Front Rack'!H59 -> 7 | F17: ='Barn - Front Rack'!J59 -> 2 | G17: ='Barn - Front Rack'!L59 -> 1 | H17: ='Barn - Front Rack'!N59 -> 3 | I17: ='Barn - Front Rack'!P59 -> 0
A18: Level 1 (Floor) | B18: ='Barn - Front Rack'!B76 -> 8 | C18: ='Barn - Front Rack'!D76 -> 0 | D18: ='Barn - Front Rack'!F76 -> 0 | E18: ='Barn - Front Rack'!H76 -> 8 | F18: ='Barn - Front Rack'!J76 -> 2 | G18: ='Barn - Front Rack'!L76 -> 2 | H18: ='Barn - Front Rack'!N76 -> 2 | I18: ='Barn - Front Rack'!P76 -> 0
A19: PALLET TOTAL | B19: =SUM(B15:B18) -> 36 | C19: =SUM(C15:C18) -> 6 | D19: =SUM(D15:D18) -> 8 | E19: =SUM(E15:E18) -> 15 | F19: =SUM(F15:F18) -> 7 | G19: =SUM(G15:G18) -> 3 | H19: =SUM(H15:H18) -> 7 | I19: =SUM(I15:I18) -> 0
A20: Sections: S1 = J+K · S2 = L+M · S3 = N+O · S4 = P+Q. This rack stands directly in front of back-rack pallets J–Q — pull from the front rack first.

Sheet Ready Models
A1: READY MODELS — total equipment ready, by model and location
A2: HOW TO USE: This whole tab is automatic — there is nothing to type here. The model list builds itself, in alphabetical order, from every entry across the Barn racks, the Equipment by Location tab and the SA & Dallas Warehouses tab, so a model you add anywhere shows up here on its own. Quantities are split by location and rolled into one total per model. Dispensers (Section S3 in the Barn) and Modules (SA & Dallas) are logged by QTY and are shown in their own columns, so they are held out of the equipment headline. Put a customer in parentheses after a model name anywhere in the workbook — e.g. Bunn ITCB (Coco’s) — and the unit still counts toward its model while the customer is captured in Notes and in the Customer-Owned Equipment table below.
A3: LIVE TOTALS — every location
A4: TOTAL EQUIPMENT READY (all locations, excl. dispensers & modules) | B4: BARN BACK RACK | C4: BARN FRONT RACK | D4: FRONT LOBBY | E4: SERVICE ROOM | F4: PRODUCTION | G4: TRAINING ROOM | H4: OUT OF STATE | I4: SAN ANTONIO (equip. only) | J4: DALLAS (equip. only) | K4: DISPENSER UNITS (accessories) | L4: MODULES (SA + Dallas) | M4: DISTINCT MODELS | N4: CUSTOMER-OWNED UNITS
A5: =SUM($K$8:$K$157)-SUM($L$8:$L$157)-SUM($M$8:$M$157) -> 279 | B5: =SUM($B$8:$B$157)-SUM($L$8:$L$157) -> 143 | C5: =SUM($C$8:$C$157) -> 82 | D5: =SUM($D$8:$D$157) -> 9 | E5: =SUM($E$8:$E$157) -> 8 | F5: =SUM($F$8:$F$157) -> 12 | G5: =SUM($G$8:$G$157) -> 14 | H5: =SUM($H$8:$H$157) -> 1 | I5: =SUM($I$8:$I$157)-SUMIFS('Equipment Index'!$F$2:$F$1513,'Equipment Index'!$C$2:$C$1513,"MOD",'Equipment Index'!$A$2:$A$1513,"San Antonio") -> 10 | J5: =SUM($J$8:$J$157)-SUMIFS('Equipment Index'!$F$2:$F$1513,'Equipment Index'!$C$2:$C$1513,"MOD",'Equipment Index'!$A$2:$A$1513,"Dallas") -> 0 | K5: =SUM($L$8:$L$157) -> 146 | L5: =SUM($M$8:$M$157) -> 0 | M5: =SUMPRODUCT(($A$8:$A$157<>"")*1) -> 86 | N5: =COUNTIF('Equipment Index'!$H$2:$H$1513,"?*") -> 5
A6: Barn capacity: back rack 672 equipment slots + 96 dispenser lines (Section S3); front rack 384. Front Lobby, Service Room, Production, Training Room and Out of State hold 40 lines each; SA and Dallas hold 40 equipment lines and 40 module lines each.
A7: Model | B7: Barn – Back Rack | C7: Barn – Front Rack | D7: Front Lobby | E7: Service Room | F7: Production | G7: Training Room | H7: Out of State | I7: San Antonio | J7: Dallas | K7: TOTAL READY | L7: of which: Dispenser Units | M7: of which: Modules | N7: Notes (auto)
A8: =IFERROR(INDEX('Equipment Index'!$G$2:$G$1513,MATCH(ROW()-7,'Equipment Index'!$J$2:$J$1513,0)),"") -> Bauhuas 2 Group | B8: =IF($A8="","",SUMIFS('Equipment Index'!$F$2:$F$1513,'Equipment Index'!$G$2:$G$1513,$A8,'Equipment Index'!$A$2:$A$1513,"Barn - Back Rack")) -> 0 | C8: =IF($A8="","",SUMIFS('Equipment Index'!$F$2:$F$1513,'Equipment Index'!$G$2:$G$1513,$A8,'Equipment Index'!$A$2:$A$1513,"Barn - Front Rack")) -> 1 | D8: =IF($A8="","",SUMIFS('Equipment Index'!$F$2:$F$1513,'Equipment Index'!$G$2:$G$1513,$A8,'Equipment Index'!$A$2:$A$1513,"Front Lobby")) -> 0 | E8: =IF($A8="","",SUMIFS('Equipment Index'!$F$2:$F$1513,'Equipment Index'!$G$2:$G$1513,$A8,'Equipment Index'!$A$2:$A$1513,"Service Room")) -> 0 | F8: =IF($A8="","",SUMIFS('Equipment Index'!$F$2:$F$1513,'Equipment Index'!$G$2:$G$1513,$A8,'Equipment Index'!$A$2:$A$1513,"Production")) -> 0 | G8: =IF($A8="","",SUMIFS('Equipment Index'!$F$2:$F$1513,'Equipment Index'!$G$2:$G$1513,$A8,'Equipment Index'!$A$2:$A$1513,"Training Room")) -> 0 | H8: =IF($A8="","",SUMIFS('Equipment Index'!$F$2:$F$1513,'Equipment Index'!$G$2:$G$1513,$A8,'Equipment Index'!$A$2:$A$1513,"Out of State")) -> 0 | I8: =IF($A8="","",SUMIFS('Equipment Index'!$F$2:$F$1513,'Equipment Index'!$G$2:$G$1513,$A8,'Equipment Index'!$A$2:$A$1513,"San Antonio")) -> 0 | J8: =IF($A8="","",SUMIFS('Equipment Index'!$F$2:$F$1513,'Equipment Index'!$G$2:$G$1513,$A8,'Equipment Index'!$A$2:$A$1513,"Dallas")) -> 0 | K8: =IF($A8="","",SUM($B8:$J8)) -> 1 | L8: =IF($A8="","",SUMIFS('Equipment Index'!$F$2:$F$1513,'Equipment Index'!$G$2:$G$1513,$A8,'Equipment Index'!$C$2:$C$1513,"DISP")) -> 0 | M8: =IF($A8="","",SUMIFS('Equipment Index'!$F$2:$F$1513,'Equipment Index'!$G$2:$G$1513,$A8,'Equipment Index'!$C$2:$C$1513,"MOD")) -> 0 | N8: =IF($A8="","",IF(COUNTIFS('Equipment Index'!$G$2:$G$1513,$A8,'Equipment Index'!$H$2:$H$1513,"?*")=0,"","Customer-owned — "&COUNTIFS('Equipment Index'!$G$2:$G$1513,$A8,'Equipment Index'!$H$2:$H$1513,"?*")&" unit(s): "&IFERROR(INDEX('Equipment Index'!$H$2:$H$1513,SUMPRODUCT(MATCH(1,('Equipment Index'!$G$2:$G$1513=$A8)*('Equipment Index'!$H$2:$H$1513<>""),0))),"")&IF(COUNTIFS('Equipment Index'!$G$2:$G$1513,$A8,'Equipment Index'!$H$2:$H$1513,"?*")>1," + see table below","")))
A9: =IFERROR(INDEX('Equipment Index'!$G$2:$G$1513,MATCH(ROW()-7,'Equipment Index'!$J$2:$J$1513,0)),"") -> BNP 1.9L Carafes | B9: =IF($A9="","",SUMIFS('Equipment Index'!$F$2:$F$1513,'Equipment Index'!$G$2:$G$1513,$A9,'Equipment Index'!$A$2:$A$1513,"Barn - Back Rack")) -> 36 | C9: =IF($A9="","",SUMIFS('Equipment Index'!$F$2:$F$1513,'Equipment Index'!$G$2:$G$1513,$A9,'Equipment Index'!$A$2:$A$1513,"Barn - Front Rack")) -> 0 | D9: =IF($A9="","",SUMIFS('Equipment Index'!$F$2:$F$1513,'Equipment Index'!$G$2:$G$1513,$A9,'Equipment Index'!$A$2:$A$1513,"Front Lobby")) -> 0 | E9: =IF($A9="","",SUMIFS('Equipment Index'!$F$2:$F$1513,'Equipment Index'!$G$2:$G$1513,$A9,'Equipment Index'!$A$2:$A$1513,"Service Room")) -> 0 | F9: =IF($A9="","",SUMIFS('Equipment Index'!$F$2:$F$1513,'Equipment Index'!$G$2:$G$1513,$A9,'Equipment Index'!$A$2:$A$1513,"Production")) -> 0 | G9: =IF($A9="","",SUMIFS('Equipment Index'!$F$2:$F$1513,'Equipment Index'!$G$2:$G$1513,$A9,'Equipment Index'!$A$2:$A$1513,"Training Room")) -> 0 | H9: =IF($A9="","",SUMIFS('Equipment Index'!$F$2:$F$1513,'Equipment Index'!$G$2:$G$1513,$A9,'Equipment Index'!$A$2:$A$1513,"Out of State")) -> 0 | I9: =IF($A9="","",SUMIFS('Equipment Index'!$F$2:$F$1513,'Equipment Index'!$G$2:$G$1513,$A9,'Equipment Index'!$A$2:$A$1513,"San Antonio")) -> 0 | J9: =IF($A9="","",SUMIFS('Equipment Index'!$F$2:$F$1513,'Equipment Index'!$G$2:$G$1513,$A9,'Equipment Index'!$A$2:$A$1513,"Dallas")) -> 0 | K9: =IF($A9="","",SUM($B9:$J9)) -> 36 | L9: =IF($A9="","",SUMIFS('Equipment Index'!$F$2:$F$1513,'Equipment Index'!$G$2:$G$1513,$A9,'Equipment Index'!$C$2:$C$1513,"DISP")) -> 36 | M9: =IF($A9="","",SUMIFS('Equipment Index'!$F$2:$F$1513,'Equipment Index'!$G$2:$G$1513,$A9,'Equipment Index'!$C$2:$C$1513,"MOD")) -> 0 | N9: =IF($A9="","",IF(COUNTIFS('Equipment Index'!$G$2:$G$1513,$A9,'Equipment Index'!$H$2:$H$1513,"?*")=0,"","Customer-owned — "&COUNTIFS('Equipment Index'!$G$2:$G$1513,$A9,'Equipment Index'!$H$2:$H$1513,"?*")&" unit(s): "&IFERROR(INDEX('Equipment Index'!$H$2:$H$1513,SUMPRODUCT(MATCH(1,('Equipment Index'!$G$2:$G$1513=$A9)*('Equipment Index'!$H$2:$H$1513<>""),0))),"")&IF(COUNTIFS('Equipment Index'!$G$2:$G$1513,$A9,'Equipment Index'!$H$2:$H$1513,"?*")>1," + see table below","")))
A10: =IFERROR(INDEX('Equipment Index'!$G$2:$G$1513,MATCH(ROW()-7,'Equipment Index'!$J$2:$J$1513,0)),"") -> Bravilor Esprecious 22 | B10: =IF($A10="","",SUMIFS('Equipment Index'!$F$2:$F$1513,'Equipment Index'!$G$2:$G$1513,$A10,'Equipment Index'!$A$2:$A$1513,"Barn - Back Rack")) -> 0 | C10: =IF($A10="","",SUMIFS('Equipment Index'!$F$2:$F$1513,'Equipment Index'!$G$2:$G$1513,$A10,'Equipment Index'!$A$2:$A$1513,"Barn - Front Rack")) -> 1 | D10: =IF($A10="","",SUMIFS('Equipment Index'!$F$2:$F$1513,'Equipment Index'!$G$2:$G$1513,$A10,'Equipment Index'!$A$2:$A$1513,"Front Lobby")) -> 0 | E10: =IF($A10="","",SUMIFS('Equipment Index'!$F$2:$F$1513,'Equipment Index'!$G$2:$G$1513,$A10,'Equipment Index'!$A$2:$A$1513,"Service Room")) -> 0 | F10: =IF($A10="","",SUMIFS('Equipment Index'!$F$2:$F$1513,'Equipment Index'!$G$2:$G$1513,$A10,'Equipment Index'!$A$2:$A$1513,"Production")) -> 0 | G10: =IF($A10="","",SUMIFS('Equipment Index'!$F$2:$F$1513,'Equipment Index'!$G$2:$G$1513,$A10,'Equipment Index'!$A$2:$A$1513,"Training Room")) -> 0 | H10: =IF($A10="","",SUMIFS('Equipment Index'!$F$2:$F$1513,'Equipment Index'!$G$2:$G$1513,$A10,'Equipment Index'!$A$2:$A$1513,"Out of State")) -> 0 | I10: =IF($A10="","",SUMIFS('Equipment Index'!$F$2:$F$1513,'Equipment Index'!$G$2:$G$1513,$A10,'Equipment Index'!$A$2:$A$1513,"San Antonio")) -> 0 | J10: =IF($A10="","",SUMIFS('Equipment Index'!$F$2:$F$1513,'Equipment Index'!$G$2:$G$1513,$A10,'Equipment Index'!$A$2:$A$1513,"Dallas")) -> 0 | K10: =IF($A10="","",SUM($B10:$J10)) -> 1 | L10: =IF($A10="","",SUMIFS('Equipment Index'!$F$2:$F$1513,'Equipment Index'!$G$2:$G$1513,$A10,'Equipment Index'!$C$2:$C$1513,"DISP")) -> 0 | M10: =IF($A10="","",SUMIFS('Equipment Index'!$F$2:$F$1513,'Equipment Index'!$G$2:$G$1513,$A10,'Equipment Index'!$C$2:$C$1513,"MOD")) -> 0 | N10: =IF($A10="","",IF(COUNTIFS('Equipment Index'!$G$2:$G$1513,$A10,'Equipment Index'!$H$2:$H$1513,"?*")=0,"","Customer-owned — "&COUNTIFS('Equipment Index'!$G$2:$G$1513,$A10,'Equipment Index'!$H$2:$H$1513,"?*")&" unit(s): "&IFERROR(INDEX('Equipment Index'!$H$2:$H$1513,SUMPRODUCT(MATCH(1,('Equipment Index'!$G$2:$G$1513=$A10)*('Equipment Index'!$H$2:$H$1513<>""),0))),"")&IF(COUNTIFS('Equipment Index'!$G$2:$G$1513,$A10,'Equipment Index'!$H$2:$H$1513,"?*")>1," + see table below","")))
A11: =IFERROR(INDEX('Equipment Index'!$G$2:$G$1513,MATCH(ROW()-7,'Equipment Index'!$J$2:$J$1513,0)),"") -> Bunn Axiom-15-2U1L | B11: =IF($A11="","",SUMIFS('Equipment Index'!$F$2:$F$1513,'Equipment Index'!$G$2:$G$1513,$A11,'Equipment Index'!$A$2:$A$1513,"Barn - Back Rack")) -> 4 | C11: =IF($A11="","",SUMIFS('Equipment Index'!$F$2:$F$1513,'Equipment Index'!$G$2:$G$1513,$A11,'Equipment Index'!$A$2:$A$1513,"Barn - Front Rack")) -> 0 | D11: =IF($A11="","",SUMIFS('Equipment Index'!$F$2:$F$1513,'Equipment Index'!$G$2:$G$1513,$A11,'Equipment Index'!$A$2:$A$1513,"Front Lobby")) -> 0 | E11: =IF($A11="","",SUMIFS('Equipment Index'!$F$2:$F$1513,'Equipment Index'!$G$2:$G$1513,$A11,'Equipment Index'!$A$2:$A$1513,"Service Room")) -> 0 | F11: =IF($A11="","",SUMIFS('Equipment Index'!$F$2:$F$1513,'Equipment Index'!$G$2:$G$1513,$A11,'Equipment Index'!$A$2:$A$1513,"Production")) -> 0 | G11: =IF($A11="","",SUMIFS('Equipment Index'!$F$2:$F$1513,'Equipment Index'!$G$2:$G$1513,$A11,'Equipment Index'!$A$2:$A$1513,"Training Room")) -> 0 | H11: =IF($A11="","",SUMIFS('Equipment Index'!$F$2:$F$1513,'Equipment Index'!$G$2:$G$1513,$A11,'Equipment Index'!$A$2:$A$1513,"Out of State")) -> 0 | I11: =IF($A11="","",SUMIFS('Equipment Index'!$F$2:$F$1513,'Equipment Index'!$G$2:$G$1513,$A11,'Equipment Index'!$A$2:$A$1513,"San Antonio")) -> 0 | J11: =IF($A11="","",SUMIFS('Equipment Index'!$F$2:$F$1513,'Equipment Index'!$G$2:$G$1513,$A11,'Equipment Index'!$A$2:$A$1513,"Dallas")) -> 0 | K11: =IF($A11="","",SUM($B11:$J11)) -> 4 | L11: =IF($A11="","",SUMIFS('Equipment Index'!$F$2:$F$1513,'Equipment Index'!$G$2:$G$1513,$A11,'Equipment Index'!$C$2:$C$1513,"DISP")) -> 0 | M11: =IF($A11="","",SUMIFS('Equipment Index'!$F$2:$F$1513,'Equipment Index'!$G$2:$G$1513,$A11,'Equipment Index'!$C$2:$C$1513,"MOD")) -> 0 | N11: =IF($A11="","",IF(COUNTIFS('Equipment Index'!$G$2:$G$1513,$A11,'Equipment Index'!$H$2:$H$1513,"?*")=0,"","Customer-owned — "&COUNTIFS('Equipment Index'!$G$2:$G$1513,$A11,'Equipment Index'!$H$2:$H$1513,"?*")&" unit(s): "&IFERROR(INDEX('Equipment Index'!$H$2:$H$1513,SUMPRODUCT(MATCH(1,('Equipment Index'!$G$2:$G$1513=$A11)*('Equipment Index'!$H$2:$H$1513<>""),0))),"")&IF(COUNTIFS('Equipment Index'!$G$2:$G$1513,$A11,'Equipment Index'!$H$2:$H$1513,"?*")>1," + see table below","")))
A12: =IFERROR(INDEX('Equipment Index'!$G$2:$G$1513,MATCH(ROW()-7,'Equipment Index'!$J$2:$J$1513,0)),"") -> Bunn Axiom-APS | B12: =IF($A12="","",SUMIFS('Equipment Index'!$F$2:$F$1513,'Equipment Index'!$G$2:$G$1513,$A12,'Equipment Index'!$A$2:$A$1513,"Barn - Back Rack")) -> 20 | C12: =IF($A12="","",SUMIFS('Equipment Index'!$F$2:$F$1513,'Equipment Index'!$G$2:$G$1513,$A12,'Equipment Index'!$A$2:$A$1513,"Barn - Front Rack")) -> 6 | D12: =IF($A12="","",SUMIFS('Equipment Index'!$F$2:$F$1513,'Equipment Index'!$G$2:$G$1513,$A12,'Equipment Index'!$A$2:$A$1513,"Front Lobby")) -> 0 | E12: =IF($A12="","",SUMIFS('Equipment Index'!$F$2:$F$1513,'Equipment Index'!$G$2:$G$1513,$A12,'Equipment Index'!$A$2:$A$1513,"Service Room")) -> 0 | F12: =IF($A12="","",SUMIFS('Equipment Index'!$F$2:$F$1513,'Equipment Index'!$G$2:$G$1513,$A12,'Equipment Index'!$A$2:$A$1513,"Production")) -> 0 | G12: =IF($A12="","",SUMIFS('Equipment Index'!$F$2:$F$1513,'Equipment Index'!$G$2:$G$1513,$A12,'Equipment Index'!$A$2:$A$1513,"Training Room")) -> 0 | H12: =IF($A12="","",SUMIFS('Equipment Index'!$F$2:$F$1513,'Equipment Index'!$G$2:$G$1513,$A12,'Equipment Index'!$A$2:$A$1513,"Out of State")) -> 0 | I12: =IF($A12="","",SUMIFS('Equipment Index'!$F$2:$F$1513,'Equipment Index'!$G$2:$G$1513,$A12,'Equipment Index'!$A$2:$A$1513,"San Antonio")) -> 0 | J12: =IF($A12="","",SUMIFS('Equipment Index'!$F$2:$F$1513,'Equipment Index'!$G$2:$G$1513,$A12,'Equipment Index'!$A$2:$A$1513,"Dallas")) -> 0 | K12: =IF($A12="","",SUM($B12:$J12)) -> 26 | L12: =IF($A12="","",SUMIFS('Equipment Index'!$F$2:$F$1513,'Equipment Index'!$G$2:$G$1513,$A12,'Equipment Index'!$C$2:$C$1513,"DISP")) -> 0 | M12: =IF($A12="","",SUMIFS('Equipment Index'!$F$2:$F$1513,'Equipment Index'!$G$2:$G$1513,$A12,'Equipment Index'!$C$2:$C$1513,"MOD")) -> 0 | N12: =IF($A12="","",IF(COUNTIFS('Equipment Index'!$G$2:$G$1513,$A12,'Equipment Index'!$H$2:$H$1513,"?*")=0,"","Customer-owned — "&COUNTIFS('Equipment Index'!$G$2:$G$1513,$A12,'Equipment Index'!$H$2:$H$1513,"?*")&" unit(s): "&IFERROR(INDEX('Equipment Index'!$H$2:$H$1513,SUMPRODUCT(MATCH(1,('Equipment Index'!$G$2:$G$1513=$A12)*('Equipment Index'!$H$2:$H$1513<>""),0))),"")&IF(COUNTIFS('Equipment Index'!$G$2:$G$1513,$A12,'Equipment Index'!$H$2:$H$1513,"?*")>1," + see table below","")))
A13: =IFERROR(INDEX('Equipment Index'!$G$2:$G$1513,MATCH(ROW()-7,'Equipment Index'!$J$2:$J$1513,0)),"") -> Bunn CWTF-15-2U1L | B13: =IF($A13="","",SUMIFS('Equipment Index'!$F$2:$F$1513,'Equipment Index'!$G$2:$G$1513,$A13,'Equipment Index'!$A$2:$A$1513,"Barn - Back Rack")) -> 3 | C13: =IF($A13="","",SUMIFS('Equipment Index'!$F$2:$F$1513,'Equipment Index'!$G$2:$G$1513,$A13,'Equipment Index'!$A$2:$A$1513,"Barn - Front Rack")) -> 0 | D13: =IF($A13="","",SUMIFS('Equipment Index'!$F$2:$F$1513,'Equipment Index'!$G$2:$G$1513,$A13,'Equipment Index'!$A$2:$A$1513,"Front Lobby")) -> 0 | E13: =IF($A13="","",SUMIFS('Equipment Index'!$F$2:$F$1513,'Equipment Index'!$G$2:$G$1513,$A13,'Equipment Index'!$A$2:$A$1513,"Service Room")) -> 0 | F13: =IF($A13="","",SUMIFS('Equipment Index'!$F$2:$F$1513,'Equipment Index'!$G$2:$G$1513,$A13,'Equipment Index'!$A$2:$A$1513,"Production")) -> 0 | G13: =IF($A13="","",SUMIFS('Equipment Index'!$F$2:$F$1513,'Equipment Index'!$G$2:$G$1513,$A13,'Equipment Index'!$A$2:$A$1513,"Training Room")) -> 0 | H13: =IF($A13="","",SUMIFS('Equipment Index'!$F$2:$F$1513,'Equipment Index'!$G$2:$G$1513,$A13,'Equipment Index'!$A$2:$A$1513,"Out of State")) -> 0 | I13: =IF($A13="","",SUMIFS('Equipment Index'!$F$2:$F$1513,'Equipment Index'!$G$2:$G$1513,$A13,'Equipment Index'!$A$2:$A$1513,"San Antonio")) -> 0 | J13: =IF($A13="","",SUMIFS('Equipment Index'!$F$2:$F$1513,'Equipment Index'!$G$2:$G$1513,$A13,'Equipment Index'!$A$2:$A$1513,"Dallas")) -> 0 | K13: =IF($A13="","",SUM($B13:$J13)) -> 3 | L13: =IF($A13="","",SUMIFS('Equipment Index'!$F$2:$F$1513,'Equipment Index'!$G$2:$G$1513,$A13,'Equipment Index'!$C$2:$C$1513,"DISP")) -> 0 | M13: =IF($A13="","",SUMIFS('Equipment Index'!$F$2:$F$1513,'Equipment Index'!$G$2:$G$1513,$A13,'Equipment Index'!$C$2:$C$1513,"MOD")) -> 0 | N13: =IF($A13="","",IF(COUNTIFS('Equipment Index'!$G$2:$G$1513,$A13,'Equipment Index'!$H$2:$H$1513,"?*")=0,"","Customer-owned — "&COUNTIFS('Equipment Index'!$G$2:$G$1513,$A13,'Equipment Index'!$H$2:$H$1513,"?*")&" unit(s): "&IFERROR(INDEX('Equipment Index'!$H$2:$H$1513,SUMPRODUCT(MATCH(1,('Equipment Index'!$G$2:$G$1513=$A13)*('Equipment Index'!$H$2:$H$1513<>""),0))),"")&IF(COUNTIFS('Equipment Index'!$G$2:$G$1513,$A13,'Equipment Index'!$H$2:$H$1513,"?*")>1," + see table below","")))
A14: =IFERROR(INDEX('Equipment Index'!$G$2:$G$1513,MATCH(ROW()-7,'Equipment Index'!$J$2:$J$1513,0)),"") -> Bunn CWTF-APS | B14: =IF($A14="","",SUMIFS('Equipment Index'!$F$2:$F$1513,'Equipment Index'!$G$2:$G$1513,$A14,'Equipment Index'!$A$2:$A$1513,"Barn - Back Rack")) -> 0 | C14: =IF($A14="","",SUMIFS('Equipment Index'!$F$2:$F$1513,'Equipment Index'!$G$2:$G$1513,$A14,'Equipment Index'!$A$2:$A$1513,"Barn - Front Rack")) -> 0 | D14: =IF($A14="","",SUMIFS('Equipment Index'!$F$2:$F$1513,'Equipment Index'!$G$2:$G$1513,$A14,'Equipment Index'!$A$2:$A$1513,"Front Lobby")) -> 0 | E14: =IF($A14="","",SUMIFS('Equipment Index'!$F$2:$F$1513,'Equipment Index'!$G$2:$G$1513,$A14,'Equipment Index'!$A$2:$A$1513,"Service Room")) -> 1 | F14: =IF($A14="","",SUMIFS('Equipment Index'!$F$2:$F$1513,'Equipment Index'!$G$2:$G$1513,$A14,'Equipment Index'!$A$2:$A$1513,"Production")) -> 0 | G14: =IF($A14="","",SUMIFS('Equipment Index'!$F$2:$F$1513,'Equipment Index'!$G$2:$G$1513,$A14,'Equipment Index'!$A$2:$A$1513,"Training Room")) -> 0 | H14: =IF($A14="","",SUMIFS('Equipment Index'!$F$2:$F$1513,'Equipment Index'!$G$2:$G$1513,$A14,'Equipment Index'!$A$2:$A$1513,"Out of State")) -> 0 | I14: =IF($A14="","",SUMIFS('Equipment Index'!$F$2:$F$1513,'Equipment Index'!$G$2:$G$1513,$A14,'Equipment Index'!$A$2:$A$1513,"San Antonio")) -> 0 | J14: =IF($A14="","",SUMIFS('Equipment Index'!$F$2:$F$1513,'Equipment Index'!$G$2:$G$1513,$A14,'Equipment Index'!$A$2:$A$1513,"Dallas")) -> 0 | K14: =IF($A14="","",SUM($B14:$J14)) -> 1 | L14: =IF($A14="","",SUMIFS('Equipment Index'!$F$2:$F$1513,'Equipment Index'!$G$2:$G$1513,$A14,'Equipment Index'!$C$2:$C$1513,"DISP")) -> 0 | M14: =IF($A14="","",SUMIFS('Equipment Index'!$F$2:$F$1513,'Equipment Index'!$G$2:$G$1513,$A14,'Equipment Index'!$C$2:$C$1513,"MOD")) -> 0 | N14: =IF($A14="","",IF(COUNTIFS('Equipment Index'!$G$2:$G$1513,$A14,'Equipment Index'!$H$2:$H$1513,"?*")=0,"","Customer-owned — "&COUNTIFS('Equipment Index'!$G$2:$G$1513,$A14,'Equipment Index'!$H$2:$H$1513,"?*")&" unit(s): "&IFERROR(INDEX('Equipment Index'!$H$2:$H$1513,SUMPRODUCT(MATCH(1,('Equipment Index'!$G$2:$G$1513=$A14)*('Equipment Index'!$H$2:$H$1513<>""),0))),"")&IF(COUNTIFS('Equipment Index'!$G$2:$G$1513,$A14,'Equipment Index'!$H$2:$H$1513,"?*")>1," + see table below","")))
A15: =IFERROR(INDEX('Equipment Index'!$G$2:$G$1513,MATCH(ROW()-7,'Equipment Index'!$J$2:$J$1513,0)),"") -> Bunn CWTF-APS Twin | B15: =IF($A15="","",SUMIFS('Equipment Index'!$F$2:$F$1513,'Equipment Index'!$G$2:$G$1513,$A15,'Equipment Index'!$A$2:$A$1513,"Barn - Back Rack")) -> 2 | C15: =IF($A15="","",SUMIFS('Equipment Index'!$F$2:$F$1513,'Equipment Index'!$G$2:$G$1513,$A15,'Equipment Index'!$A$2:$A$1513,"Barn - Front Rack")) -> 0 | D15: =IF($A15="","",SUMIFS('Equipment Index'!$F$2:$F$1513,'Equipment Index'!$G$2:$G$1513,$A15,'Equipment Index'!$A$2:$A$1513,"Front Lobby")) -> 0 | E15: =IF($A15="","",SUMIFS('Equipment Index'!$F$2:$F$1513,'Equipment Index'!$G$2:$G$1513,$A15,'Equipment Index'!$A$2:$A$1513,"Service Room")) -> 0 | F15: =IF($A15="","",SUMIFS('Equipment Index'!$F$2:$F$1513,'Equipment Index'!$G$2:$G$1513,$A15,'Equipment Index'!$A$2:$A$1513,"Production")) -> 0 | G15: =IF($A15="","",SUMIFS('Equipment Index'!$F$2:$F$1513,'Equipment Index'!$G$2:$G$1513,$A15,'Equipment Index'!$A$2:$A$1513,"Training Room")) -> 0 | H15: =IF($A15="","",SUMIFS('Equipment Index'!$F$2:$F$1513,'Equipment Index'!$G$2:$G$1513,$A15,'Equipment Index'!$A$2:$A$1513,"Out of State")) -> 0 | I15: =IF($A15="","",SUMIFS('Equipment Index'!$F$2:$F$1513,'Equipment Index'!$G$2:$G$1513,$A15,'Equipment Index'!$A$2:$A$1513,"San Antonio")) -> 0 | J15: =IF($A15="","",SUMIFS('Equipment Index'!$F$2:$F$1513,'Equipment Index'!$G$2:$G$1513,$A15,'Equipment Index'!$A$2:$A$1513,"Dallas")) -> 0 | K15: =IF($A15="","",SUM($B15:$J15)) -> 2 | L15: =IF($A15="","",SUMIFS('Equipment Index'!$F$2:$F$1513,'Equipment Index'!$G$2:$G$1513,$A15,'Equipment Index'!$C$2:$C$1513,"DISP")) -> 0 | M15: =IF($A15="","",SUMIFS('Equipment Index'!$F$2:$F$1513,'Equipment Index'!$G$2:$G$1513,$A15,'Equipment Index'!$C$2:$C$1513,"MOD")) -> 0 | N15: =IF($A15="","",IF(COUNTIFS('Equipment Index'!$G$2:$G$1513,$A15,'Equipment Index'!$H$2:$H$1513,"?*")=0,"","Customer-owned — "&COUNTIFS('Equipment Index'!$G$2:$G$1513,$A15,'Equipment Index'!$H$2:$H$1513,"?*")&" unit(s): "&IFERROR(INDEX('Equipment Index'!$H$2:$H$1513,SUMPRODUCT(MATCH(1,('Equipment Index'!$G$2:$G$1513=$A15)*('Equipment Index'!$H$2:$H$1513<>""),0))),"")&IF(COUNTIFS('Equipment Index'!$G$2:$G$1513,$A15,'Equipment Index'!$H$2:$H$1513,"?*")>1," + see table below","")))
A16: =IFERROR(INDEX('Equipment Index'!$G$2:$G$1513,MATCH(ROW()-7,'Equipment Index'!$J$2:$J$1513,0)),"") -> Bunn CWTF-TC Twin | B16: =IF($A16="","",SUMIFS('Equipment Index'!$F$2:$F$1513,'Equipment Index'!$G$2:$G$1513,$A16,'Equipment Index'!$A$2:$A$1513,"Barn - Back Rack")) -> 3 | C16: =IF($A16="","",SUMIFS('Equipment Index'!$F$2:$F$1513,'Equipment Index'!$G$2:$G$1513,$A16,'Equipment Index'!$A$2:$A$1513,"Barn - Front Rack")) -> 0 | D16: =IF($A16="","",SUMIFS('Equipment Index'!$F$2:$F$1513,'Equipment Index'!$G$2:$G$1513,$A16,'Equipment Index'!$A$2:$A$1513,"Front Lobby")) -> 0 | E16: =IF($A16="","",SUMIFS('Equipment Index'!$F$2:$F$1513,'Equipment Index'!$G$2:$G$1513,$A16,'Equipment Index'!$A$2:$A$1513,"Service Room")) -> 0 | F16: =IF($A16="","",SUMIFS('Equipment Index'!$F$2:$F$1513,'Equipment Index'!$G$2:$G$1513,$A16,'Equipment Index'!$A$2:$A$1513,"Production")) -> 0 | G16: =IF($A16="","",SUMIFS('Equipment Index'!$F$2:$F$1513,'Equipment Index'!$G$2:$G$1513,$A16,'Equipment Index'!$A$2:$A$1513,"Training Room")) -> 0 | H16: =IF($A16="","",SUMIFS('Equipment Index'!$F$2:$F$1513,'Equipment Index'!$G$2:$G$1513,$A16,'Equipment Index'!$A$2:$A$1513,"Out of State")) -> 0 | I16: =IF($A16="","",SUMIFS('Equipment Index'!$F$2:$F$1513,'Equipment Index'!$G$2:$G$1513,$A16,'Equipment Index'!$A$2:$A$1513,"San Antonio")) -> 0 | J16: =IF($A16="","",SUMIFS('Equipment Index'!$F$2:$F$1513,'Equipment Index'!$G$2:$G$1513,$A16,'Equipment Index'!$A$2:$A$1513,"Dallas")) -> 0 | K16: =IF($A16="","",SUM($B16:$J16)) -> 3 | L16: =IF($A16="","",SUMIFS('Equipment Index'!$F$2:$F$1513,'Equipment Index'!$G$2:$G$1513,$A16,'Equipment Index'!$C$2:$C$1513,"DISP")) -> 0 | M16: =IF($A16="","",SUMIFS('Equipment Index'!$F$2:$F$1513,'Equipment Index'!$G$2:$G$1513,$A16,'Equipment Index'!$C$2:$C$1513,"MOD")) -> 0 | N16: =IF($A16="","",IF(COUNTIFS('Equipment Index'!$G$2:$G$1513,$A16,'Equipment Index'!$H$2:$H$1513,"?*")=0,"","Customer-owned — "&COUNTIFS('Equipment Index'!$G$2:$G$1513,$A16,'Equipment Index'!$H$2:$H$1513,"?*")&" unit(s): "&IFERROR(INDEX('Equipment Index'!$H$2:$H$1513,SUMPRODUCT(MATCH(1,('Equipment Index'!$G$2:$G$1513=$A16)*('Equipment Index'!$H$2:$H$1513<>""),0))),"")&IF(COUNTIFS('Equipment Index'!$G$2:$G$1513,$A16,'Equipment Index'!$H$2:$H$1513,"?*")>1," + see table below","")))
A17: =IFERROR(INDEX('Equipment Index'!$G$2:$G$1513,MATCH(ROW()-7,'Equipment Index'!$J$2:$J$1513,0)),"") -> Bunn FPG-2E | B17: =IF($A17="","",SUMIFS('Equipment Index'!$F$2:$F$1513,'Equipment Index'!$G$2:$G$1513,$A17,'Equipment Index'!$A$2:$A$1513,"Barn - Back Rack")) -> 2 | C17: =IF($A17="","",SUMIFS('Equipment Index'!$F$2:$F$1513,'Equipment Index'!$G$2:$G$1513,$A17,'Equipment Index'!$A$2:$A$1513,"Barn - Front Rack")) -> 0 | D17: =IF($A17="","",SUMIFS('Equipment Index'!$F$2:$F$1513,'Equipment Index'!$G$2:$G$1513,$A17,'Equipment Index'!$A$2:$A$1513,"Front Lobby")) -> 0 | E17: =IF($A17="","",SUMIFS('Equipment Index'!$F$2:$F$1513,'Equipment Index'!$G$2:$G$1513,$A17,'Equipment Index'!$A$2:$A$1513,"Service Room")) -> 0 | F17: =IF($A17="","",SUMIFS('Equipment Index'!$F$2:$F$1513,'Equipment Index'!$G$2:$G$1513,$A17,'Equipment Index'!$A$2:$A$1513,"Production")) -> 0 | G17: =IF($A17="","",SUMIFS('Equipment Index'!$F$2:$F$1513,'Equipment Index'!$G$2:$G$1513,$A17,'Equipment Index'!$A$2:$A$1513,"Training Room")) -> 0 | H17: =IF($A17="","",SUMIFS('Equipment Index'!$F$2:$F$1513,'Equipment Index'!$G$2:$G$1513,$A17,'Equipment Index'!$A$2:$A$1513,"Out of State")) -> 0 | I17: =IF($A17="","",SUMIFS('Equipment Index'!$F$2:$F$1513,'Equipment Index'!$G$2:$G$1513,$A17,'Equipment Index'!$A$2:$A$1513,"San Antonio")) -> 1 | J17: =IF($A17="","",SUMIFS('Equipment Index'!$F$2:$F$1513,'Equipment Index'!$G$2:$G$1513,$A17,'Equipment Index'!$A$2:$A$1513,"Dallas")) -> 0 | K17: =IF($A17="","",SUM($B17:$J17)) -> 3 | L17: =IF($A17="","",SUMIFS('Equipment Index'!$F$2:$F$1513,'Equipment Index'!$G$2:$G$1513,$A17,'Equipment Index'!$C$2:$C$1513,"DISP")) -> 0 | M17: =IF($A17="","",SUMIFS('Equipment Index'!$F$2:$F$1513,'Equipment Index'!$G$2:$G$1513,$A17,'Equipment Index'!$C$2:$C$1513,"MOD")) -> 0 | N17: =IF($A17="","",IF(COUNTIFS('Equipment Index'!$G$2:$G$1513,$A17,'Equipment Index'!$H$2:$H$1513,"?*")=0,"","Customer-owned — "&COUNTIFS('Equipment Index'!$G$2:$G$1513,$A17,'Equipment Index'!$H$2:$H$1513,"?*")&" unit(s): "&IFERROR(INDEX('Equipment Index'!$H$2:$H$1513,SUMPRODUCT(MATCH(1,('Equipment Index'!$G$2:$G$1513=$A17)*('Equipment Index'!$H$2:$H$1513<>""),0))),"")&IF(COUNTIFS('Equipment Index'!$G$2:$G$1513,$A17,'Equipment Index'!$H$2:$H$1513,"?*")>1," + see table below","")))
A18: =IFERROR(INDEX('Equipment Index'!$G$2:$G$1513,MATCH(ROW()-7,'Equipment Index'!$J$2:$J$1513,0)),"") -> Bunn G1 | B18: =IF($A18="","",SUMIFS('Equipment Index'!$F$2:$F$1513,'Equipment Index'!$G$2:$G$1513,$A18,'Equipment Index'!$A$2:$A$1513,"Barn - Back Rack")) -> 0 | C18: =IF($A18="","",SUMIFS('Equipment Index'!$F$2:$F$1513,'Equipment Index'!$G$2:$G$1513,$A18,'Equipment Index'!$A$2:$A$1513,"Barn - Front Rack")) -> 0 | D18: =IF($A18="","",SUMIFS('Equipment Index'!$F$2:$F$1513,'Equipment Index'!$G$2:$G$1513,$A18,'Equipment Index'!$A$2:$A$1513,"Front Lobby")) -> 0 | E18: =IF($A18="","",SUMIFS('Equipment Index'!$F$2:$F$1513,'Equipment Index'!$G$2:$G$1513,$A18,'Equipment Index'!$A$2:$A$1513,"Service Room")) -> 0 | F18: =IF($A18="","",SUMIFS('Equipment Index'!$F$2:$F$1513,'Equipment Index'!$G$2:$G$1513,$A18,'Equipment Index'!$A$2:$A$1513,"Production")) -> 0 | G18: =IF($A18="","",SUMIFS('Equipment Index'!$F$2:$F$1513,'Equipment Index'!$G$2:$G$1513,$A18,'Equipment Index'!$A$2:$A$1513,"Training Room")) -> 0 | H18: =IF($A18="","",SUMIFS('Equipment Index'!$F$2:$F$1513,'Equipment Index'!$G$2:$G$1513,$A18,'Equipment Index'!$A$2:$A$1513,"Out of State")) -> 0 | I18: =IF($A18="","",SUMIFS('Equipment Index'!$F$2:$F$1513,'Equipment Index'!$G$2:$G$1513,$A18,'Equipment Index'!$A$2:$A$1513,"San Antonio")) -> 1 | J18: =IF($A18="","",SUMIFS('Equipment Index'!$F$2:$F$1513,'Equipment Index'!$G$2:$G$1513,$A18,'Equipment Index'!$A$2:$A$1513,"Dallas")) -> 0 | K18: =IF($A18="","",SUM($B18:$J18)) -> 1 | L18: =IF($A18="","",SUMIFS('Equipment Index'!$F$2:$F$1513,'Equipment Index'!$G$2:$G$1513,$A18,'Equipment Index'!$C$2:$C$1513,"DISP")) -> 0 | M18: =IF($A18="","",SUMIFS('Equipment Index'!$F$2:$F$1513,'Equipment Index'!$G$2:$G$1513,$A18,'Equipment Index'!$C$2:$C$1513,"MOD")) -> 0 | N18: =IF($A18="","",IF(COUNTIFS('Equipment Index'!$G$2:$G$1513,$A18,'Equipment Index'!$H$2:$H$1513,"?*")=0,"","Customer-owned — "&COUNTIFS('Equipment Index'!$G$2:$G$1513,$A18,'Equipment Index'!$H$2:$H$1513,"?*")&" unit(s): "&IFERROR(INDEX('Equipment Index'!$H$2:$H$1513,SUMPRODUCT(MATCH(1,('Equipment Index'!$G$2:$G$1513=$A18)*('Equipment Index'!$H$2:$H$1513<>""),0))),"")&IF(COUNTIFS('Equipment Index'!$G$2:$G$1513,$A18,'Equipment Index'!$H$2:$H$1513,"?*")>1," + see table below","")))
A19: =IFERROR(INDEX('Equipment Index'!$G$2:$G$1513,MATCH(ROW()-7,'Equipment Index'!$J$2:$J$1513,0)),"") -> Bunn G2 | B19: =IF($A19="","",SUMIFS('Equipment Index'!$F$2:$F$1513,'Equipment Index'!$G$2:$G$1513,$A19,'Equipment Index'!$A$2:$A$1513,"Barn - Back Rack")) -> 0 | C19: =IF($A19="","",SUMIFS('Equipment Index'!$F$2:$F$1513,'Equipment Index'!$G$2:$G$1513,$A19,'Equipment Index'!$A$2:$A$1513,"Barn - Front Rack")) -> 0 | D19: =IF($A19="","",SUMIFS('Equipment Index'!$F$2:$F$1513,'Equipment Index'!$G$2:$G$1513,$A19,'Equipment Index'!$A$2:$A$1513,"Front Lobby")) -> 1 | E19: =IF($A19="","",SUMIFS('Equipment Index'!$F$2:$F$1513,'Equipment Index'!$G$2:$G$1513,$A19,'Equipment Index'!$A$2:$A$1513,"Service Room")) -> 0 | F19: =IF($A19="","",SUMIFS('Equipment Index'!$F$2:$F$1513,'Equipment Index'!$G$2:$G$1513,$A19,'Equipment Index'!$A$2:$A$1513,"Production")) -> 0 | G19: =IF($A19="","",SUMIFS('Equipment Index'!$F$2:$F$1513,'Equipment Index'!$G$2:$G$1513,$A19,'Equipment Index'!$A$2:$A$1513,"Training Room")) -> 0 | H19: =IF($A19="","",SUMIFS('Equipment Index'!$F$2:$F$1513,'Equipment Index'!$G$2:$G$1513,$A19,'Equipment Index'!$A$2:$A$1513,"Out of State")) -> 0 | I19: =IF($A19="","",SUMIFS('Equipment Index'!$F$2:$F$1513,'Equipment Index'!$G$2:$G$1513,$A19,'Equipment Index'!$A$2:$A$1513,"San Antonio")) -> 0 | J19: =IF($A19="","",SUMIFS('Equipment Index'!$F$2:$F$1513,'Equipment Index'!$G$2:$G$1513,$A19,'Equipment Index'!$A$2:$A$1513,"Dallas")) -> 0 | K19: =IF($A19="","",SUM($B19:$J19)) -> 1 | L19: =IF($A19="","",SUMIFS('Equipment Index'!$F$2:$F$1513,'Equipment Index'!$G$2:$G$1513,$A19,'Equipment Index'!$C$2:$C$1513,"DISP")) -> 0 | M19: =IF($A19="","",SUMIFS('Equipment Index'!$F$2:$F$1513,'Equipment Index'!$G$2:$G$1513,$A19,'Equipment Index'!$C$2:$C$1513,"MOD")) -> 0 | N19: =IF($A19="","",IF(COUNTIFS('Equipment Index'!$G$2:$G$1513,$A19,'Equipment Index'!$H$2:$H$1513,"?*")=0,"","Customer-owned — "&COUNTIFS('Equipment Index'!$G$2:$G$1513,$A19,'Equipment Index'!$H$2:$H$1513,"?*")&" unit(s): "&IFERROR(INDEX('Equipment Index'!$H$2:$H$1513,SUMPRODUCT(MATCH(1,('Equipment Index'!$G$2:$G$1513=$A19)*('Equipment Index'!$H$2:$H$1513<>""),0))),"")&IF(COUNTIFS('Equipment Index'!$G$2:$G$1513,$A19,'Equipment Index'!$H$2:$H$1513,"?*")>1," + see table below","")))
... A157: =IFERROR(INDEX('Equipment Index'!$G$2:$G$1513,MATCH(ROW()-7,'Equipment Index'!$J$2:$J$1513,0)),"") | B157: =IF($A157="","",SUMIFS('Equipment Index'!$F$2:$F$1513,'Equipment Index'!$G$2:$G$1513,$A157,'Equipment Index'!$A$2:$A$1513,"Barn - Back Rack")) | C157: =IF($A157="","",SUMIFS('Equipment Index'!$F$2:$F$1513,'Equipment Index'!$G$2:$G$1513,$A157,'Equipment Index'!$A$2:$A$1513,"Barn - Front Rack")) | D157: =IF($A157="","",SUMIFS('Equipment Index'!$F$2:$F$1513,'Equipment Index'!$G$2:$G$1513,$A157,'Equipment Index'!$A$2:$A$1513,"Front Lobby")) | E157: =IF($A157="","",SUMIFS('Equipment Index'!$F$2:$F$1513,'Equipment Index'!$G$2:$G$1513,$A157,'Equipment Index'!$A$2:$A$1513,"Service Room")) | F157: =IF($A157="","",SUMIFS('Equipment Index'!$F$2:$F$1513,'Equipment Index'!$G$2:$G$1513,$A157,'Equipment Index'!$A$2:$A$1513,"Production")) | G157: =IF($A157="","",SUMIFS('Equipment Index'!$F$2:$F$1513,'Equipment Index'!$G$2:$G$1513,$A157,'Equipment Index'!$A$2:$A$1513,"Training Room")) | H157: =IF($A157="","",SUMIFS('Equipment Index'!$F$2:$F$1513,'Equipment Index'!$G$2:$G$1513,$A157,'Equipment Index'!$A$2:$A$1513,"Out of State")) | I157: =IF($A157="","",SUMIFS('Equipment Index'!$F$2:$F$1513,'Equipment Index'!$G$2:$G$1513,$A157,'Equipment Index'!$A$2:$A$1513,"San Antonio")) | J157: =IF($A157="","",SUMIFS('Equipment Index'!$F$2:$F$1513,'Equipment Index'!$G$2:$G$1513,$A157,'Equipment Index'!$A$2:$A$1513,"Dallas")) | K157: =IF($A157="","",SUM($B157:$J157)) | L157: =IF($A157="","",SUMIFS('Equipment Index'!$F$2:$F$1513,'Equipment Index'!$G$2:$G$1513,$A157,'Equipment Index'!$C$2:$C$1513,"DISP")) | M157: =IF($A157="","",SUMIFS('Equipment Index'!$F$2:$F$1513,'Equipment Index'!$G$2:$G$1513,$A157,'Equipment Index'!$C$2:$C$1513,"MOD")) | N157: =IF($A157="","",IF(COUNTIFS('Equipment Index'!$G$2:$G$1513,$A157,'Equipment Index'!$H$2:$H$1513,"?*")=0,"","Customer-owned — "&COUNTIFS('Equipment Index'!$G$2:$G$1513,$A157,'Equipment Index'!$H$2:$H$1513,"?*")&" unit(s): "&IFERROR(INDEX('Equipment Index'!$H$2:$H$1513,SUMPRODUCT(MATCH(1,('Equipment Index'!$G$2:$G$1513=$A157)*('Equipment Index'!$H$2:$H$1513<>""),0))),"")&IF(COUNTIFS('Equipment Index'!$G$2:$G$1513,$A157,'Equipment Index'!$H$2:$H$1513,"?*")>1," + see table below","")))
A160: CUSTOMER-OWNED EQUIPMENT — built automatically from any model entered with a customer in parentheses
A161: Model | B161: Serial # | C161: Customer | D161: Location | E161: Position
A162: =IFERROR(INDEX('Equipment Index'!$G$2:$G$1513,MATCH(1,'Equipment Index'!$K$2:$K$1513,0)),"") -> Eversys e'4s | B162: =IFERROR(INDEX('Equipment Index'!$E$2:$E$1513,MATCH(1,'Equipment Index'!$K$2:$K$1513,0)),"") | C162: =IFERROR(INDEX('Equipment Index'!$H$2:$H$1513,MATCH(1,'Equipment Index'!$K$2:$K$1513,0)),"") -> Vida | D162: =IFERROR(INDEX('Equipment Index'!$A$2:$A$1513,MATCH(1,'Equipment Index'!$K$2:$K$1513,0)),"") -> Barn - Back Rack | E162: =IFERROR(INDEX('Equipment Index'!$B$2:$B$1513,MATCH(1,'Equipment Index'!$K$2:$K$1513,0)),"") -> Pallet H · L3 · line 1
